Workbook
Name A: #N/A
Name A: #REF!
Name A: #N/A
Name A: [0]!A
Name A: #REF!
Name A: #REF!
Name A00: [1]督導二課!$D$80
Name AA: #REF!
Name AA: #REF!
Name AA: #REF!
Name AA: #REF!
Name AA: #REF!
Name AA: #REF!
Name BEGIN: #N/A
Name BEGIN: #REF!
Name BEGIN: #N/A
Name BEGIN: [0]!BEGIN
Name BEGIN: #REF!
Name BEGIN: #REF!
Name BONUS: #N/A
Name BONUS: #REF!
Name BONUS: #N/A
Name BONUS: [0]!BONUS
Name BONUS: #REF!
Name BONUS: #REF!
Name CALK3: #N/A
Name CALK3: #REF!
Name CALK3: #N/A
Name CALK3: [0]!CALK3
Name CALK3: #REF!
Name CALK3: #REF!
Name CALP3: #N/A
Name CALP3: #REF!
Name CALP3: #N/A
Name CALP3: [0]!CALP3
Name CALP3: #REF!
Name CALP3: #REF!
Name DRALINE: #N/A
Name DRALINE: #REF!
Name DRALINE: #N/A
Name DRALINE: [0]!DRALINE
Name DRALINE: #REF!
Name DRALINE: #REF!
Name DRAWLINE: #N/A
Name DRAWLINE: #REF!
Name DRAWLINE: #N/A
Name DRAWLINE: [0]!DRAWLINE
Name DRAWLINE: #REF!
Name DRAWLINE: #REF!
Name FUCK: #REF!
Name FUCK: #REF!
Name FUCK: #REF!
Name FUCK: #REF!
Name FUCK: #REF!
Name FUCK: #REF!
Name FUCK1: #REF!
Name FUCK1: #REF!
Name FUCK1: #REF!
Name FUCK1: #REF!
Name FUCK1: #REF!

Sheet 勤務統計
A1: =首頁!B5 -> 46023 | B1: =首頁!E5 -> 46113 | C1: =首頁!A14 -> PMQ1 | D1: =首頁!B14 -> -- | E1: =IF(首頁!C14=0,"",首頁!C14) -> +L90 | F1: =IF(首頁!D14=0,"",首頁!D14) -> +721 | G1: 小坪頂 | H1: {=IFERROR(HYPERLINK("#" & ADDRESS(MIN(IF(ISNUMBER(SEARCH(G1, 門市總表!A5:W274)), ROW(門市總表!A5:W274), 10000000000)), MIN(IF(ISNUMBER(SEARCH(G1, 門市總表!A5:W274)), COLUMN(門市總表!A5:W274), 10000000000))), "搜索"), "未找到")} -> 未找到
A2: =IFERROR(HYPERLINK("#'門市主檔'!A"&MATCH(門市總表!A5,門市總表!A3:A279,0)+20, "新北一部"), "查無店編") -> 新北一部 | B2: =IFERROR(HYPERLINK("#'門市主檔'!A"&MATCH(門市總表!A212,勤務統計!A:A,0), "統計"), "查無店編") -> 查無店編 | C2: 石門區 | D2: 三芝區 | E2: 淡水區 | F2: 金山區 | G2: 八里區 | H2: 蘆洲區 | I2: 三重區 | J2: 蘆竹區 | K2: 龜山區 | L2: 五股區 | M2: 新莊區 | N2: 泰山區 | O2: 林口區 | P2: 板橋區 | Q2: 中和區 | R2: 永和區 | S2: (定保) | T2: - | U2: (定保) | V2: -
A3: 門市數量(307) | B3: =SUM(C3:R3) -> 306 | C3: =COUNTIF(門市總表!$D:$D,C2)-C23 -> 1 | D3: =COUNTIF(門市總表!$D:$D,D2)-D23 -> 3 | E3: =COUNTIF(門市總表!$D:$D,E2)-E23 -> 16 | F3: =COUNTIF(門市總表!$D:$D,F2)-F23 -> 2 | G3: =COUNTIF(門市總表!$D:$D,G2)-G23 -> 8 | H3: =COUNTIF(門市總表!$D:$D,H2)-H23 -> 18 | I3: =COUNTIF(門市總表!$D:$D,I2)-I23 -> 73 | J3: =COUNTIF(門市總表!$D:$D,J2)-J23 -> 25 | ... R3: =COUNTIF(門市總表!$D:$D,R2)-R23 -> 6
A4: =首頁!A14&" 進度" -> PMQ1 進度 | B4: =B5/B3 -> 0.29738562 | C4: =C5/(C3-C23) -> 0 | D4: =D5/(D3-D23) -> 1 | E4: =E5/(E3-E23) -> 0.25 | F4: =F5/(F3-F23) -> 0 | G4: =G5/(G3-G23) -> 1 | H4: =H5/(H3-H23) -> 0.11111111 | I4: =I5/(I3-I23) -> 0.23611111 | J4: =J5/(J3-J23) -> 0.4 | ... R4: =R5/(R3-R23) -> 0.66666667
A5: 完工數量 | B5: =SUM(C5:R5) -> 91 | C5: =COUNTIFS(門市總表!$D:$D,C2,門市總表!$I:$I,$C$1) -> 0 | D5: =COUNTIFS(門市總表!$D:$D,D2,門市總表!$I:$I,$C$1) -> 3 | E5: =COUNTIFS(門市總表!$D:$D,E2,門市總表!$I:$I,$C$1) -> 4 | F5: =COUNTIFS(門市總表!$D:$D,F2,門市總表!$I:$I,$C$1) -> 0 | G5: =COUNTIFS(門市總表!$D:$D,G2,門市總表!$I:$I,$C$1) -> 8 | H5: =COUNTIFS(門市總表!$D:$D,H2,門市總表!$I:$I,$C$1) -> 2 | I5: =COUNTIFS(門市總表!$D:$D,I2,門市總表!$I:$I,$C$1) -> 17 | J5: =COUNTIFS(門市總表!$D:$D,J2,門市總表!$I:$I,$C$1) -> 10 | ... R5: =COUNTIFS(門市總表!$D:$D,R2,門市總表!$I:$I,$C$1) -> 4
A6: 剩餘門市 | B6: =SUM(C6:R6) -> 215 | C6: =IF(C3-C5<0,0,C3-C5) -> 1 | D6: =IF(D3-D5<0,0,D3-D5) -> 0 | E6: =IF(E3-E5<0,0,E3-E5) -> 12 | F6: =IF(F3-F5<0,0,F3-F5) -> 2 | G6: =IF(G3-G5<0,0,G3-G5) -> 0 | H6: =IF(H3-H5<0,0,H3-H5) -> 16 | I6: =IF(I3-I5<0,0,I3-I5) -> 56 | J6: =IF(J3-J5<0,0,J3-J5) -> 15 | ... R6: =IF(R3-R5<0,0,R3-R5) -> 2 | S6: =IF(#REF!-#REF!<0,0) -> #REF!
A7: 維修件數 | B7: =SUM(C7:R7) -> 75 | C7: =COUNTIFS(IM!$H:$H,"*"&C2&"*",IM!$B:$B,"維修",IM!$AM:$AM,">="&$A$1,IM!$AM:$AM,"<="&$B$1) -> 0 | D7: =COUNTIFS(IM!$H:$H,"*"&D2&"*",IM!$B:$B,"維修",IM!$AM:$AM,">="&$A$1,IM!$AM:$AM,"<="&$B$1) -> 0 | E7: =COUNTIFS(IM!$H:$H,"*"&E2&"*",IM!$B:$B,"維修",IM!$AM:$AM,">="&$A$1,IM!$AM:$AM,"<="&$B$1) -> 4 | F7: =COUNTIFS(IM!$H:$H,"*"&F2&"*",IM!$B:$B,"維修",IM!$AM:$AM,">="&$A$1,IM!$AM:$AM,"<="&$B$1) -> 0 | G7: =COUNTIFS(IM!$H:$H,"*"&G2&"*",IM!$B:$B,"維修",IM!$AM:$AM,">="&$A$1,IM!$AM:$AM,"<="&$B$1) -> 5 | H7: =COUNTIFS(IM!$H:$H,"*"&H2&"*",IM!$B:$B,"維修",IM!$AM:$AM,">="&$A$1,IM!$AM:$AM,"<="&$B$1) -> 2 | I7: =COUNTIFS(IM!$H:$H,"*"&I2&"*",IM!$B:$B,"維修",IM!$AM:$AM,">="&$A$1,IM!$AM:$AM,"<="&$B$1) -> 36 | J7: =COUNTIFS(IM!$H:$H,"*"&J2&"*",IM!$B:$B,"維修",IM!$AM:$AM,">="&$A$1,IM!$AM:$AM,"<="&$B$1) -> 3 | ... R7: =COUNTIFS(IM!$H:$H,"*"&R2&"*",IM!$B:$B,"維修",IM!$AM:$AM,">="&$A$1,IM!$AM:$AM,"<="&$B$1) -> 1
A8: 當區報修率 | B8: =SUM(C8:R8)/B3 -> 0.0089404602 | C8: =IF(C3=0,0,C7/C3) -> 0 | D8: =IF(D3=0,0,D7/D3) -> 0 | E8: =IF(E3=0,0,E7/E3) -> 0.25 | F8: =IF(F3=0,0,F7/F3) -> 0 | G8: =IF(G3=0,0,G7/G3) -> 0.625 | H8: =IF(H3=0,0,H7/H3) -> 0.11111111 | I8: =IF(I3=0,0,I7/I3) -> 0.49315068 | J8: =IF(J3=0,0,J7/J3) -> 0.12 | ... R8: =IF(R3=0,0,R7/R3) -> 0.16666667
A9: 全區報修率 | B9: =SUM(C9:R9) -> 0.24509804 | C9: =C7/$B$3 -> 0 | D9: =D7/$B$3 -> 0 | E9: =E7/$B$3 -> 0.013071895 | F9: =F7/$B$3 -> 0 | G9: =G7/$B$3 -> 0.016339869 | H9: =H7/$B$3 -> 0.0065359477 | I9: =I7/$B$3 -> 0.11764706 | J9: =J7/$B$3 -> 0.0098039216 | ... R9: =R7/$B$3 -> 0.0032679739
A10: =D1 -> -- | B10: =SUM(C10:R10) -> 0 | C10: =COUNTIFS('0919門市清單主檔'!$V:$V,C2,'0919門市清單主檔'!$AF:$AF,$D$1) -> 0 | D10: =COUNTIFS('0919門市清單主檔'!$V:$V,D2,'0919門市清單主檔'!$AF:$AF,$D$1) -> 0 | E10: =COUNTIFS('0919門市清單主檔'!$V:$V,E2,'0919門市清單主檔'!$AF:$AF,$D$1) -> 0 | F10: =COUNTIFS('0919門市清單主檔'!$V:$V,F2,'0919門市清單主檔'!$AF:$AF,$D$1) -> 0 | G10: =COUNTIFS('0919門市清單主檔'!$V:$V,G2,'0919門市清單主檔'!$AF:$AF,$D$1) -> 0 | H10: =COUNTIFS('0919門市清單主檔'!$V:$V,H2,'0919門市清單主檔'!$AF:$AF,$D$1) -> 0 | I10: =COUNTIFS('0919門市清單主檔'!$V:$V,I2,'0919門市清單主檔'!$AF:$AF,$D$1) -> 0 | J10: =COUNTIFS('0919門市清單主檔'!$V:$V,J2,'0919門市清單主檔'!$AF:$AF,$D$1) -> 0 | ... R10: =COUNTIFS('0919門市清單主檔'!$V:$V,R2,'0919門市清單主檔'!$AF:$AF,$D$1) -> 0
A11: 完工進度 | B11: =IF(A10<>"-",B12/B10,"") -> #DIV/0! | C11: =C12/C10 -> #DIV/0! | D11: =D12/D10 -> #DIV/0! | E11: =E12/E10 -> #DIV/0! | F11: =F12/F10 -> #DIV/0! | G11: =G12/G10 -> #DIV/0! | H11: =H12/H10 -> #DIV/0! | I11: =I12/I10 -> #DIV/0! | J11: =J12/J10 -> #DIV/0! | ... R11: =R12/R10 -> #DIV/0!
A12: 完工數量 | B12: =IF(A10<>"-",SUM(C12:R12),"") -> 0 | C12: =COUNTIFS(門市總表!$D:$D,C2,門市總表!$Q:$Q,$D$1) -> 0 | D12: =COUNTIFS(門市總表!$D:$D,D2,門市總表!$Q:$Q,$D$1) -> 0 | E12: =COUNTIFS(門市總表!$D:$D,E2,門市總表!$Q:$Q,$D$1) -> 0 | F12: =COUNTIFS(門市總表!$D:$D,F2,門市總表!$Q:$Q,$D$1) -> 0 | G12: =COUNTIFS(門市總表!$D:$D,G2,門市總表!$Q:$Q,$D$1) -> 0 | H12: =COUNTIFS(門市總表!$D:$D,H2,門市總表!$Q:$Q,$D$1) -> 0 | I12: =COUNTIFS(門市總表!$D:$D,I2,門市總表!$Q:$Q,$D$1) -> 0 | J12: =COUNTIFS(門市總表!$D:$D,J2,門市總表!$Q:$Q,$D$1) -> 0 | ... R12: =COUNTIFS(門市總表!$D:$D,R2,門市總表!$Q:$Q,$D$1) -> 0
A13: 剩餘門市 | B13: =IF(A10<>"-",SUM(C13:R13),"") -> 0 | C13: =C10-C12 -> 0 | D13: =D10-D12 -> 0 | E13: =E10-E12 -> 0 | F13: =F10-F12 -> 0 | G13: =G10-G12 -> 0 | H13: =H10-H12 -> 0 | I13: =I10-I12 -> 0 | J13: =J10-J12 -> 0 | ... R13: =R10-R12 -> 0
A14: =E1 -> +L90 | B14: =IF(SUM(C14:R14)=0,"",(SUM(C14:R14))) -> 300 | C14: =COUNTIFS('0919門市清單主檔'!$V:$V,C2,'0919門市清單主檔'!$AG:$AG,$E$1) -> 1 | D14: =COUNTIFS('0919門市清單主檔'!$V:$V,D2,'0919門市清單主檔'!$AG:$AG,$E$1) -> 3 | E14: =COUNTIFS('0919門市清單主檔'!$V:$V,E2,'0919門市清單主檔'!$AG:$AG,$E$1) -> 16 | F14: =COUNTIFS('0919門市清單主檔'!$V:$V,F2,'0919門市清單主檔'!$AG:$AG,$E$1) -> 2 | G14: =COUNTIFS('0919門市清單主檔'!$V:$V,G2,'0919門市清單主檔'!$AG:$AG,$E$1) -> 8 | H14: =COUNTIFS('0919門市清單主檔'!$V:$V,H2,'0919門市清單主檔'!$AG:$AG,$E$1) -> 17 | I14: =COUNTIFS('0919門市清單主檔'!$V:$V,I2,'0919門市清單主檔'!$AG:$AG,$E$1) -> 72 | J14: =COUNTIFS('0919門市清單主檔'!$V:$V,J2,'0919門市清單主檔'!$AG:$AG,$E$1) -> 25 | ... R14: =COUNTIFS('0919門市清單主檔'!$V:$V,R2,'0919門市清單主檔'!$AG:$AG,$E$1) -> 6
A15: 完工進度 | B15: =IF(A14<>"--",B16/B14,"") -> 0.67666667 | C15: =C16/C14 -> 1 | D15: =D16/D14 -> 1 | E15: =E16/E14 -> 1 | F15: =F16/F14 -> 1 | G15: =G16/G14 -> 1 | H15: =H16/H14 -> 0.94117647 | I15: =I16/I14 -> 0.93055556 | J15: =J16/J14 -> 0.32 | ... R15: =R16/R14 -> 0
A16: 完工數量 | B16: =IF(A14<>"--",SUM(C16:R16),"") -> 203 | C16: =COUNTIFS(門市總表!$D:$D,C2,門市總表!$S:$S,$E$1) -> 1 | D16: =COUNTIFS(門市總表!$D:$D,D2,門市總表!$S:$S,$E$1) -> 3 | E16: =COUNTIFS(門市總表!$D:$D,E2,門市總表!$S:$S,$E$1) -> 16 | F16: =COUNTIFS(門市總表!$D:$D,F2,門市總表!$S:$S,$E$1) -> 2 | G16: =COUNTIFS(門市總表!$D:$D,G2,門市總表!$S:$S,$E$1) -> 8 | H16: =COUNTIFS(門市總表!$D:$D,H2,門市總表!$S:$S,$E$1) -> 16 | I16: =COUNTIFS(門市總表!$D:$D,I2,門市總表!$S:$S,$E$1) -> 67 | J16: =COUNTIFS(門市總表!$D:$D,J2,門市總表!$S:$S,$E$1) -> 8 | ... R16: =COUNTIFS(門市總表!$D:$D,R2,門市總表!$S:$S,$E$1) -> 0
A17: 剩餘門市 | B17: =IF(A14<>"--",SUM(C17:R17),"") -> 97 | C17: =C14-C16 -> 0 | D17: =D14-D16 -> 0 | E17: =E14-E16 -> 0 | F17: =F14-F16 -> 0 | G17: =G14-G16 -> 0 | H17: =H14-H16 -> 1 | I17: =I14-I16 -> 5 | J17: =J14-J16 -> 17 | ... R17: =R14-R16 -> 6
A18: =F1 -> +721 | B18: =IF(SUM(C18:R18)=0,"",SUM(C18:R18)) -> 261 | C18: =COUNTIFS('0919門市清單主檔'!$V:$V,C2,'0919門市清單主檔'!$AH:$AH,$F$1) -> 1 | D18: =COUNTIFS('0919門市清單主檔'!$V:$V,D2,'0919門市清單主檔'!$AH:$AH,$F$1) -> 3 | E18: =COUNTIFS('0919門市清單主檔'!$V:$V,E2,'0919門市清單主檔'!$AH:$AH,$F$1) -> 16 | F18: =COUNTIFS('0919門市清單主檔'!$V:$V,F2,'0919門市清單主檔'!$AH:$AH,$F$1) -> 2 | G18: =COUNTIFS('0919門市清單主檔'!$V:$V,G2,'0919門市清單主檔'!$AH:$AH,$F$1) -> 8 | H18: =COUNTIFS('0919門市清單主檔'!$V:$V,H2,'0919門市清單主檔'!$AH:$AH,$F$1) -> 16 | I18: =COUNTIFS('0919門市清單主檔'!$V:$V,I2,'0919門市清單主檔'!$AH:$AH,$F$1) -> 65 | J18: =COUNTIFS('0919門市清單主檔'!$V:$V,J2,'0919門市清單主檔'!$AH:$AH,$F$1) -> 20 | ... R18: =COUNTIFS('0919門市清單主檔'!$V:$V,R2,'0919門市清單主檔'!$AH:$AH,$F$1) -> 6
A19: 完工進度 | B19: =IF(A18<>"--",B20/B18,"") -> 0.31034483 | C19: =C20/C18 -> 0 | D19: =D20/D18 -> 1 | E19: =E20/E18 -> 0.25 | F19: =F20/F18 -> 0 | G19: =G20/G18 -> 1 | H19: =H20/H18 -> 0.125 | I19: =I20/I18 -> 0.24615385 | J19: =J20/J18 -> 0.4 | ... R19: =R20/R18 -> 0.66666667
A20: 完工數量 | B20: =IF(A18<>"--",SUM(C20:R20),"") -> 81 | C20: =COUNTIFS(門市總表!$D:$D,C2,門市總表!$U:$U,$F$1) -> 0 | D20: =COUNTIFS(門市總表!$D:$D,D2,門市總表!$U:$U,$F$1) -> 3 | E20: =COUNTIFS(門市總表!$D:$D,E2,門市總表!$U:$U,$F$1) -> 4 | F20: =COUNTIFS(門市總表!$D:$D,F2,門市總表!$U:$U,$F$1) -> 0 | G20: =COUNTIFS(門市總表!$D:$D,G2,門市總表!$U:$U,$F$1) -> 8 | H20: =COUNTIFS(門市總表!$D:$D,H2,門市總表!$U:$U,$F$1) -> 2 | I20: =COUNTIFS(門市總表!$D:$D,I2,門市總表!$U:$U,$F$1) -> 16 | J20: =COUNTIFS(門市總表!$D:$D,J2,門市總表!$U:$U,$F$1) -> 8 | ... R20: =COUNTIFS(門市總表!$D:$D,R2,門市總表!$U:$U,$F$1) -> 4
A21: 剩餘門市 | B21: =IF(A18<>"--",SUM(C21:R21),"") -> 180 | C21: =C18-C20 -> 1 | D21: =D18-D20 -> 0 | E21: =E18-E20 -> 12 | F21: =F18-F20 -> 2 | G21: =G18-G20 -> 0 | H21: =H18-H20 -> 14 | I21: =I18-I20 -> 49 | J21: =J18-J20 -> 12 | ... R21: =R18-R20 -> 2
A22: 撤店 | B22: =SUM(C22:R22) -> 4 | C22: =COUNTIFS(門市總表!$D:$D,C2,門市總表!$F:$F,"*撤店*") -> 0 | D22: =COUNTIFS(門市總表!$D:$D,D2,門市總表!$F:$F,"*撤店*") -> 1 | E22: =COUNTIFS(門市總表!$D:$D,E2,門市總表!$F:$F,"*撤店*") -> 1 | F22: =COUNTIFS(門市總表!$D:$D,F2,門市總表!$F:$F,"*撤店*") -> 0 | G22: =COUNTIFS(門市總表!$D:$D,G2,門市總表!$F:$F,"*撤店*") -> 0 | H22: =COUNTIFS(門市總表!$D:$D,H2,門市總表!$F:$F,"*撤店*") -> 0 | I22: =COUNTIFS(門市總表!$D:$D,I2,門市總表!$F:$F,"*撤店*") -> 0 | J22: =COUNTIFS(門市總表!$D:$D,J2,門市總表!$F:$F,"*撤店*") -> 0 | ... R22: =COUNTIFS(門市總表!$D:$D,R2,門市總表!$F:$F,"*撤店*") -> 0 | S22: =COUNTIFS(門市總表!$D$3:$D$277,#REF!,門市總表!$F$3:$F$277,"*撤店*") -> 0
A23: 新開 | B23: =SUM(C23:R23) -> 3 | C23: =COUNTIFS(門市總表!$D:$D,C2,門市總表!$F:$F,"新開") -> 0 | D23: =COUNTIFS(門市總表!$D:$D,D2,門市總表!$F:$F,"新開") -> 0 | E23: =COUNTIFS(門市總表!$D:$D,E2,門市總表!$F:$F,"新開") -> 0 | F23: =COUNTIFS(門市總表!$D:$D,F2,門市總表!$F:$F,"新開") -> 0 | G23: =COUNTIFS(門市總表!$D:$D,G2,門市總表!$F:$F,"新開") -> 0 | H23: =COUNTIFS(門市總表!$D:$D,H2,門市總表!$F:$F,"新開") -> 0 | I23: =COUNTIFS(門市總表!$D:$D,I2,門市總表!$F:$F,"新開") -> 1 | J23: =COUNTIFS(門市總表!$D:$D,J2,門市總表!$F:$F,"新開") -> 0 | ... R23: =COUNTIFS(門市總表!$D:$D,R2,門市總表!$F:$F,"新開") -> 0
A24: 萊到店 | B24: =SUM(C24:R24) -> 8 | C24: =COUNTIFS(門市總表!$G:$G,"*萊到店*",門市總表!$D:$D,C2) -> 0 | D24: =COUNTIFS(門市總表!$G:$G,"*萊到店*",門市總表!$D:$D,D2) -> 0 | E24: =COUNTIFS(門市總表!$G:$G,"*萊到店*",門市總表!$D:$D,E2) -> 0 | F24: =COUNTIFS(門市總表!$G:$G,"*萊到店*",門市總表!$D:$D,F2) -> 0 | G24: =COUNTIFS(門市總表!$G:$G,"*萊到店*",門市總表!$D:$D,G2) -> 0 | H24: =COUNTIFS(門市總表!$G:$G,"*萊到店*",門市總表!$D:$D,H2) -> 1 | I24: =COUNTIFS(門市總表!$G:$G,"*萊到店*",門市總表!$D:$D,I2) -> 0 | J24: =COUNTIFS(門市總表!$G:$G,"*萊到店*",門市總表!$D:$D,J2) -> 0 | ... R24: =COUNTIFS(門市總表!$G:$G,"*萊到店*",門市總表!$D:$D,R2) -> 0

Sheet 門市總表
A1: 漢江 | B1: {=IFERROR(HYPERLINK("#" & ADDRESS(MIN(IF(ISNUMBER(SEARCH(A1, 門市總表!A3:W274)), ROW(門市總表!A3:W274), 10000000000)), MIN(IF(ISNUMBER(SEARCH(A1, 門市總表!A3:W274)), COLUMN(門市總表!A3:W274), 10000000000))), "搜索"), "未找到")} -> 搜索
A2: 門市編號 | B2: 門市名稱 | C2: 縣市別 | D2: 鄉鎮市區 | E2: 工程師 | F2: 門市狀態 | G2: 門市屬性 | H2: 保養單 | I2: PMQ_ 檢核 | J2: 完工檢核2 | K2: iM筆數 | L2: iMainte | M2: 專案檢核 | N2: HUB | O2: 完工檢核 | P2: 完工確認 | Q2: 專案1檢核 | R2: 完成日期 | S2: 專案2檢核 | T2: 完成日期 | U2: 專案3檢核 | V2: 完成日期 | W2: HUB
A3: 2109 | B3: =VLOOKUP(A3,'0919門市清單主檔'!B:C,2,FALSE) -> 新莊瓊林南 | C3: =VLOOKUP($A3,'0919門市清單主檔'!B:V,20,FALSE) -> 新北市 | D3: =VLOOKUP($A3,'0919門市清單主檔'!B:V,21,FALSE) -> 新莊區 | E3: =VLOOKUP(D3,門市狀態!G:H,2,FALSE) -> 湯家瑋 | F3: =IFERROR(IF(VLOOKUP(A3,門市狀態!A:D,4,FALSE)=0,"",VLOOKUP(A3,門市狀態!A:D,4,FALSE)),"") | H3: =IF(I3>0,(TEXT(I3,"yyyymmdd")&勤務統計!$V$2&A3&勤務統計!$V$2&B3&勤務統計!$S$2),"") -> PMQ1-2109-新莊瓊林南(定保) | I3: {=IF(AND(SUMPRODUCT((IM!$F$2:$F$5000=A3)*(ISNUMBER(SEARCH(勤務統計!$C$1, IM!$AC$2:$AC$5000))))>0), 勤務統計!$C$1, "")} -> PMQ1 | J3: {=IFERROR(INDEX(IM!$AM$2:$AM$5000, MATCH(1, (IM!$F$2:$F$5000=A3) * (ISNUMBER(SEARCH(勤務統計!$C$1, IM!$AC$2:$AC$5000))), 0)), "")} -> 46024 | K3: {=SUMPRODUCT((IM!$F$2:$F$5000=A3)*(IM!$AD$2:$AD$5000="O")*(ISNUMBER(SEARCH(勤務統計!$C$1, IM!$AC$2:$AC$5000))))} -> 1 | L3: {=IF(K3>0,IFERROR(HYPERLINK("#'IM'!AC"&MATCH(1,(IM!$F$1:$F$5000=A3)*(ISNUMBER(SEARCH(勤務統計!$C$1,IM!$AC$1:$AC$5000))),0),"檢核"),"未登錄"),"")} -> 檢核 | M3: =Q3&S3&U3 -> +L90 | N3: {=IF(AND( SUMPRODUCT( (IM!$F$2:$F$522=A3) * ISNUMBER(SEARCH("*HUB*", IM!$AC$2:$AC$522)) * (IM!$X$2:$X$522>=勤務統計!$A$1) * (IM!$X$2:$X$522<=勤務統計!$B$1)*(W3="HUB") ) > 0 ), "HUB", "")} | O3: =IF( IFERROR(VLOOKUP(A3,勤務統計!A:I,9,FALSE),"")<>勤務統計!$C$1, "未完工", IF( AND(勤務統計!$D$1="--",勤務統計!$E$1="--",勤務統計!$F$1="--"), "已完工", IF( OR( AND(勤務統計!$D$1<>"--", IFERROR(VLOOKUP(A3,'0919門市清單主檔'!B:AH,31,FALSE),"")=勤務統計!$D$1, IFERROR(VLOOKUP(A3,勤務統計!A:Q,17,FALSE),"")<>勤務統計!$D$1), AND(勤務統計!$E$1<>"--", IFERROR(VLOOKUP(A3,'0919門市清單主檔'!B:AH,32,FALSE),"")=勤務統計!$E$1, IFERROR(VLOOKUP(A3,勤務統計!A:S,19,FALSE),"")<>勤務統計!$E$1), AND(勤務統計!$F$1<>"--", IFERROR(VLOOKUP(A3,'0919門市清單主檔'!B:AH,33,FALSE),"")=勤務統計!$F$1, IFERROR(VLOOKUP(A3,勤務統計!A:U,21,FALSE),"")<>勤務統計!$F$1), AND(IFERROR(VLOOKUP(A3,'0919門市清單主檔'!B:AH,28,FALSE),"")="HUB", IFERROR(VLOOKUP(A3,勤務統計!A:W,23,FALSE),"")<>"HUB") ), _xlfn.TEXTJOIN( "，", TRUE, IF(AND(勤務統計!$D$1<>"--", IFERROR(VLOOKUP(A3,'0919門市清單主檔'!B:AH,31,FALSE),"")=勤務統計!$D$1, IFERROR(VLOOKUP(A3,勤務統計!A:Q,17,FALSE),"")<>勤務統計!$D$1), 勤務統計!$D$1, ""), IF(AND(勤務統計!$E$1<>"--", IFERROR(VLOOKUP(A3,'0919門市清單主檔'!B:AH,32,FALSE),"")=勤務統計!$E$1, IFERROR(VLOOKUP(A3,勤務統計!A:S,19,FALSE),"")<>勤務統計!$E$1), 勤務統計!$E$1, ""), IF(AND(勤務統計!$F$1<>"--", IFERROR(VLOOKUP(A3,'0919門市清單主檔'!B:AH,33,FALSE),"")=勤務統計!$F$1, IFERROR(VLOOKUP(A3,勤務統計!A:U,21,FALSE),"")<>勤務統計!$F$1), 勤務統計!$F$1, ""), IF(AND(IFERROR(VLOOKUP(A3,'0919門市清單主檔'!B:AH,28,FALSE),"")="HUB", IFERROR(VLOOKUP(A3,勤務統計!A:W,23,FALSE),"")<>"HUB"), "HUB", "") ) & "未完工", "已完工" ) ) ) -> 未完工 | P3: =(TEXT(I3,"yyyymmdd"))&勤務統計!$V$2&A3&勤務統計!$V$2&B3&勤務統計!$S$2 -> PMQ1-2109-新莊瓊林南(定保) | Q3: {=IF(AND(SUMPRODUCT((IM!$F$2:$F$5000=A3)*(ISNUMBER(SEARCH(勤務統計!$D$1, IM!$AC$2:$AC$5000))))>0), 勤務統計!$D$1, "")} | R3: {=IFERROR(INDEX(IM!$AM$2:$AM$5000, MATCH(1, (IM!$F$2:$F$5000=A3) * (ISNUMBER(SEARCH(勤務統計!$D$1, IM!$AC$2:$AC$5000))), 0)), "")} | S3: {=IF(AND(SUMPRODUCT((IM!$F$2:$F$5000=A3)*(ISNUMBER(SEARCH(勤務統計!$E$1, IM!$AC$2:$AC$5000))))>0), 勤務統計!$E$1, "")} -> +L90 | T3: {=IFERROR(INDEX(IM!$AM$2:$AM$5000, MATCH(1, (IM!$F$2:$F$5000=A3) * (ISNUMBER(SEARCH(勤務統計!$E$1, IM!$AC$2:$AC$5000))), 0)), "")} -> 46024 | U3: {=IF(AND(SUMPRODUCT((IM!$F$2:$F$5000=A3)*(ISNUMBER(SEARCH(勤務統計!$F$1, IM!$AC$2:$AC$5000))))>0), 勤務統計!$F$1, "")} | V3: {=IFERROR(INDEX(IM!$AM$2:$AM$5000, MATCH(1, (IM!$F$2:$F$5000=A3) * (ISNUMBER(SEARCH(勤務統計!$F$1, IM!$AC$2:$AC$5000))), 0)), "")} | W3: =IF(VLOOKUP(A3,'0919門市清單主檔'!B:AC,28,FALSE)=0,"",VLOOKUP(A3,'0919門市清單主檔'!B:AC,28,FALSE))
A4: 2399 | B4: =VLOOKUP(A4,'0919門市清單主檔'!B:C,2,FALSE) -> 三重三陽店 | C4: =VLOOKUP($A4,'0919門市清單主檔'!B:V,20,FALSE) -> 新北市 | D4: =VLOOKUP($A4,'0919門市清單主檔'!B:V,21,FALSE) -> 三重區 | E4: =VLOOKUP(D4,門市狀態!G:H,2,FALSE) -> 劉柏均 | F4: =IFERROR(IF(VLOOKUP(A4,門市狀態!A:D,4,FALSE)=0,"",VLOOKUP(A4,門市狀態!A:D,4,FALSE)),"") | H4: =IF(I4>0,(TEXT(I4,"yyyymmdd")&勤務統計!$V$2&A4&勤務統計!$V$2&B4&勤務統計!$S$2),"") -> PMQ1-2399-三重三陽店(定保) | I4: {=IF(AND(SUMPRODUCT((IM!$F$2:$F$5000=A4)*(ISNUMBER(SEARCH(勤務統計!$C$1, IM!$AC$2:$AC$5000))))>0), 勤務統計!$C$1, "")} -> PMQ1 | J4: {=IFERROR(INDEX(IM!$AM$2:$AM$5000, MATCH(1, (IM!$F$2:$F$5000=A4) * (ISNUMBER(SEARCH(勤務統計!$C$1, IM!$AC$2:$AC$5000))), 0)), "")} -> 46024 | K4: {=SUMPRODUCT((IM!$F$2:$F$5000=A4)*(IM!$AD$2:$AD$5000="O")*(ISNUMBER(SEARCH(勤務統計!$C$1, IM!$AC$2:$AC$5000))))} -> 1 | L4: {=IF(K4>0,IFERROR(HYPERLINK("#'IM'!AC"&MATCH(1,(IM!$F$1:$F$5000=A4)*(ISNUMBER(SEARCH(勤務統計!$C$1,IM!$AC$1:$AC$5000))),0),"檢核"),"未登錄"),"")} -> 檢核 | M4: =Q4&S4&U4 -> +L90+721 | N4: {=IF(AND( SUMPRODUCT( (IM!$F$2:$F$522=A4) * ISNUMBER(SEARCH("*HUB*", IM!$AC$2:$AC$522)) * (IM!$X$2:$X$522>=勤務統計!$A$1) * (IM!$X$2:$X$522<=勤務統計!$B$1)*(W4="HUB") ) > 0 ), "HUB", "")} | O4: =IF( IFERROR(VLOOKUP(A4,勤務統計!A:I,9,FALSE),"")<>勤務統計!$C$1, "未完工", IF( AND(勤務統計!$D$1="--",勤務統計!$E$1="--",勤務統計!$F$1="--"), "已完工", IF( OR( AND(勤務統計!$D$1<>"--", IFERROR(VLOOKUP(A4,'0919門市清單主檔'!B:AH,31,FALSE),"")=勤務統計!$D$1, IFERROR(VLOOKUP(A4,勤務統計!A:Q,17,FALSE),"")<>勤務統計!$D$1), AND(勤務統計!$E$1<>"--", IFERROR(VLOOKUP(A4,'0919門市清單主檔'!B:AH,32,FALSE),"")=勤務統計!$E$1, IFERROR(VLOOKUP(A4,勤務統計!A:S,19,FALSE),"")<>勤務統計!$E$1), AND(勤務統計!$F$1<>"--", IFERROR(VLOOKUP(A4,'0919門市清單主檔'!B:AH,33,FALSE),"")=勤務統計!$F$1, IFERROR(VLOOKUP(A4,勤務統計!A:U,21,FALSE),"")<>勤務統計!$F$1), AND(IFERROR(VLOOKUP(A4,'0919門市清單主檔'!B:AH,28,FALSE),"")="HUB", IFERROR(VLOOKUP(A4,勤務統計!A:W,23,FALSE),"")<>"HUB") ), _xlfn.TEXTJOIN( "，", TRUE, IF(AND(勤務統計!$D$1<>"--", IFERROR(VLOOKUP(A4,'0919門市清單主檔'!B:AH,31,FALSE),"")=勤務統計!$D$1, IFERROR(VLOOKUP(A4,勤務統計!A:Q,17,FALSE),"")<>勤務統計!$D$1), 勤務統計!$D$1, ""), IF(AND(勤務統計!$E$1<>"--", IFERROR(VLOOKUP(A4,'0919門市清單主檔'!B:AH,32,FALSE),"")=勤務統計!$E$1, IFERROR(VLOOKUP(A4,勤務統計!A:S,19,FALSE),"")<>勤務統計!$E$1), 勤務統計!$E$1, ""), IF(AND(勤務統計!$F$1<>"--", IFERROR(VLOOKUP(A4,'0919門市清單主檔'!B:AH,33,FALSE),"")=勤務統計!$F$1, IFERROR(VLOOKUP(A4,勤務統計!A:U,21,FALSE),"")<>勤務統計!$F$1), 勤務統計!$F$1, ""), IF(AND(IFERROR(VLOOKUP(A4,'0919門市清單主檔'!B:AH,28,FALSE),"")="HUB", IFERROR(VLOOKUP(A4,勤務統計!A:W,23,FALSE),"")<>"HUB"), "HUB", "") ) & "未完工", "已完工" ) ) ) -> 未完工 | P4: =(TEXT(I4,"yyyymmdd"))&勤務統計!$V$2&A4&勤務統計!$V$2&B4&勤務統計!$S$2 -> PMQ1-2399-三重三陽店(定保) | Q4: {=IF(AND(SUMPRODUCT((IM!$F$2:$F$5000=A4)*(ISNUMBER(SEARCH(勤務統計!$D$1, IM!$AC$2:$AC$5000))))>0), 勤務統計!$D$1, "")} | R4: {=IFERROR(INDEX(IM!$AM$2:$AM$5000, MATCH(1, (IM!$F$2:$F$5000=A4) * (ISNUMBER(SEARCH(勤務統計!$D$1, IM!$AC$2:$AC$5000))), 0)), "")} | S4: {=IF(AND(SUMPRODUCT((IM!$F$2:$F$5000=A4)*(ISNUMBER(SEARCH(勤務統計!$E$1, IM!$AC$2:$AC$5000))))>0), 勤務統計!$E$1, "")} -> +L90 | T4: {=IFERROR(INDEX(IM!$AM$2:$AM$5000, MATCH(1, (IM!$F$2:$F$5000=A4) * (ISNUMBER(SEARCH(勤務統計!$E$1, IM!$AC$2:$AC$5000))), 0)), "")} -> 46010 | U4: {=IF(AND(SUMPRODUCT((IM!$F$2:$F$5000=A4)*(ISNUMBER(SEARCH(勤務統計!$F$1, IM!$AC$2:$AC$5000))))>0), 勤務統計!$F$1, "")} -> +721 | V4: {=IFERROR(INDEX(IM!$AM$2:$AM$5000, MATCH(1, (IM!$F$2:$F$5000=A4) * (ISNUMBER(SEARCH(勤務統計!$F$1, IM!$AC$2:$AC$5000))), 0)), "")} -> 46024 | W4: =IF(VLOOKUP(A4,'0919門市清單主檔'!B:AC,28,FALSE)=0,"",VLOOKUP(A4,'0919門市清單主檔'!B:AC,28,FALSE))
A5: 3921 | B5: =VLOOKUP(A5,'0919門市清單主檔'!B:C,2,FALSE) -> 五股福鑫店 | C5: =VLOOKUP($A5,'0919門市清單主檔'!B:V,20,FALSE) -> 新北市 | D5: =VLOOKUP($A5,'0919門市清單主檔'!B:V,21,FALSE) -> 五股區 | E5: =VLOOKUP(D5,門市狀態!G:H,2,FALSE) -> 湯家瑋 | F5: =IFERROR(IF(VLOOKUP(A5,門市狀態!A:D,4,FALSE)=0,"",VLOOKUP(A5,門市狀態!A:D,4,FALSE)),"") | H5: =IF(I5>0,(TEXT(I5,"yyyymmdd")&勤務統計!$V$2&A5&勤務統計!$V$2&B5&勤務統計!$S$2),"") -> PMQ1-3921-五股福鑫店(定保) | I5: {=IF(AND(SUMPRODUCT((IM!$F$2:$F$5000=A5)*(ISNUMBER(SEARCH(勤務統計!$C$1, IM!$AC$2:$AC$5000))))>0), 勤務統計!$C$1, "")} -> PMQ1 | J5: {=IFERROR(INDEX(IM!$AM$2:$AM$5000, MATCH(1, (IM!$F$2:$F$5000=A5) * (ISNUMBER(SEARCH(勤務統計!$C$1, IM!$AC$2:$AC$5000))), 0)), "")} -> 46024 | K5: {=SUMPRODUCT((IM!$F$2:$F$5000=A5)*(IM!$AD$2:$AD$5000="O")*(ISNUMBER(SEARCH(勤務統計!$C$1, IM!$AC$2:$AC$5000))))} -> 1 | L5: {=IF(K5>0,IFERROR(HYPERLINK("#'IM'!AC"&MATCH(1,(IM!$F$1:$F$5000=A5)*(ISNUMBER(SEARCH(勤務統計!$C$1,IM!$AC$1:$AC$5000))),0),"檢核"),"未登錄"),"")} -> 檢核 | M5: =Q5&S5&U5 -> +L90+721 | N5: {=IF(AND( SUMPRODUCT( (IM!$F$2:$F$522=A5) * ISNUMBER(SEARCH("*HUB*", IM!$AC$2:$AC$522)) * (IM!$X$2:$X$522>=勤務統計!$A$1) * (IM!$X$2:$X$522<=勤務統計!$B$1)*(W5="HUB") ) > 0 ), "HUB", "")} | O5: =IF( IFERROR(VLOOKUP(A5,勤務統計!A:I,9,FALSE),"")<>勤務統計!$C$1, "未完工", IF( AND(勤務統計!$D$1="--",勤務統計!$E$1="--",勤務統計!$F$1="--"), "已完工", IF( OR( AND(勤務統計!$D$1<>"--", IFERROR(VLOOKUP(A5,'0919門市清單主檔'!B:AH,31,FALSE),"")=勤務統計!$D$1, IFERROR(VLOOKUP(A5,勤務統計!A:Q,17,FALSE),"")<>勤務統計!$D$1), AND(勤務統計!$E$1<>"--", IFERROR(VLOOKUP(A5,'0919門市清單主檔'!B:AH,32,FALSE),"")=勤務統計!$E$1, IFERROR(VLOOKUP(A5,勤務統計!A:S,19,FALSE),"")<>勤務統計!$E$1), AND(勤務統計!$F$1<>"--", IFERROR(VLOOKUP(A5,'0919門市清單主檔'!B:AH,33,FALSE),"")=勤務統計!$F$1, IFERROR(VLOOKUP(A5,勤務統計!A:U,21,FALSE),"")<>勤務統計!$F$1), AND(IFERROR(VLOOKUP(A5,'0919門市清單主檔'!B:AH,28,FALSE),"")="HUB", IFERROR(VLOOKUP(A5,勤務統計!A:W,23,FALSE),"")<>"HUB") ), _xlfn.TEXTJOIN( "，", TRUE, IF(AND(勤務統計!$D$1<>"--", IFERROR(VLOOKUP(A5,'0919門市清單主檔'!B:AH,31,FALSE),"")=勤務統計!$D$1, IFERROR(VLOOKUP(A5,勤務統計!A:Q,17,FALSE),"")<>勤務統計!$D$1), 勤務統計!$D$1, ""), IF(AND(勤務統計!$E$1<>"--", IFERROR(VLOOKUP(A5,'0919門市清單主檔'!B:AH,32,FALSE),"")=勤務統計!$E$1, IFERROR(VLOOKUP(A5,勤務統計!A:S,19,FALSE),"")<>勤務統計!$E$1), 勤務統計!$E$1, ""), IF(AND(勤務統計!$F$1<>"--", IFERROR(VLOOKUP(A5,'0919門市清單主檔'!B:AH,33,FALSE),"")=勤務統計!$F$1, IFERROR(VLOOKUP(A5,勤務統計!A:U,21,FALSE),"")<>勤務統計!$F$1), 勤務統計!$F$1, ""), IF(AND(IFERROR(VLOOKUP(A5,'0919門市清單主檔'!B:AH,28,FALSE),"")="HUB", IFERROR(VLOOKUP(A5,勤務統計!A:W,23,FALSE),"")<>"HUB"), "HUB", "") ) & "未完工", "已完工" ) ) ) -> 未完工 | P5: =(TEXT(I5,"yyyymmdd"))&勤務統計!$V$2&A5&勤務統計!$V$2&B5&勤務統計!$S$2 -> PMQ1-3921-五股福鑫店(定保) | Q5: {=IF(AND(SUMPRODUCT((IM!$F$2:$F$5000=A5)*(ISNUMBER(SEARCH(勤務統計!$D$1, IM!$AC$2:$AC$5000))))>0), 勤務統計!$D$1, "")} | R5: {=IFERROR(INDEX(IM!$AM$2:$AM$5000, MATCH(1, (IM!$F$2:$F$5000=A5) * (ISNUMBER(SEARCH(勤務統計!$D$1, IM!$AC$2:$AC$5000))), 0)), "")} | S5: {=IF(AND(SUMPRODUCT((IM!$F$2:$F$5000=A5)*(ISNUMBER(SEARCH(勤務統計!$E$1, IM!$AC$2:$AC$5000))))>0), 勤務統計!$E$1, "")} -> +L90 | T5: {=IFERROR(INDEX(IM!$AM$2:$AM$5000, MATCH(1, (IM!$F$2:$F$5000=A5) * (ISNUMBER(SEARCH(勤務統計!$E$1, IM!$AC$2:$AC$5000))), 0)), "")} -> 45964 | U5: {=IF(AND(SUMPRODUCT((IM!$F$2:$F$5000=A5)*(ISNUMBER(SEARCH(勤務統計!$F$1, IM!$AC$2:$AC$5000))))>0), 勤務統計!$F$1, "")} -> +721 | V5: {=IFERROR(INDEX(IM!$AM$2:$AM$5000, MATCH(1, (IM!$F$2:$F$5000=A5) * (ISNUMBER(SEARCH(勤務統計!$F$1, IM!$AC$2:$AC$5000))), 0)), "")} -> 46024 | W5: =IF(VLOOKUP(A5,'0919門市清單主檔'!B:AC,28,FALSE)=0,"",VLOOKUP(A5,'0919門市清單主檔'!B:AC,28,FALSE))
A6: 4316 | B6: =VLOOKUP(A6,'0919門市清單主檔'!B:C,2,FALSE) -> 五股工商店 | C6: =VLOOKUP($A6,'0919門市清單主檔'!B:V,20,FALSE) -> 新北市 | D6: =VLOOKUP($A6,'0919門市清單主檔'!B:V,21,FALSE) -> 五股區 | E6: =VLOOKUP(D6,門市狀態!G:H,2,FALSE) -> 湯家瑋 | F6: =IFERROR(IF(VLOOKUP(A6,門市狀態!A:D,4,FALSE)=0,"",VLOOKUP(A6,門市狀態!A:D,4,FALSE)),"") | H6: =IF(I6>0,(TEXT(I6,"yyyymmdd")&勤務統計!$V$2&A6&勤務統計!$V$2&B6&勤務統計!$S$2),"") -> PMQ1-4316-五股工商店(定保) | I6: {=IF(AND(SUMPRODUCT((IM!$F$2:$F$5000=A6)*(ISNUMBER(SEARCH(勤務統計!$C$1, IM!$AC$2:$AC$5000))))>0), 勤務統計!$C$1, "")} -> PMQ1 | J6: {=IFERROR(INDEX(IM!$AM$2:$AM$5000, MATCH(1, (IM!$F$2:$F$5000=A6) * (ISNUMBER(SEARCH(勤務統計!$C$1, IM!$AC$2:$AC$5000))), 0)), "")} -> 46024 | K6: {=SUMPRODUCT((IM!$F$2:$F$5000=A6)*(IM!$AD$2:$AD$5000="O")*(ISNUMBER(SEARCH(勤務統計!$C$1, IM!$AC$2:$AC$5000))))} -> 1 | L6: {=IF(K6>0,IFERROR(HYPERLINK("#'IM'!AC"&MATCH(1,(IM!$F$1:$F$5000=A6)*(ISNUMBER(SEARCH(勤務統計!$C$1,IM!$AC$1:$AC$5000))),0),"檢核"),"未登錄"),"")} -> 檢核 | M6: =Q6&S6&U6 -> +L90+721 | N6: {=IF(AND( SUMPRODUCT( (IM!$F$2:$F$522=A6) * ISNUMBER(SEARCH("*HUB*", IM!$AC$2:$AC$522)) * (IM!$X$2:$X$522>=勤務統計!$A$1) * (IM!$X$2:$X$522<=勤務統計!$B$1)*(W6="HUB") ) > 0 ), "HUB", "")} | O6: =IF( IFERROR(VLOOKUP(A6,勤務統計!A:I,9,FALSE),"")<>勤務統計!$C$1, "未完工", IF( AND(勤務統計!$D$1="--",勤務統計!$E$1="--",勤務統計!$F$1="--"), "已完工", IF( OR( AND(勤務統計!$D$1<>"--", IFERROR(VLOOKUP(A6,'0919門市清單主檔'!B:AH,31,FALSE),"")=勤務統計!$D$1, IFERROR(VLOOKUP(A6,勤務統計!A:Q,17,FALSE),"")<>勤務統計!$D$1), AND(勤務統計!$E$1<>"--", IFERROR(VLOOKUP(A6,'0919門市清單主檔'!B:AH,32,FALSE),"")=勤務統計!$E$1, IFERROR(VLOOKUP(A6,勤務統計!A:S,19,FALSE),"")<>勤務統計!$E$1), AND(勤務統計!$F$1<>"--", IFERROR(VLOOKUP(A6,'0919門市清單主檔'!B:AH,33,FALSE),"")=勤務統計!$F$1, IFERROR(VLOOKUP(A6,勤務統計!A:U,21,FALSE),"")<>勤務統計!$F$1), AND(IFERROR(VLOOKUP(A6,'0919門市清單主檔'!B:AH,28,FALSE),"")="HUB", IFERROR(VLOOKUP(A6,勤務統計!A:W,23,FALSE),"")<>"HUB") ), _xlfn.TEXTJOIN( "，", TRUE, IF(AND(勤務統計!$D$1<>"--", IFERROR(VLOOKUP(A6,'0919門市清單主檔'!B:AH,31,FALSE),"")=勤務統計!$D$1, IFERROR(VLOOKUP(A6,勤務統計!A:Q,17,FALSE),"")<>勤務統計!$D$1), 勤務統計!$D$1, ""), IF(AND(勤務統計!$E$1<>"--", IFERROR(VLOOKUP(A6,'0919門市清單主檔'!B:AH,32,FALSE),"")=勤務統計!$E$1, IFERROR(VLOOKUP(A6,勤務統計!A:S,19,FALSE),"")<>勤務統計!$E$1), 勤務統計!$E$1, ""), IF(AND(勤務統計!$F$1<>"--", IFERROR(VLOOKUP(A6,'0919門市清單主檔'!B:AH,33,FALSE),"")=勤務統計!$F$1, IFERROR(VLOOKUP(A6,勤務統計!A:U,21,FALSE),"")<>勤務統計!$F$1), 勤務統計!$F$1, ""), IF(AND(IFERROR(VLOOKUP(A6,'0919門市清單主檔'!B:AH,28,FALSE),"")="HUB", IFERROR(VLOOKUP(A6,勤務統計!A:W,23,FALSE),"")<>"HUB"), "HUB", "") ) & "未完工", "已完工" ) ) ) -> 未完工 | P6: =(TEXT(I6,"yyyymmdd"))&勤務統計!$V$2&A6&勤務統計!$V$2&B6&勤務統計!$S$2 -> PMQ1-4316-五股工商店(定保) | Q6: {=IF(AND(SUMPRODUCT((IM!$F$2:$F$5000=A6)*(ISNUMBER(SEARCH(勤務統計!$D$1, IM!$AC$2:$AC$5000))))>0), 勤務統計!$D$1, "")} | R6: {=IFERROR(INDEX(IM!$AM$2:$AM$5000, MATCH(1, (IM!$F$2:$F$5000=A6) * (ISNUMBER(SEARCH(勤務統計!$D$1, IM!$AC$2:$AC$5000))), 0)), "")} | S6: {=IF(AND(SUMPRODUCT((IM!$F$2:$F$5000=A6)*(ISNUMBER(SEARCH(勤務統計!$E$1, IM!$AC$2:$AC$5000))))>0), 勤務統計!$E$1, "")} -> +L90 | T6: {=IFERROR(INDEX(IM!$AM$2:$AM$5000, MATCH(1, (IM!$F$2:$F$5000=A6) * (ISNUMBER(SEARCH(勤務統計!$E$1, IM!$AC$2:$AC$5000))), 0)), "")} -> 45964 | U6: {=IF(AND(SUMPRODUCT((IM!$F$2:$F$5000=A6)*(ISNUMBER(SEARCH(勤務統計!$F$1, IM!$AC$2:$AC$5000))))>0), 勤務統計!$F$1, "")} -> +721 | V6: {=IFERROR(INDEX(IM!$AM$2:$AM$5000, MATCH(1, (IM!$F$2:$F$5000=A6) * (ISNUMBER(SEARCH(勤務統計!$F$1, IM!$AC$2:$AC$5000))), 0)), "")} -> 46024 | W6: =IF(VLOOKUP(A6,'0919門市清單主檔'!B:AC,28,FALSE)=0,"",VLOOKUP(A6,'0919門市清單主檔'!B:AC,28,FALSE))
A7: 4788 | B7: =VLOOKUP(A7,'0919門市清單主檔'!B:C,2,FALSE) -> 淡水國家店 | C7: =VLOOKUP($A7,'0919門市清單主檔'!B:V,20,FALSE) -> 新北市 | D7: =VLOOKUP($A7,'0919門市清單主檔'!B:V,21,FALSE) -> 淡水區 | E7: =VLOOKUP(D7,門市狀態!G:H,2,FALSE) -> 吳宗鴻 | F7: =IFERROR(IF(VLOOKUP(A7,門市狀態!A:D,4,FALSE)=0,"",VLOOKUP(A7,門市狀態!A:D,4,FALSE)),"") | H7: =IF(I7>0,(TEXT(I7,"yyyymmdd")&勤務統計!$V$2&A7&勤務統計!$V$2&B7&勤務統計!$S$2),"") -> PMQ1-4788-淡水國家店(定保) | I7: {=IF(AND(SUMPRODUCT((IM!$F$2:$F$5000=A7)*(ISNUMBER(SEARCH(勤務統計!$C$1, IM!$AC$2:$AC$5000))))>0), 勤務統計!$C$1, "")} -> PMQ1 | J7: {=IFERROR(INDEX(IM!$AM$2:$AM$5000, MATCH(1, (IM!$F$2:$F$5000=A7) * (ISNUMBER(SEARCH(勤務統計!$C$1, IM!$AC$2:$AC$5000))), 0)), "")} -> 46024 | K7: {=SUMPRODUCT((IM!$F$2:$F$5000=A7)*(IM!$AD$2:$AD$5000="O")*(ISNUMBER(SEARCH(勤務統計!$C$1, IM!$AC$2:$AC$5000))))} -> 1 | L7: {=IF(K7>0,IFERROR(HYPERLINK("#'IM'!AC"&MATCH(1,(IM!$F$1:$F$5000=A7)*(ISNUMBER(SEARCH(勤務統計!$C$1,IM!$AC$1:$AC$5000))),0),"檢核"),"未登錄"),"")} -> 檢核 | M7: =Q7&S7&U7 -> +L90+721 | N7: {=IF(AND( SUMPRODUCT( (IM!$F$2:$F$522=A7) * ISNUMBER(SEARCH("*HUB*", IM!$AC$2:$AC$522)) * (IM!$X$2:$X$522>=勤務統計!$A$1) * (IM!$X$2:$X$522<=勤務統計!$B$1)*(W7="HUB") ) > 0 ), "HUB", "")} | O7: =IF( IFERROR(VLOOKUP(A7,勤務統計!A:I,9,FALSE),"")<>勤務統計!$C$1, "未完工", IF( AND(勤務統計!$D$1="--",勤務統計!$E$1="--",勤務統計!$F$1="--"), "已完工", IF( OR( AND(勤務統計!$D$1<>"--", IFERROR(VLOOKUP(A7,'0919門市清單主檔'!B:AH,31,FALSE),"")=勤務統計!$D$1, IFERROR(VLOOKUP(A7,勤務統計!A:Q,17,FALSE),"")<>勤務統計!$D$1), AND(勤務統計!$E$1<>"--", IFERROR(VLOOKUP(A7,'0919門市清單主檔'!B:AH,32,FALSE),"")=勤務統計!$E$1, IFERROR(VLOOKUP(A7,勤務統計!A:S,19,FALSE),"")<>勤務統計!$E$1), AND(勤務統計!$F$1<>"--", IFERROR(VLOOKUP(A7,'0919門市清單主檔'!B:AH,33,FALSE),"")=勤務統計!$F$1, IFERROR(VLOOKUP(A7,勤務統計!A:U,21,FALSE),"")<>勤務統計!$F$1), AND(IFERROR(VLOOKUP(A7,'0919門市清單主檔'!B:AH,28,FALSE),"")="HUB", IFERROR(VLOOKUP(A7,勤務統計!A:W,23,FALSE),"")<>"HUB") ), _xlfn.TEXTJOIN( "，", TRUE, IF(AND(勤務統計!$D$1<>"--", IFERROR(VLOOKUP(A7,'0919門市清單主檔'!B:AH,31,FALSE),"")=勤務統計!$D$1, IFERROR(VLOOKUP(A7,勤務統計!A:Q,17,FALSE),"")<>勤務統計!$D$1), 勤務統計!$D$1, ""), IF(AND(勤務統計!$E$1<>"--", IFERROR(VLOOKUP(A7,'0919門市清單主檔'!B:AH,32,FALSE),"")=勤務統計!$E$1, IFERROR(VLOOKUP(A7,勤務統計!A:S,19,FALSE),"")<>勤務統計!$E$1), 勤務統計!$E$1, ""), IF(AND(勤務統計!$F$1<>"--", IFERROR(VLOOKUP(A7,'0919門市清單主檔'!B:AH,33,FALSE),"")=勤務統計!$F$1, IFERROR(VLOOKUP(A7,勤務統計!A:U,21,FALSE),"")<>勤務統計!$F$1), 勤務統計!$F$1, ""), IF(AND(IFERROR(VLOOKUP(A7,'0919門市清單主檔'!B:AH,28,FALSE),"")="HUB", IFERROR(VLOOKUP(A7,勤務統計!A:W,23,FALSE),"")<>"HUB"), "HUB", "") ) & "未完工", "已完工" ) ) ) -> 未完工 | P7: =(TEXT(I7,"yyyymmdd"))&勤務統計!$V$2&A7&勤務統計!$V$2&B7&勤務統計!$S$2 -> PMQ1-4788-淡水國家店(定保) | Q7: {=IF(AND(SUMPRODUCT((IM!$F$2:$F$5000=A7)*(ISNUMBER(SEARCH(勤務統計!$D$1, IM!$AC$2:$AC$5000))))>0), 勤務統計!$D$1, "")} | R7: {=IFERROR(INDEX(IM!$AM$2:$AM$5000, MATCH(1, (IM!$F$2:$F$5000=A7) * (ISNUMBER(SEARCH(勤務統計!$D$1, IM!$AC$2:$AC$5000))), 0)), "")} | S7: {=IF(AND(SUMPRODUCT((IM!$F$2:$F$5000=A7)*(ISNUMBER(SEARCH(勤務統計!$E$1, IM!$AC$2:$AC$5000))))>0), 勤務統計!$E$1, "")} -> +L90 | T7: {=IFERROR(INDEX(IM!$AM$2:$AM$5000, MATCH(1, (IM!$F$2:$F$5000=A7) * (ISNUMBER(SEARCH(勤務統計!$E$1, IM!$AC$2:$AC$5000))), 0)), "")} -> 46000 | U7: {=IF(AND(SUMPRODUCT((IM!$F$2:$F$5000=A7)*(ISNUMBER(SEARCH(勤務統計!$F$1, IM!$AC$2:$AC$5000))))>0), 勤務統計!$F$1, "")} -> +721 | V7: {=IFERROR(INDEX(IM!$AM$2:$AM$5000, MATCH(1, (IM!$F$2:$F$5000=A7) * (ISNUMBER(SEARCH(勤務統計!$F$1, IM!$AC$2:$AC$5000))), 0)), "")} -> 46024 | W7: =IF(VLOOKUP(A7,'0919門市清單主檔'!B:AC,28,FALSE)=0,"",VLOOKUP(A7,'0919門市清單主檔'!B:AC,28,FALSE))
A8: 4852 | B8: =VLOOKUP(A8,'0919門市清單主檔'!B:C,2,FALSE) -> 蘆竹福祿店 | C8: =VLOOKUP($A8,'0919門市清單主檔'!B:V,20,FALSE) -> 桃園市 | D8: =VLOOKUP($A8,'0919門市清單主檔'!B:V,21,FALSE) -> 蘆竹區 | E8: =VLOOKUP(D8,門市狀態!G:H,2,FALSE) -> 吳宗鴻 | F8: =IFERROR(IF(VLOOKUP(A8,門市狀態!A:D,4,FALSE)=0,"",VLOOKUP(A8,門市狀態!A:D,4,FALSE)),"") | H8: =IF(I8>0,(TEXT(I8,"yyyymmdd")&勤務統計!$V$2&A8&勤務統計!$V$2&B8&勤務統計!$S$2),"") -> PMQ1-4852-蘆竹福祿店(定保) | I8: {=IF(AND(SUMPRODUCT((IM!$F$2:$F$5000=A8)*(ISNUMBER(SEARCH(勤務統計!$C$1, IM!$AC$2:$AC$5000))))>0), 勤務統計!$C$1, "")} -> PMQ1 | J8: {=IFERROR(INDEX(IM!$AM$2:$AM$5000, MATCH(1, (IM!$F$2:$F$5000=A8) * (ISNUMBER(SEARCH(勤務統計!$C$1, IM!$AC$2:$AC$5000))), 0)), "")} -> 46024 | K8: {=SUMPRODUCT((IM!$F$2:$F$5000=A8)*(IM!$AD$2:$AD$5000="O")*(ISNUMBER(SEARCH(勤務統計!$C$1, IM!$AC$2:$AC$5000))))} -> 1 | L8: {=IF(K8>0,IFERROR(HYPERLINK("#'IM'!AC"&MATCH(1,(IM!$F$1:$F$5000=A8)*(ISNUMBER(SEARCH(勤務統計!$C$1,IM!$AC$1:$AC$5000))),0),"檢核"),"未登錄"),"")} -> 檢核 | M8: =Q8&S8&U8 -> +L90+721 | N8: {=IF(AND( SUMPRODUCT( (IM!$F$2:$F$522=A8) * ISNUMBER(SEARCH("*HUB*", IM!$AC$2:$AC$522)) * (IM!$X$2:$X$522>=勤務統計!$A$1) * (IM!$X$2:$X$522<=勤務統計!$B$1)*(W8="HUB") ) > 0 ), "HUB", "")} | O8: =IF( IFERROR(VLOOKUP(A8,勤務統計!A:I,9,FALSE),"")<>勤務統計!$C$1, "未完工", IF( AND(勤務統計!$D$1="--",勤務統計!$E$1="--",勤務統計!$F$1="--"), "已完工", IF( OR( AND(勤務統計!$D$1<>"--", IFERROR(VLOOKUP(A8,'0919門市清單主檔'!B:AH,31,FALSE),"")=勤務統計!$D$1, IFERROR(VLOOKUP(A8,勤務統計!A:Q,17,FALSE),"")<>勤務統計!$D$1), AND(勤務統計!$E$1<>"--", IFERROR(VLOOKUP(A8,'0919門市清單主檔'!B:AH,32,FALSE),"")=勤務統計!$E$1, IFERROR(VLOOKUP(A8,勤務統計!A:S,19,FALSE),"")<>勤務統計!$E$1), AND(勤務統計!$F$1<>"--", IFERROR(VLOOKUP(A8,'0919門市清單主檔'!B:AH,33,FALSE),"")=勤務統計!$F$1, IFERROR(VLOOKUP(A8,勤務統計!A:U,21,FALSE),"")<>勤務統計!$F$1), AND(IFERROR(VLOOKUP(A8,'0919門市清單主檔'!B:AH,28,FALSE),"")="HUB", IFERROR(VLOOKUP(A8,勤務統計!A:W,23,FALSE),"")<>"HUB") ), _xlfn.TEXTJOIN( "，", TRUE, IF(AND(勤務統計!$D$1<>"--", IFERROR(VLOOKUP(A8,'0919門市清單主檔'!B:AH,31,FALSE),"")=勤務統計!$D$1, IFERROR(VLOOKUP(A8,勤務統計!A:Q,17,FALSE),"")<>勤務統計!$D$1), 勤務統計!$D$1, ""), IF(AND(勤務統計!$E$1<>"--", IFERROR(VLOOKUP(A8,'0919門市清單主檔'!B:AH,32,FALSE),"")=勤務統計!$E$1, IFERROR(VLOOKUP(A8,勤務統計!A:S,19,FALSE),"")<>勤務統計!$E$1), 勤務統計!$E$1, ""), IF(AND(勤務統計!$F$1<>"--", IFERROR(VLOOKUP(A8,'0919門市清單主檔'!B:AH,33,FALSE),"")=勤務統計!$F$1, IFERROR(VLOOKUP(A8,勤務統計!A:U,21,FALSE),"")<>勤務統計!$F$1), 勤務統計!$F$1, ""), IF(AND(IFERROR(VLOOKUP(A8,'0919門市清單主檔'!B:AH,28,FALSE),"")="HUB", IFERROR(VLOOKUP(A8,勤務統計!A:W,23,FALSE),"")<>"HUB"), "HUB", "") ) & "未完工", "已完工" ) ) ) -> 未完工 | P8: =(TEXT(I8,"yyyymmdd"))&勤務統計!$V$2&A8&勤務統計!$V$2&B8&勤務統計!$S$2 -> PMQ1-4852-蘆竹福祿店(定保) | Q8: {=IF(AND(SUMPRODUCT((IM!$F$2:$F$5000=A8)*(ISNUMBER(SEARCH(勤務統計!$D$1, IM!$AC$2:$AC$5000))))>0), 勤務統計!$D$1, "")} | R8: {=IFERROR(INDEX(IM!$AM$2:$AM$5000, MATCH(1, (IM!$F$2:$F$5000=A8) * (ISNUMBER(SEARCH(勤務統計!$D$1, IM!$AC$2:$AC$5000))), 0)), "")} | S8: {=IF(AND(SUMPRODUCT((IM!$F$2:$F$5000=A8)*(ISNUMBER(SEARCH(勤務統計!$E$1, IM!$AC$2:$AC$5000))))>0), 勤務統計!$E$1, "")} -> +L90 | T8: {=IFERROR(INDEX(IM!$AM$2:$AM$5000, MATCH(1, (IM!$F$2:$F$5000=A8) * (ISNUMBER(SEARCH(勤務統計!$E$1, IM!$AC$2:$AC$5000))), 0)), "")} -> 46024 | U8: {=IF(AND(SUMPRODUCT((IM!$F$2:$F$5000=A8)*(ISNUMBER(SEARCH(勤務統計!$F$1, IM!$AC$2:$AC$5000))))>0), 勤務統計!$F$1, "")} -> +721 | V8: {=IFERROR(INDEX(IM!$AM$2:$AM$5000, MATCH(1, (IM!$F$2:$F$5000=A8) * (ISNUMBER(SEARCH(勤務統計!$F$1, IM!$AC$2:$AC$5000))), 0)), "")} -> 46024 | W8: =IF(VLOOKUP(A8,'0919門市清單主檔'!B:AC,28,FALSE)=0,"",VLOOKUP(A8,'0919門市清單主檔'!B:AC,28,FALSE))
A9: 3913 | B9: =VLOOKUP(A9,'0919門市清單主檔'!B:C,2,FALSE) -> 中和和玉店 | C9: =VLOOKUP($A9,'0919門市清單主檔'!B:V,20,FALSE) -> 新北市 | D9: =VLOOKUP($A9,'0919門市清單主檔'!B:V,21,FALSE) -> 中和區 | E9: =VLOOKUP(D9,門市狀態!G:H,2,FALSE) -> 劉柏均 | F9: =IFERROR(IF(VLOOKUP(A9,門市狀態!A:D,4,FALSE)=0,"",VLOOKUP(A9,門市狀態!A:D,4,FALSE)),"") | H9: =IF(I9>0,(TEXT(I9,"yyyymmdd")&勤務統計!$V$2&A9&勤務統計!$V$2&B9&勤務統計!$S$2),"") -> PMQ1-3913-中和和玉店(定保) | I9: {=IF(AND(SUMPRODUCT((IM!$F$2:$F$5000=A9)*(ISNUMBER(SEARCH(勤務統計!$C$1, IM!$AC$2:$AC$5000))))>0), 勤務統計!$C$1, "")} -> PMQ1 | J9: {=IFERROR(INDEX(IM!$AM$2:$AM$5000, MATCH(1, (IM!$F$2:$F$5000=A9) * (ISNUMBER(SEARCH(勤務統計!$C$1, IM!$AC$2:$AC$5000))), 0)), "")} -> 46024 | K9: {=SUMPRODUCT((IM!$F$2:$F$5000=A9)*(IM!$AD$2:$AD$5000="O")*(ISNUMBER(SEARCH(勤務統計!$C$1, IM!$AC$2:$AC$5000))))} -> 1 | L9: {=IF(K9>0,IFERROR(HYPERLINK("#'IM'!AC"&MATCH(1,(IM!$F$1:$F$5000=A9)*(ISNUMBER(SEARCH(勤務統計!$C$1,IM!$AC$1:$AC$5000))),0),"檢核"),"未登錄"),"")} -> 檢核 | M9: =Q9&S9&U9 -> +721 | N9: {=IF(AND( SUMPRODUCT( (IM!$F$2:$F$522=A9) * ISNUMBER(SEARCH("*HUB*", IM!$AC$2:$AC$522)) * (IM!$X$2:$X$522>=勤務統計!$A$1) * (IM!$X$2:$X$522<=勤務統計!$B$1)*(W9="HUB") ) > 0 ), "HUB", "")} | O9: =IF( IFERROR(VLOOKUP(A9,勤務統計!A:I,9,FALSE),"")<>勤務統計!$C$1, "未完工", IF( AND(勤務統計!$D$1="--",勤務統計!$E$1="--",勤務統計!$F$1="--"), "已完工", IF( OR( AND(勤務統計!$D$1<>"--", IFERROR(VLOOKUP(A9,'0919門市清單主檔'!B:AH,31,FALSE),"")=勤務統計!$D$1, IFERROR(VLOOKUP(A9,勤務統計!A:Q,17,FALSE),"")<>勤務統計!$D$1), AND(勤務統計!$E$1<>"--", IFERROR(VLOOKUP(A9,'0919門市清單主檔'!B:AH,32,FALSE),"")=勤務統計!$E$1, IFERROR(VLOOKUP(A9,勤務統計!A:S,19,FALSE),"")<>勤務統計!$E$1), AND(勤務統計!$F$1<>"--", IFERROR(VLOOKUP(A9,'0919門市清單主檔'!B:AH,33,FALSE),"")=勤務統計!$F$1, IFERROR(VLOOKUP(A9,勤務統計!A:U,21,FALSE),"")<>勤務統計!$F$1), AND(IFERROR(VLOOKUP(A9,'0919門市清單主檔'!B:AH,28,FALSE),"")="HUB", IFERROR(VLOOKUP(A9,勤務統計!A:W,23,FALSE),"")<>"HUB") ), _xlfn.TEXTJOIN( "，", TRUE, IF(AND(勤務統計!$D$1<>"--", IFERROR(VLOOKUP(A9,'0919門市清單主檔'!B:AH,31,FALSE),"")=勤務統計!$D$1, IFERROR(VLOOKUP(A9,勤務統計!A:Q,17,FALSE),"")<>勤務統計!$D$1), 勤務統計!$D$1, ""), IF(AND(勤務統計!$E$1<>"--", IFERROR(VLOOKUP(A9,'0919門市清單主檔'!B:AH,32,FALSE),"")=勤務統計!$E$1, IFERROR(VLOOKUP(A9,勤務統計!A:S,19,FALSE),"")<>勤務統計!$E$1), 勤務統計!$E$1, ""), IF(AND(勤務統計!$F$1<>"--", IFERROR(VLOOKUP(A9,'0919門市清單主檔'!B:AH,33,FALSE),"")=勤務統計!$F$1, IFERROR(VLOOKUP(A9,勤務統計!A:U,21,FALSE),"")<>勤務統計!$F$1), 勤務統計!$F$1, ""), IF(AND(IFERROR(VLOOKUP(A9,'0919門市清單主檔'!B:AH,28,FALSE),"")="HUB", IFERROR(VLOOKUP(A9,勤務統計!A:W,23,FALSE),"")<>"HUB"), "HUB", "") ) & "未完工", "已完工" ) ) ) -> 未完工 | P9: =(TEXT(I9,"yyyymmdd"))&勤務統計!$V$2&A9&勤務統計!$V$2&B9&勤務統計!$S$2 -> PMQ1-3913-中和和玉店(定保) | Q9: {=IF(AND(SUMPRODUCT((IM!$F$2:$F$5000=A9)*(ISNUMBER(SEARCH(勤務統計!$D$1, IM!$AC$2:$AC$5000))))>0), 勤務統計!$D$1, "")} | R9: {=IFERROR(INDEX(IM!$AM$2:$AM$5000, MATCH(1, (IM!$F$2:$F$5000=A9) * (ISNUMBER(SEARCH(勤務統計!$D$1, IM!$AC$2:$AC$5000))), 0)), "")} | S9: {=IF(AND(SUMPRODUCT((IM!$F$2:$F$5000=A9)*(ISNUMBER(SEARCH(勤務統計!$E$1, IM!$AC$2:$AC$5000))))>0), 勤務統計!$E$1, "")} | T9: {=IFERROR(INDEX(IM!$AM$2:$AM$5000, MATCH(1, (IM!$F$2:$F$5000=A9) * (ISNUMBER(SEARCH(勤務統計!$E$1, IM!$AC$2:$AC$5000))), 0)), "")} | U9: {=IF(AND(SUMPRODUCT((IM!$F$2:$F$5000=A9)*(ISNUMBER(SEARCH(勤務統計!$F$1, IM!$AC$2:$AC$5000))))>0), 勤務統計!$F$1, "")} -> +721 | V9: {=IFERROR(INDEX(IM!$AM$2:$AM$5000, MATCH(1, (IM!$F$2:$F$5000=A9) * (ISNUMBER(SEARCH(勤務統計!$F$1, IM!$AC$2:$AC$5000))), 0)), "")} -> 46024 | W9: =IF(VLOOKUP(A9,'0919門市清單主檔'!B:AC,28,FALSE)=0,"",VLOOKUP(A9,'0919門市清單主檔'!B:AC,28,FALSE))
A10: 2375 | B10: =VLOOKUP(A10,'0919門市清單主檔'!B:C,2,FALSE) -> 桃縣桃貿店 | C10: =VLOOKUP($A10,'0919門市清單主檔'!B:V,20,FALSE) -> 桃園市 | D10: =VLOOKUP($A10,'0919門市清單主檔'!B:V,21,FALSE) -> 龜山區 | E10: =VLOOKUP(D10,門市狀態!G:H,2,FALSE) -> 吳宗鴻 | F10: =IFERROR(IF(VLOOKUP(A10,門市狀態!A:D,4,FALSE)=0,"",VLOOKUP(A10,門市狀態!A:D,4,FALSE)),"") | H10: =IF(I10>0,(TEXT(I10,"yyyymmdd")&勤務統計!$V$2&A10&勤務統計!$V$2&B10&勤務統計!$S$2),"") -> PMQ1-2375-桃縣桃貿店(定保) | I10: {=IF(AND(SUMPRODUCT((IM!$F$2:$F$5000=A10)*(ISNUMBER(SEARCH(勤務統計!$C$1, IM!$AC$2:$AC$5000))))>0), 勤務統計!$C$1, "")} -> PMQ1 | J10: {=IFERROR(INDEX(IM!$AM$2:$AM$5000, MATCH(1, (IM!$F$2:$F$5000=A10) * (ISNUMBER(SEARCH(勤務統計!$C$1, IM!$AC$2:$AC$5000))), 0)), "")} -> 46027 | K10: {=SUMPRODUCT((IM!$F$2:$F$5000=A10)*(IM!$AD$2:$AD$5000="O")*(ISNUMBER(SEARCH(勤務統計!$C$1, IM!$AC$2:$AC$5000))))} -> 1 | L10: {=IF(K10>0,IFERROR(HYPERLINK("#'IM'!AC"&MATCH(1,(IM!$F$1:$F$5000=A10)*(ISNUMBER(SEARCH(勤務統計!$C$1,IM!$AC$1:$AC$5000))),0),"檢核"),"未登錄"),"")} -> 檢核 | M10: =Q10&S10&U10 -> +L90+721 | N10: {=IF(AND( SUMPRODUCT( (IM!$F$2:$F$522=A10) * ISNUMBER(SEARCH("*HUB*", IM!$AC$2:$AC$522)) * (IM!$X$2:$X$522>=勤務統計!$A$1) * (IM!$X$2:$X$522<=勤務統計!$B$1)*(W10="HUB") ) > 0 ), "HUB", "")} | O10: =IF( IFERROR(VLOOKUP(A10,勤務統計!A:I,9,FALSE),"")<>勤務統計!$C$1, "未完工", IF( AND(勤務統計!$D$1="--",勤務統計!$E$1="--",勤務統計!$F$1="--"), "已完工", IF( OR( AND(勤務統計!$D$1<>"--", IFERROR(VLOOKUP(A10,'0919門市清單主檔'!B:AH,31,FALSE),"")=勤務統計!$D$1, IFERROR(VLOOKUP(A10,勤務統計!A:Q,17,FALSE),"")<>勤務統計!$D$1), AND(勤務統計!$E$1<>"--", IFERROR(VLOOKUP(A10,'0919門市清單主檔'!B:AH,32,FALSE),"")=勤務統計!$E$1, IFERROR(VLOOKUP(A10,勤務統計!A:S,19,FALSE),"")<>勤務統計!$E$1), AND(勤務統計!$F$1<>"--", IFERROR(VLOOKUP(A10,'0919門市清單主檔'!B:AH,33,FALSE),"")=勤務統計!$F$1, IFERROR(VLOOKUP(A10,勤務統計!A:U,21,FALSE),"")<>勤務統計!$F$1), AND(IFERROR(VLOOKUP(A10,'0919門市清單主檔'!B:AH,28,FALSE),"")="HUB", IFERROR(VLOOKUP(A10,勤務統計!A:W,23,FALSE),"")<>"HUB") ), _xlfn.TEXTJOIN( "，", TRUE, IF(AND(勤務統計!$D$1<>"--", IFERROR(VLOOKUP(A10,'0919門市清單主檔'!B:AH,31,FALSE),"")=勤務統計!$D$1, IFERROR(VLOOKUP(A10,勤務統計!A:Q,17,FALSE),"")<>勤務統計!$D$1), 勤務統計!$D$1, ""), IF(AND(勤務統計!$E$1<>"--", IFERROR(VLOOKUP(A10,'0919門市清單主檔'!B:AH,32,FALSE),"")=勤務統計!$E$1, IFERROR(VLOOKUP(A10,勤務統計!A:S,19,FALSE),"")<>勤務統計!$E$1), 勤務統計!$E$1, ""), IF(AND(勤務統計!$F$1<>"--", IFERROR(VLOOKUP(A10,'0919門市清單主檔'!B:AH,33,FALSE),"")=勤務統計!$F$1, IFERROR(VLOOKUP(A10,勤務統計!A:U,21,FALSE),"")<>勤務統計!$F$1), 勤務統計!$F$1, ""), IF(AND(IFERROR(VLOOKUP(A10,'0919門市清單主檔'!B:AH,28,FALSE),"")="HUB", IFERROR(VLOOKUP(A10,勤務統計!A:W,23,FALSE),"")<>"HUB"), "HUB", "") ) & "未完工", "已完工" ) ) ) -> 未完工 | P10: =(TEXT(I10,"yyyymmdd"))&勤務統計!$V$2&A10&勤務統計!$V$2&B10&勤務統計!$S$2 -> PMQ1-2375-桃縣桃貿店(定保) | Q10: {=IF(AND(SUMPRODUCT((IM!$F$2:$F$5000=A10)*(ISNUMBER(SEARCH(勤務統計!$D$1, IM!$AC$2:$AC$5000))))>0), 勤務統計!$D$1, "")} | R10: {=IFERROR(INDEX(IM!$AM$2:$AM$5000, MATCH(1, (IM!$F$2:$F$5000=A10) * (ISNUMBER(SEARCH(勤務統計!$D$1, IM!$AC$2:$AC$5000))), 0)), "")} | S10: {=IF(AND(SUMPRODUCT((IM!$F$2:$F$5000=A10)*(ISNUMBER(SEARCH(勤務統計!$E$1, IM!$AC$2:$AC$5000))))>0), 勤務統計!$E$1, "")} -> +L90 | T10: {=IFERROR(INDEX(IM!$AM$2:$AM$5000, MATCH(1, (IM!$F$2:$F$5000=A10) * (ISNUMBER(SEARCH(勤務統計!$E$1, IM!$AC$2:$AC$5000))), 0)), "")} -> 46027 | U10: {=IF(AND(SUMPRODUCT((IM!$F$2:$F$5000=A10)*(ISNUMBER(SEARCH(勤務統計!$F$1, IM!$AC$2:$AC$5000))))>0), 勤務統計!$F$1, "")} -> +721 | V10: {=IFERROR(INDEX(IM!$AM$2:$AM$5000, MATCH(1, (IM!$F$2:$F$5000=A10) * (ISNUMBER(SEARCH(勤務統計!$F$1, IM!$AC$2:$AC$5000))), 0)), "")} -> 46027 | W10: =IF(VLOOKUP(A10,'0919門市清單主檔'!B:AC,28,FALSE)=0,"",VLOOKUP(A10,'0919門市清單主檔'!B:AC,28,FALSE))
A11: 3017 | B11: =VLOOKUP(A11,'0919門市清單主檔'!B:C,2,FALSE) -> 龜山大同店 | C11: =VLOOKUP($A11,'0919門市清單主檔'!B:V,20,FALSE) -> 桃園市 | D11: =VLOOKUP($A11,'0919門市清單主檔'!B:V,21,FALSE) -> 龜山區 | E11: =VLOOKUP(D11,門市狀態!G:H,2,FALSE) -> 吳宗鴻 | F11: =IFERROR(IF(VLOOKUP(A11,門市狀態!A:D,4,FALSE)=0,"",VLOOKUP(A11,門市狀態!A:D,4,FALSE)),"") | H11: =IF(I11>0,(TEXT(I11,"yyyymmdd")&勤務統計!$V$2&A11&勤務統計!$V$2&B11&勤務統計!$S$2),"") -> PMQ1-3017-龜山大同店(定保) | I11: {=IF(AND(SUMPRODUCT((IM!$F$2:$F$5000=A11)*(ISNUMBER(SEARCH(勤務統計!$C$1, IM!$AC$2:$AC$5000))))>0), 勤務統計!$C$1, "")} -> PMQ1 | J11: {=IFERROR(INDEX(IM!$AM$2:$AM$5000, MATCH(1, (IM!$F$2:$F$5000=A11) * (ISNUMBER(SEARCH(勤務統計!$C$1, IM!$AC$2:$AC$5000))), 0)), "")} -> 46027 | K11: {=SUMPRODUCT((IM!$F$2:$F$5000=A11)*(IM!$AD$2:$AD$5000="O")*(ISNUMBER(SEARCH(勤務統計!$C$1, IM!$AC$2:$AC$5000))))} -> 1 | L11: {=IF(K11>0,IFERROR(HYPERLINK("#'IM'!AC"&MATCH(1,(IM!$F$1:$F$5000=A11)*(ISNUMBER(SEARCH(勤務統計!$C$1,IM!$AC$1:$AC$5000))),0),"檢核"),"未登錄"),"")} -> 檢核 | M11: =Q11&S11&U11 -> +L90+721 | N11: {=IF(AND( SUMPRODUCT( (IM!$F$2:$F$522=A11) * ISNUMBER(SEARCH("*HUB*", IM!$AC$2:$AC$522)) * (IM!$X$2:$X$522>=勤務統計!$A$1) * (IM!$X$2:$X$522<=勤務統計!$B$1)*(W11="HUB") ) > 0 ), "HUB", "")} | O11: =IF( IFERROR(VLOOKUP(A11,勤務統計!A:I,9,FALSE),"")<>勤務統計!$C$1, "未完工", IF( AND(勤務統計!$D$1="--",勤務統計!$E$1="--",勤務統計!$F$1="--"), "已完工", IF( OR( AND(勤務統計!$D$1<>"--", IFERROR(VLOOKUP(A11,'0919門市清單主檔'!B:AH,31,FALSE),"")=勤務統計!$D$1, IFERROR(VLOOKUP(A11,勤務統計!A:Q,17,FALSE),"")<>勤務統計!$D$1), AND(勤務統計!$E$1<>"--", IFERROR(VLOOKUP(A11,'0919門市清單主檔'!B:AH,32,FALSE),"")=勤務統計!$E$1, IFERROR(VLOOKUP(A11,勤務統計!A:S,19,FALSE),"")<>勤務統計!$E$1), AND(勤務統計!$F$1<>"--", IFERROR(VLOOKUP(A11,'0919門市清單主檔'!B:AH,33,FALSE),"")=勤務統計!$F$1, IFERROR(VLOOKUP(A11,勤務統計!A:U,21,FALSE),"")<>勤務統計!$F$1), AND(IFERROR(VLOOKUP(A11,'0919門市清單主檔'!B:AH,28,FALSE),"")="HUB", IFERROR(VLOOKUP(A11,勤務統計!A:W,23,FALSE),"")<>"HUB") ), _xlfn.TEXTJOIN( "，", TRUE, IF(AND(勤務統計!$D$1<>"--", IFERROR(VLOOKUP(A11,'0919門市清單主檔'!B:AH,31,FALSE),"")=勤務統計!$D$1, IFERROR(VLOOKUP(A11,勤務統計!A:Q,17,FALSE),"")<>勤務統計!$D$1), 勤務統計!$D$1, ""), IF(AND(勤務統計!$E$1<>"--", IFERROR(VLOOKUP(A11,'0919門市清單主檔'!B:AH,32,FALSE),"")=勤務統計!$E$1, IFERROR(VLOOKUP(A11,勤務統計!A:S,19,FALSE),"")<>勤務統計!$E$1), 勤務統計!$E$1, ""), IF(AND(勤務統計!$F$1<>"--", IFERROR(VLOOKUP(A11,'0919門市清單主檔'!B:AH,33,FALSE),"")=勤務統計!$F$1, IFERROR(VLOOKUP(A11,勤務統計!A:U,21,FALSE),"")<>勤務統計!$F$1), 勤務統計!$F$1, ""), IF(AND(IFERROR(VLOOKUP(A11,'0919門市清單主檔'!B:AH,28,FALSE),"")="HUB", IFERROR(VLOOKUP(A11,勤務統計!A:W,23,FALSE),"")<>"HUB"), "HUB", "") ) & "未完工", "已完工" ) ) ) -> 未完工 | P11: =(TEXT(I11,"yyyymmdd"))&勤務統計!$V$2&A11&勤務統計!$V$2&B11&勤務統計!$S$2 -> PMQ1-3017-龜山大同店(定保) | Q11: {=IF(AND(SUMPRODUCT((IM!$F$2:$F$5000=A11)*(ISNUMBER(SEARCH(勤務統計!$D$1, IM!$AC$2:$AC$5000))))>0), 勤務統計!$D$1, "")} | R11: {=IFERROR(INDEX(IM!$AM$2:$AM$5000, MATCH(1, (IM!$F$2:$F$5000=A11) * (ISNUMBER(SEARCH(勤務統計!$D$1, IM!$AC$2:$AC$5000))), 0)), "")} | S11: {=IF(AND(SUMPRODUCT((IM!$F$2:$F$5000=A11)*(ISNUMBER(SEARCH(勤務統計!$E$1, IM!$AC$2:$AC$5000))))>0), 勤務統計!$E$1, "")} -> +L90 | T11: {=IFERROR(INDEX(IM!$AM$2:$AM$5000, MATCH(1, (IM!$F$2:$F$5000=A11) * (ISNUMBER(SEARCH(勤務統計!$E$1, IM!$AC$2:$AC$5000))), 0)), "")} -> 46027 | U11: {=IF(AND(SUMPRODUCT((IM!$F$2:$F$5000=A11)*(ISNUMBER(SEARCH(勤務統計!$F$1, IM!$AC$2:$AC$5000))))>0), 勤務統計!$F$1, "")} -> +721 | V11: {=IFERROR(INDEX(IM!$AM$2:$AM$5000, MATCH(1, (IM!$F$2:$F$5000=A11) * (ISNUMBER(SEARCH(勤務統計!$F$1, IM!$AC$2:$AC$5000))), 0)), "")} -> 46027 | W11: =IF(VLOOKUP(A11,'0919門市清單主檔'!B:AC,28,FALSE)=0,"",VLOOKUP(A11,'0919門市清單主檔'!B:AC,28,FALSE))
A12: 4690 | B12: =VLOOKUP(A12,'0919門市清單主檔'!B:C,2,FALSE) -> 龜山同福店 | C12: =VLOOKUP($A12,'0919門市清單主檔'!B:V,20,FALSE) -> 桃園市 | D12: =VLOOKUP($A12,'0919門市清單主檔'!B:V,21,FALSE) -> 蘆竹區 | E12: =VLOOKUP(D12,門市狀態!G:H,2,FALSE) -> 吳宗鴻 | F12: =IFERROR(IF(VLOOKUP(A12,門市狀態!A:D,4,FALSE)=0,"",VLOOKUP(A12,門市狀態!A:D,4,FALSE)),"") | H12: =IF(I12>0,(TEXT(I12,"yyyymmdd")&勤務統計!$V$2&A12&勤務統計!$V$2&B12&勤務統計!$S$2),"") -> PMQ1-4690-龜山同福店(定保) | I12: {=IF(AND(SUMPRODUCT((IM!$F$2:$F$5000=A12)*(ISNUMBER(SEARCH(勤務統計!$C$1, IM!$AC$2:$AC$5000))))>0), 勤務統計!$C$1, "")} -> PMQ1 | J12: {=IFERROR(INDEX(IM!$AM$2:$AM$5000, MATCH(1, (IM!$F$2:$F$5000=A12) * (ISNUMBER(SEARCH(勤務統計!$C$1, IM!$AC$2:$AC$5000))), 0)), "")} -> 46027 | K12: {=SUMPRODUCT((IM!$F$2:$F$5000=A12)*(IM!$AD$2:$AD$5000="O")*(ISNUMBER(SEARCH(勤務統計!$C$1, IM!$AC$2:$AC$5000))))} -> 1 | L12: {=IF(K12>0,IFERROR(HYPERLINK("#'IM'!AC"&MATCH(1,(IM!$F$1:$F$5000=A12)*(ISNUMBER(SEARCH(勤務統計!$C$1,IM!$AC$1:$AC$5000))),0),"檢核"),"未登錄"),"")} -> 檢核 | M12: =Q12&S12&U12 -> +L90+721 | N12: {=IF(AND( SUMPRODUCT( (IM!$F$2:$F$522=A12) * ISNUMBER(SEARCH("*HUB*", IM!$AC$2:$AC$522)) * (IM!$X$2:$X$522>=勤務統計!$A$1) * (IM!$X$2:$X$522<=勤務統計!$B$1)*(W12="HUB") ) > 0 ), "HUB", "")} | O12: =IF( IFERROR(VLOOKUP(A12,勤務統計!A:I,9,FALSE),"")<>勤務統計!$C$1, "未完工", IF( AND(勤務統計!$D$1="--",勤務統計!$E$1="--",勤務統計!$F$1="--"), "已完工", IF( OR( AND(勤務統計!$D$1<>"--", IFERROR(VLOOKUP(A12,'0919門市清單主檔'!B:AH,31,FALSE),"")=勤務統計!$D$1, IFERROR(VLOOKUP(A12,勤務統計!A:Q,17,FALSE),"")<>勤務統計!$D$1), AND(勤務統計!$E$1<>"--", IFERROR(VLOOKUP(A12,'0919門市清單主檔'!B:AH,32,FALSE),"")=勤務統計!$E$1, IFERROR(VLOOKUP(A12,勤務統計!A:S,19,FALSE),"")<>勤務統計!$E$1), AND(勤務統計!$F$1<>"--", IFERROR(VLOOKUP(A12,'0919門市清單主檔'!B:AH,33,FALSE),"")=勤務統計!$F$1, IFERROR(VLOOKUP(A12,勤務統計!A:U,21,FALSE),"")<>勤務統計!$F$1), AND(IFERROR(VLOOKUP(A12,'0919門市清單主檔'!B:AH,28,FALSE),"")="HUB", IFERROR(VLOOKUP(A12,勤務統計!A:W,23,FALSE),"")<>"HUB") ), _xlfn.TEXTJOIN( "，", TRUE, IF(AND(勤務統計!$D$1<>"--", IFERROR(VLOOKUP(A12,'0919門市清單主檔'!B:AH,31,FALSE),"")=勤務統計!$D$1, IFERROR(VLOOKUP(A12,勤務統計!A:Q,17,FALSE),"")<>勤務統計!$D$1), 勤務統計!$D$1, ""), IF(AND(勤務統計!$E$1<>"--", IFERROR(VLOOKUP(A12,'0919門市清單主檔'!B:AH,32,FALSE),"")=勤務統計!$E$1, IFERROR(VLOOKUP(A12,勤務統計!A:S,19,FALSE),"")<>勤務統計!$E$1), 勤務統計!$E$1, ""), IF(AND(勤務統計!$F$1<>"--", IFERROR(VLOOKUP(A12,'0919門市清單主檔'!B:AH,33,FALSE),"")=勤務統計!$F$1, IFERROR(VLOOKUP(A12,勤務統計!A:U,21,FALSE),"")<>勤務統計!$F$1), 勤務統計!$F$1, ""), IF(AND(IFERROR(VLOOKUP(A12,'0919門市清單主檔'!B:AH,28,FALSE),"")="HUB", IFERROR(VLOOKUP(A12,勤務統計!A:W,23,FALSE),"")<>"HUB"), "HUB", "") ) & "未完工", "已完工" ) ) ) -> 未完工 | P12: =(TEXT(I12,"yyyymmdd"))&勤務統計!$V$2&A12&勤務統計!$V$2&B12&勤務統計!$S$2 -> PMQ1-4690-龜山同福店(定保) | Q12: {=IF(AND(SUMPRODUCT((IM!$F$2:$F$5000=A12)*(ISNUMBER(SEARCH(勤務統計!$D$1, IM!$AC$2:$AC$5000))))>0), 勤務統計!$D$1, "")} | R12: {=IFERROR(INDEX(IM!$AM$2:$AM$5000, MATCH(1, (IM!$F$2:$F$5000=A12) * (ISNUMBER(SEARCH(勤務統計!$D$1, IM!$AC$2:$AC$5000))), 0)), "")} | S12: {=IF(AND(SUMPRODUCT((IM!$F$2:$F$5000=A12)*(ISNUMBER(SEARCH(勤務統計!$E$1, IM!$AC$2:$AC$5000))))>0), 勤務統計!$E$1, "")} -> +L90 | T12: {=IFERROR(INDEX(IM!$AM$2:$AM$5000, MATCH(1, (IM!$F$2:$F$5000=A12) * (ISNUMBER(SEARCH(勤務統計!$E$1, IM!$AC$2:$AC$5000))), 0)), "")} -> 46027 | U12: {=IF(AND(SUMPRODUCT((IM!$F$2:$F$5000=A12)*(ISNUMBER(SEARCH(勤務統計!$F$1, IM!$AC$2:$AC$5000))))>0), 勤務統計!$F$1, "")} -> +721 | V12: {=IFERROR(INDEX(IM!$AM$2:$AM$5000, MATCH(1, (IM!$F$2:$F$5000=A12) * (ISNUMBER(SEARCH(勤務統計!$F$1, IM!$AC$2:$AC$5000))), 0)), "")} -> 46027 | W12: =IF(VLOOKUP(A12,'0919門市清單主檔'!B:AC,28,FALSE)=0,"",VLOOKUP(A12,'0919門市清單主檔'!B:AC,28,FALSE))
A13: 4825 | B13: =VLOOKUP(A13,'0919門市清單主檔'!B:C,2,FALSE) -> 龜山兔子坑 | C13: =VLOOKUP($A13,'0919門市清單主檔'!B:V,20,FALSE) -> 桃園市 | D13: =VLOOKUP($A13,'0919門市清單主檔'!B:V,21,FALSE) -> 蘆竹區 | E13: =VLOOKUP(D13,門市狀態!G:H,2,FALSE) -> 吳宗鴻 | F13: =IFERROR(IF(VLOOKUP(A13,門市狀態!A:D,4,FALSE)=0,"",VLOOKUP(A13,門市狀態!A:D,4,FALSE)),"") | H13: =IF(I13>0,(TEXT(I13,"yyyymmdd")&勤務統計!$V$2&A13&勤務統計!$V$2&B13&勤務統計!$S$2),"") -> PMQ1-4825-龜山兔子坑(定保) | I13: {=IF(AND(SUMPRODUCT((IM!$F$2:$F$5000=A13)*(ISNUMBER(SEARCH(勤務統計!$C$1, IM!$AC$2:$AC$5000))))>0), 勤務統計!$C$1, "")} -> PMQ1 | J13: {=IFERROR(INDEX(IM!$AM$2:$AM$5000, MATCH(1, (IM!$F$2:$F$5000=A13) * (ISNUMBER(SEARCH(勤務統計!$C$1, IM!$AC$2:$AC$5000))), 0)), "")} -> 46027 | K13: {=SUMPRODUCT((IM!$F$2:$F$5000=A13)*(IM!$AD$2:$AD$5000="O")*(ISNUMBER(SEARCH(勤務統計!$C$1, IM!$AC$2:$AC$5000))))} -> 1 | L13: {=IF(K13>0,IFERROR(HYPERLINK("#'IM'!AC"&MATCH(1,(IM!$F$1:$F$5000=A13)*(ISNUMBER(SEARCH(勤務統計!$C$1,IM!$AC$1:$AC$5000))),0),"檢核"),"未登錄"),"")} -> 檢核 | M13: =Q13&S13&U13 -> +L90+721 | N13: {=IF(AND( SUMPRODUCT( (IM!$F$2:$F$522=A13) * ISNUMBER(SEARCH("*HUB*", IM!$AC$2:$AC$522)) * (IM!$X$2:$X$522>=勤務統計!$A$1) * (IM!$X$2:$X$522<=勤務統計!$B$1)*(W13="HUB") ) > 0 ), "HUB", "")} | O13: =IF( IFERROR(VLOOKUP(A13,勤務統計!A:I,9,FALSE),"")<>勤務統計!$C$1, "未完工", IF( AND(勤務統計!$D$1="--",勤務統計!$E$1="--",勤務統計!$F$1="--"), "已完工", IF( OR( AND(勤務統計!$D$1<>"--", IFERROR(VLOOKUP(A13,'0919門市清單主檔'!B:AH,31,FALSE),"")=勤務統計!$D$1, IFERROR(VLOOKUP(A13,勤務統計!A:Q,17,FALSE),"")<>勤務統計!$D$1), AND(勤務統計!$E$1<>"--", IFERROR(VLOOKUP(A13,'0919門市清單主檔'!B:AH,32,FALSE),"")=勤務統計!$E$1, IFERROR(VLOOKUP(A13,勤務統計!A:S,19,FALSE),"")<>勤務統計!$E$1), AND(勤務統計!$F$1<>"--", IFERROR(VLOOKUP(A13,'0919門市清單主檔'!B:AH,33,FALSE),"")=勤務統計!$F$1, IFERROR(VLOOKUP(A13,勤務統計!A:U,21,FALSE),"")<>勤務統計!$F$1), AND(IFERROR(VLOOKUP(A13,'0919門市清單主檔'!B:AH,28,FALSE),"")="HUB", IFERROR(VLOOKUP(A13,勤務統計!A:W,23,FALSE),"")<>"HUB") ), _xlfn.TEXTJOIN( "，", TRUE, IF(AND(勤務統計!$D$1<>"--", IFERROR(VLOOKUP(A13,'0919門市清單主檔'!B:AH,31,FALSE),"")=勤務統計!$D$1, IFERROR(VLOOKUP(A13,勤務統計!A:Q,17,FALSE),"")<>勤務統計!$D$1), 勤務統計!$D$1, ""), IF(AND(勤務統計!$E$1<>"--", IFERROR(VLOOKUP(A13,'0919門市清單主檔'!B:AH,32,FALSE),"")=勤務統計!$E$1, IFERROR(VLOOKUP(A13,勤務統計!A:S,19,FALSE),"")<>勤務統計!$E$1), 勤務統計!$E$1, ""), IF(AND(勤務統計!$F$1<>"--", IFERROR(VLOOKUP(A13,'0919門市清單主檔'!B:AH,33,FALSE),"")=勤務統計!$F$1, IFERROR(VLOOKUP(A13,勤務統計!A:U,21,FALSE),"")<>勤務統計!$F$1), 勤務統計!$F$1, ""), IF(AND(IFERROR(VLOOKUP(A13,'0919門市清單主檔'!B:AH,28,FALSE),"")="HUB", IFERROR(VLOOKUP(A13,勤務統計!A:W,23,FALSE),"")<>"HUB"), "HUB", "") ) & "未完工", "已完工" ) ) ) -> 未完工 | P13: =(TEXT(I13,"yyyymmdd"))&勤務統計!$V$2&A13&勤務統計!$V$2&B13&勤務統計!$S$2 -> PMQ1-4825-龜山兔子坑(定保) | Q13: {=IF(AND(SUMPRODUCT((IM!$F$2:$F$5000=A13)*(ISNUMBER(SEARCH(勤務統計!$D$1, IM!$AC$2:$AC$5000))))>0), 勤務統計!$D$1, "")} | R13: {=IFERROR(INDEX(IM!$AM$2:$AM$5000, MATCH(1, (IM!$F$2:$F$5000=A13) * (ISNUMBER(SEARCH(勤務統計!$D$1, IM!$AC$2:$AC$5000))), 0)), "")} | S13: {=IF(AND(SUMPRODUCT((IM!$F$2:$F$5000=A13)*(ISNUMBER(SEARCH(勤務統計!$E$1, IM!$AC$2:$AC$5000))))>0), 勤務統計!$E$1, "")} -> +L90 | T13: {=IFERROR(INDEX(IM!$AM$2:$AM$5000, MATCH(1, (IM!$F$2:$F$5000=A13) * (ISNUMBER(SEARCH(勤務統計!$E$1, IM!$AC$2:$AC$5000))), 0)), "")} -> 46027 | U13: {=IF(AND(SUMPRODUCT((IM!$F$2:$F$5000=A13)*(ISNUMBER(SEARCH(勤務統計!$F$1, IM!$AC$2:$AC$5000))))>0), 勤務統計!$F$1, "")} -> +721 | V13: {=IFERROR(INDEX(IM!$AM$2:$AM$5000, MATCH(1, (IM!$F$2:$F$5000=A13) * (ISNUMBER(SEARCH(勤務統計!$F$1, IM!$AC$2:$AC$5000))), 0)), "")} -> 46027 | W13: =IF(VLOOKUP(A13,'0919門市清單主檔'!B:AC,28,FALSE)=0,"",VLOOKUP(A13,'0919門市清單主檔'!B:AC,28,FALSE))
A14: 5162 | B14: =VLOOKUP(A14,'0919門市清單主檔'!B:C,2,FALSE) -> 龜山茶專店 | C14: =VLOOKUP($A14,'0919門市清單主檔'!B:V,20,FALSE) -> 桃園市 | D14: =VLOOKUP($A14,'0919門市清單主檔'!B:V,21,FALSE) -> 蘆竹區 | E14: =VLOOKUP(D14,門市狀態!G:H,2,FALSE) -> 吳宗鴻 | F14: =IFERROR(IF(VLOOKUP(A14,門市狀態!A:D,4,FALSE)=0,"",VLOOKUP(A14,門市狀態!A:D,4,FALSE)),"") | H14: =IF(I14>0,(TEXT(I14,"yyyymmdd")&勤務統計!$V$2&A14&勤務統計!$V$2&B14&勤務統計!$S$2),"") -> PMQ1-5162-龜山茶專店(定保) | I14: {=IF(AND(SUMPRODUCT((IM!$F$2:$F$5000=A14)*(ISNUMBER(SEARCH(勤務統計!$C$1, IM!$AC$2:$AC$5000))))>0), 勤務統計!$C$1, "")} -> PMQ1 | J14: {=IFERROR(INDEX(IM!$AM$2:$AM$5000, MATCH(1, (IM!$F$2:$F$5000=A14) * (ISNUMBER(SEARCH(勤務統計!$C$1, IM!$AC$2:$AC$5000))), 0)), "")} -> 46027 | K14: {=SUMPRODUCT((IM!$F$2:$F$5000=A14)*(IM!$AD$2:$AD$5000="O")*(ISNUMBER(SEARCH(勤務統計!$C$1, IM!$AC$2:$AC$5000))))} -> 1 | L14: {=IF(K14>0,IFERROR(HYPERLINK("#'IM'!AC"&MATCH(1,(IM!$F$1:$F$5000=A14)*(ISNUMBER(SEARCH(勤務統計!$C$1,IM!$AC$1:$AC$5000))),0),"檢核"),"未登錄"),"")} -> 檢核 | M14: =Q14&S14&U14 -> +L90+721 | N14: {=IF(AND( SUMPRODUCT( (IM!$F$2:$F$522=A14) * ISNUMBER(SEARCH("*HUB*", IM!$AC$2:$AC$522)) * (IM!$X$2:$X$522>=勤務統計!$A$1) * (IM!$X$2:$X$522<=勤務統計!$B$1)*(W14="HUB") ) > 0 ), "HUB", "")} | O14: =IF( IFERROR(VLOOKUP(A14,勤務統計!A:I,9,FALSE),"")<>勤務統計!$C$1, "未完工", IF( AND(勤務統計!$D$1="--",勤務統計!$E$1="--",勤務統計!$F$1="--"), "已完工", IF( OR( AND(勤務統計!$D$1<>"--", IFERROR(VLOOKUP(A14,'0919門市清單主檔'!B:AH,31,FALSE),"")=勤務統計!$D$1, IFERROR(VLOOKUP(A14,勤務統計!A:Q,17,FALSE),"")<>勤務統計!$D$1), AND(勤務統計!$E$1<>"--", IFERROR(VLOOKUP(A14,'0919門市清單主檔'!B:AH,32,FALSE),"")=勤務統計!$E$1, IFERROR(VLOOKUP(A14,勤務統計!A:S,19,FALSE),"")<>勤務統計!$E$1), AND(勤務統計!$F$1<>"--", IFERROR(VLOOKUP(A14,'0919門市清單主檔'!B:AH,33,FALSE),"")=勤務統計!$F$1, IFERROR(VLOOKUP(A14,勤務統計!A:U,21,FALSE),"")<>勤務統計!$F$1), AND(IFERROR(VLOOKUP(A14,'0919門市清單主檔'!B:AH,28,FALSE),"")="HUB", IFERROR(VLOOKUP(A14,勤務統計!A:W,23,FALSE),"")<>"HUB") ), _xlfn.TEXTJOIN( "，", TRUE, IF(AND(勤務統計!$D$1<>"--", IFERROR(VLOOKUP(A14,'0919門市清單主檔'!B:AH,31,FALSE),"")=勤務統計!$D$1, IFERROR(VLOOKUP(A14,勤務統計!A:Q,17,FALSE),"")<>勤務統計!$D$1), 勤務統計!$D$1, ""), IF(AND(勤務統計!$E$1<>"--", IFERROR(VLOOKUP(A14,'0919門市清單主檔'!B:AH,32,FALSE),"")=勤務統計!$E$1, IFERROR(VLOOKUP(A14,勤務統計!A:S,19,FALSE),"")<>勤務統計!$E$1), 勤務統計!$E$1, ""), IF(AND(勤務統計!$F$1<>"--", IFERROR(VLOOKUP(A14,'0919門市清單主檔'!B:AH,33,FALSE),"")=勤務統計!$F$1, IFERROR(VLOOKUP(A14,勤務統計!A:U,21,FALSE),"")<>勤務統計!$F$1), 勤務統計!$F$1, ""), IF(AND(IFERROR(VLOOKUP(A14,'0919門市清單主檔'!B:AH,28,FALSE),"")="HUB", IFERROR(VLOOKUP(A14,勤務統計!A:W,23,FALSE),"")<>"HUB"), "HUB", "") ) & "未完工", "已完工" ) ) ) -> 未完工 | P14: =(TEXT(I14,"yyyymmdd"))&勤務統計!$V$2&A14&勤務統計!$V$2&B14&勤務統計!$S$2 -> PMQ1-5162-龜山茶專店(定保) | Q14: {=IF(AND(SUMPRODUCT((IM!$F$2:$F$5000=A14)*(ISNUMBER(SEARCH(勤務統計!$D$1, IM!$AC$2:$AC$5000))))>0), 勤務統計!$D$1, "")} | R14: {=IFERROR(INDEX(IM!$AM$2:$AM$5000, MATCH(1, (IM!$F$2:$F$5000=A14) * (ISNUMBER(SEARCH(勤務統計!$D$1, IM!$AC$2:$AC$5000))), 0)), "")} | S14: {=IF(AND(SUMPRODUCT((IM!$F$2:$F$5000=A14)*(ISNUMBER(SEARCH(勤務統計!$E$1, IM!$AC$2:$AC$5000))))>0), 勤務統計!$E$1, "")} -> +L90 | T14: {=IFERROR(INDEX(IM!$AM$2:$AM$5000, MATCH(1, (IM!$F$2:$F$5000=A14) * (ISNUMBER(SEARCH(勤務統計!$E$1, IM!$AC$2:$AC$5000))), 0)), "")} -> 46027 | U14: {=IF(AND(SUMPRODUCT((IM!$F$2:$F$5000=A14)*(ISNUMBER(SEARCH(勤務統計!$F$1, IM!$AC$2:$AC$5000))))>0), 勤務統計!$F$1, "")} -> +721 | V14: {=IFERROR(INDEX(IM!$AM$2:$AM$5000, MATCH(1, (IM!$F$2:$F$5000=A14) * (ISNUMBER(SEARCH(勤務統計!$F$1, IM!$AC$2:$AC$5000))), 0)), "")} -> 46027 | W14: =IF(VLOOKUP(A14,'0919門市清單主檔'!B:AC,28,FALSE)=0,"",VLOOKUP(A14,'0919門市清單主檔'!B:AC,28,FALSE))
... A32: 4057 | B32: =VLOOKUP(A32,'0919門市清單主檔'!B:C,2,FALSE) -> 林口香澄店 | C32: =VLOOKUP($A32,'0919門市清單主檔'!B:V,20,FALSE) -> 新北市 | D32: =VLOOKUP($A32,'0919門市清單主檔'!B:V,21,FALSE) -> 林口區 | E32: =VLOOKUP(D32,門市狀態!G:H,2,FALSE) -> 吳宗鴻 | F32: =IFERROR(IF(VLOOKUP(A32,門市狀態!A:D,4,FALSE)=0,"",VLOOKUP(A32,門市狀態!A:D,4,FALSE)),"") | H32: =IF(I32>0,(TEXT(I32,"yyyymmdd")&勤務統計!$V$2&A32&勤務統計!$V$2&B32&勤務統計!$S$2),"") -> PMQ1-4057-林口香澄店(定保) | I32: {=IF(AND(SUMPRODUCT((IM!$F$2:$F$5000=A32)*(ISNUMBER(SEARCH(勤務統計!$C$1, IM!$AC$2:$AC$5000))))>0), 勤務統計!$C$1, "")} -> PMQ1 | J32: {=IFERROR(INDEX(IM!$AM$2:$AM$5000, MATCH(1, (IM!$F$2:$F$5000=A32) * (ISNUMBER(SEARCH(勤務統計!$C$1, IM!$AC$2:$AC$5000))), 0)), "")} -> 46030 | K32: {=SUMPRODUCT((IM!$F$2:$F$5000=A32)*(IM!$AD$2:$AD$5000="O")*(ISNUMBER(SEARCH(勤務統計!$C$1, IM!$AC$2:$AC$5000))))} -> 1 | L32: {=IF(K32>0,IFERROR(HYPERLINK("#'IM'!AC"&MATCH(1,(IM!$F$1:$F$5000=A32)*(ISNUMBER(SEARCH(勤務統計!$C$1,IM!$AC$1:$AC$5000))),0),"檢核"),"未登錄"),"")} -> 檢核 | M32: =Q32&S32&U32 -> +L90+721 | N32: {=IF(AND( SUMPRODUCT( (IM!$F$2:$F$522=A32) * ISNUMBER(SEARCH("*HUB*", IM!$AC$2:$AC$522)) * (IM!$X$2:$X$522>=勤務統計!$A$1) * (IM!$X$2:$X$522<=勤務統計!$B$1)*(W32="HUB") ) > 0 ), "HUB", "")} | O32: =IF( IFERROR(VLOOKUP(A32,勤務統計!A:I,9,FALSE),"")<>勤務統計!$C$1, "未完工", IF( AND(勤務統計!$D$1="--",勤務統計!$E$1="--",勤務統計!$F$1="--"), "已完工", IF( OR( AND(勤務統計!$D$1<>"--", IFERROR(VLOOKUP(A32,'0919門市清單主檔'!B:AH,31,FALSE),"")=勤務統計!$D$1, IFERROR(VLOOKUP(A32,勤務統計!A:Q,17,FALSE),"")<>勤務統計!$D$1), AND(勤務統計!$E$1<>"--", IFERROR(VLOOKUP(A32,'0919門市清單主檔'!B:AH,32,FALSE),"")=勤務統計!$E$1, IFERROR(VLOOKUP(A32,勤務統計!A:S,19,FALSE),"")<>勤務統計!$E$1), AND(勤務統計!$F$1<>"--", IFERROR(VLOOKUP(A32,'0919門市清單主檔'!B:AH,33,FALSE),"")=勤務統計!$F$1, IFERROR(VLOOKUP(A32,勤務統計!A:U,21,FALSE),"")<>勤務統計!$F$1), AND(IFERROR(VLOOKUP(A32,'0919門市清單主檔'!B:AH,28,FALSE),"")="HUB", IFERROR(VLOOKUP(A32,勤務統計!A:W,23,FALSE),"")<>"HUB") ), _xlfn.TEXTJOIN( "，", TRUE, IF(AND(勤務統計!$D$1<>"--", IFERROR(VLOOKUP(A32,'0919門市清單主檔'!B:AH,31,FALSE),"")=勤務統計!$D$1, IFERROR(VLOOKUP(A32,勤務統計!A:Q,17,FALSE),"")<>勤務統計!$D$1), 勤務統計!$D$1, ""), IF(AND(勤務統計!$E$1<>"--", IFERROR(VLOOKUP(A32,'0919門市清單主檔'!B:AH,32,FALSE),"")=勤務統計!$E$1, IFERROR(VLOOKUP(A32,勤務統計!A:S,19,FALSE),"")<>勤務統計!$E$1), 勤務統計!$E$1, ""), IF(AND(勤務統計!$F$1<>"--", IFERROR(VLOOKUP(A32,'0919門市清單主檔'!B:AH,33,FALSE),"")=勤務統計!$F$1, IFERROR(VLOOKUP(A32,勤務統計!A:U,21,FALSE),"")<>勤務統計!$F$1), 勤務統計!$F$1, ""), IF(AND(IFERROR(VLOOKUP(A32,'0919門市清單主檔'!B:AH,28,FALSE),"")="HUB", IFERROR(VLOOKUP(A32,勤務統計!A:W,23,FALSE),"")<>"HUB"), "HUB", "") ) & "未完工", "已完工" ) ) ) -> 未完工 | P32: =(TEXT(I32,"yyyymmdd"))&勤務統計!$V$2&A32&勤務統計!$V$2&B32&勤務統計!$S$2 -> PMQ1-4057-林口香澄店(定保) | Q32: {=IF(AND(SUMPRODUCT((IM!$F$2:$F$5000=A32)*(ISNUMBER(SEARCH(勤務統計!$D$1, IM!$AC$2:$AC$5000))))>0), 勤務統計!$D$1, "")} | R32: {=IFERROR(INDEX(IM!$AM$2:$AM$5000, MATCH(1, (IM!$F$2:$F$5000=A32) * (ISNUMBER(SEARCH(勤務統計!$D$1, IM!$AC$2:$AC$5000))), 0)), "")} | S32: {=IF(AND(SUMPRODUCT((IM!$F$2:$F$5000=A32)*(ISNUMBER(SEARCH(勤務統計!$E$1, IM!$AC$2:$AC$5000))))>0), 勤務統計!$E$1, "")} -> +L90 | T32: {=IFERROR(INDEX(IM!$AM$2:$AM$5000, MATCH(1, (IM!$F$2:$F$5000=A32) * (ISNUMBER(SEARCH(勤務統計!$E$1, IM!$AC$2:$AC$5000))), 0)), "")} -> 45992 | U32: {=IF(AND(SUMPRODUCT((IM!$F$2:$F$5000=A32)*(ISNUMBER(SEARCH(勤務統計!$F$1, IM!$AC$2:$AC$5000))))>0), 勤務統計!$F$1, "")} -> +721 | V32: {=IFERROR(INDEX(IM!$AM$2:$AM$5000, MATCH(1, (IM!$F$2:$F$5000=A32) * (ISNUMBER(SEARCH(勤務統計!$F$1, IM!$AC$2:$AC$5000))), 0)), "")} -> 46030 | W32: =IF(VLOOKUP(A32,'0919門市清單主檔'!B:AC,28,FALSE)=0,"",VLOOKUP(A32,'0919門市清單主檔'!B:AC,28,FALSE))
