Workbook

Sheet Part
A1: No. | B1: 型号 | C1: 部品号 | D1: 部品号 | E1: 部品名称 | F1: 寿命 (x1000印次) (黑白/全色) | G1: 内容 | H1: 数量 | I1: 备注
A2: 66 | B2: 2505 | C2: 6LJ83358000 | D2: T6LJ83358000 | E2: OD-2505 | F2: 55 | G2: 滾筒 | H2: 1 | I2: for all
A3: 67 | B3: 2505 | C3: 6LJ83445000 | D3: T6LJ83445000 | E3: D-2505 | F3: 55 | G3: 顯像鐵粉 | H3: 1
A4: 68 | B4: 2505 | C4: 6LA27845000 | D4: T6LA27845000 | E4: BL-2320D | F4: 55 | G4: 滾筒刮片 | H4: 1
A5: 69 | B5: 2505 | C5: 6LJ83407000 | D5: T6LJ83407000 | E5: CR-2505-TR | F5: 55 | G5: 轉寫滾軸 | H5: 1
A6: 70 | B6: 2505 | C6: 6LJ78116000 | D6: T6LJ78116000 | E6: HR-2505-U | F6: 165 | G6: 上熱滾軸 | H6: 1 | I6: for Machine Refreshing
A7: 71 | B7: 2505 | C7: 6LJ83406000 | D7: T6LJ83406000 | E7: HR-2505-L | F7: 165 | G7: 下熱滾軸 | H7: 1 | I7: for Machine Refreshing
A8: 72 | B8: 2505 | C8: 6LE58405000 | D8: T6LE58405000 | E8: SCRAPER-282 | F8: 165 | G8: 定著分離爪 | H8: 5 | I8: for Machine Refreshing
A9: 73 | B9: 2505 | C9: 6LJ78009000 | D9: T6LJ78009000 | E9: BUSH-FUS-HR-H24X | F9: 165 | G9: 上熱滾軸軸套 | H9: 2 | I9: for Machine Refreshing
A10: 74 | B10: 2505 | C10: 6LA79618000 | D10: T6LA79618000 | E10: SCRAPER-371 | F10: 165 | G10: 滾筒分離爪 | H10: 2 | I10: for Machine Refreshing
A11: 75 | B11: 2505 | C11: 6LJ76609000 | D11: T6LJ76609000 | E11: SHEET-BLADE-REC-H24X_N | F11: 165 | G11: 回收刮片 | H11: 1 | I11: for Machine Refreshing
A12: 76 | B12: 2505 | C12: 6LJ80213000 | D12: T6LJ80213000 | E12: FILTER-OZONE-H24X | F12: 165 | G12: 臭氧過濾棉 | H12: 1 | I12: for Machine Refreshing
A13: 77 | B13: 2505 | C13: 6LJ78626000 | D13: T6LJ78626000 | E13: CH-M-H24X-NEW | F13: 165 | G13: 放電座針狀放電線 | H13: 1 | I13: for Machine Refreshing
A14: 78 | B14: 2505 | C14: 6LJ78604000 | D14: T6LJ78604000 | E14: GRID-CH-M-H24X | F14: 55 | G14: 柵極網 | H14: 1
A15: 79 | B15: 2505 | C15: 6LJ75249000 | D15: T6LJ75249000 | E15: ASYS-ROL-F32 | F15: 80 | G15: 紙匣用送紙滾軸 | H15: 1 | I15: Drawer
A16: 80 | B16: 2505 | C16: 6LJ75285000 | D16: T6LJ75285000 | E16: ASYS-PAD-CST-H394-2 | F16: 80 | G16: 分頁片组件 | H16: 1 | I16: Drawer
A17: 81 | B17: 2505 | C17: 6LJ75249000 | D17: T6LJ75249000 | E17: ASYS-ROL-F32 | F17: 80 | G17: 手送台送纸器用送紙滾軸 | H17: 1 | I17: SFB
A18: 82 | B18: 2505 | C18: 6LJ74927000 | D18: T6LJ74927000 | E18: ASYS-PAD-SFB-H24X | F18: 80 | G18: 手送台送纸器用分頁片 | H18: 1 | I18: SFB
A19: 83 | B19: 2505 | C19: 6LJ83556000 | D19: T6LJ83556000 | E19: DEV-KIT-2505-NEW | F19: 55 | G19: 顯像保養套件 | H19: -
A20: 84 | B20: 2505 | C20: 6LJ78114000 | D20: T6LJ78114000 | E20: FR_R-KIT-2505-NEW | F20: 165 | G20: 保養更新套件 | H20: - | I20: for Machine Refreshing
A21: 85 | B21: 2505 | C21: 6LJ76605000 | D21: T6LJ76605000 | E21: DEV-UNIT-2505 | F21: - | G21: 顯像組 | H21: -
A22: 86 | B22: 2505 | C22: 6LJ75530000 | D22: T6LJ75530000 | E22: CLN-DRUM-2505 | F22: - | G22: 滾筒清潔組 | H22: -
A23: 87 | B23: 2505 | C23: 6LJ78627000 | D23: T6LJ78627000 | E23: MAIN-CH-2505-N | F23: - | G23: 放電座组件 | H23: -
A24: 88 | B24: 2505 | C24: 6LJ78111000 | D24: T6LJ78111000 | E24: FUSER-2505-230 | F24: - | G24: 定著組（230V） | H24: -
A25: 89 | B25: 2802A/AM/AF, 2822AM | C25: 6LJ83358000 | D25: T6LJ83358000 | E25: OD-2505 | F25: 64 | G25: 滾筒 | H25: 1 | I25: for all
A26: 90 | B26: 2802A/AM/AF, 2822AM | C26: 6LJ83445000 | D26: T6LJ83445000 | E26: D-2505 | F26: 64 | G26: 顯像鐵粉 | H26: 1
A27: 91 | B27: 2802A/AM/AF, 2822AM | C27: 6LJ84278000 | D27: T6LJ84278000 | E27: D-2309 | F27: 64 | G27: 新機鐵粉盒 | H27: 1 | I27: Co-packed with the initial machine (New)
A28: 92 | B28: 2802A/AM/AF, 2822AM | C28: 6LA27845000 | D28: T6LA27845000 | E28: BL-2320D | F28: 64 | G28: 滾筒刮片 | H28: 1
A29: 93 | B29: 2802A/AM/AF, 2822AM | C29: 6LJ83407000 | D29: T6LJ83407000 | E29: CR-2505-TR | F29: 64 | G29: 轉寫滾軸 | H29: 1
A30: 94 | B30: 2802A/AM/AF, 2822AM | C30: 6LJ78116000 | D30: T6LJ78116000 | E30: HR-2505-U | F30: 192 | G30: 上熱滾軸 | H30: 1 | I30: for Machine Refreshing
A31: 95 | B31: 2802A/AM/AF, 2822AM | C31: 6LJ78088000 | D31: T6LJ78088000 | E31: HR-2809-L | F31: 192 | G31: 下熱滾軸 | H31: 1 | I31: for Machine Refreshing (eS2802, 2822, 2303A and 2323A Series)
A32: 96 | B32: 2802A/AM/AF, 2822AM | C32: 6LE58405000 | D32: T6LE58405000 | E32: SCRAPER-282 | F32: 192 | G32: 定著分離爪 | H32: 5 | I32: for Machine Refreshing
A33: 97 | B33: 2802A/AM/AF, 2822AM | C33: 6LJ78009000 | D33: T6LJ78009000 | E33: BUSH-FUS-HR-H24X | F33: 192 | G33: 上熱滾軸軸套 | H33: 2 | I33: for Machine Refreshing
A34: 98 | B34: 2802A/AM/AF, 2822AM | C34: 6LA79618000 | D34: T6LA79618000 | E34: SCRAPER-371 | F34: 192 | G34: 滾筒分離爪 | H34: 2 | I34: for Machine Refreshing
A35: 99 | B35: 2802A/AM/AF, 2822AM | C35: 6LJ76609000 | D35: T6LJ76609000 | E35: SHEET-BLADE-REC-H24X_N | F35: 192 | G35: 回收刮片 | H35: 1 | I35: for Machine Refreshing
A36: 100 | B36: 2802A/AM/AF, 2822AM | C36: 6LJ80213000 | D36: T6LJ80213000 | E36: FILTER-OZONE-H24X | F36: 192 | G36: 臭氧過濾棉 | H36: 1 | I36: for Machine Refreshing
A37: 101 | B37: 2802A/AM/AF, 2822AM | C37: 6LJ78626000 | D37: T6LJ78626000 | E37: CH-M-H24X-NEW | F37: 192 | G37: 放電座針狀放電線 | H37: 1 | I37: for Machine Refreshing
A38: 102 | B38: 2802A/AM/AF, 2822AM | C38: 6LJ78604000 | D38: T6LJ78604000 | E38: GRID-CH-M-H24X | F38: 64 | G38: 柵極網 | H38: 1
A39: 103 | B39: 2802A/AM/AF, 2822AM | C39: 6LJ75249000 | D39: T6LJ75249000 | E39: ASYS-ROL-F32 | F39: 80 | G39: 紙匣用送紙滾軸 | H39: 1 | I39: Common with e-STUDIO2505/H/F
A40: 104 | B40: 2802A/AM/AF, 2822AM | C40: 6LJ75285000 | D40: T6LJ75285000 | E40: ASYS-PAD-CST-H394-2 | F40: 80 | G40: 分頁片组件 | H40: 1 | I40: Common with e-STUDIO2505/H/F
...

Sheet 工作表1
A1: 型号
A2: e-STUDIO2000AC/2010AC/2110AC
A3: e-STUDIO2006/2306/2506/2007/2307/2507
A4: e-STUDIO2020AC
A5: e-STUDIO2050C/2051C
A6: e-STUDIO2303A/2309A, 2323AM/AMS/AMW
A7: e-STUDIO2500AC/2510AC/2610AC
A9: e-STUDIO2505AC/2515AC/2615AC
A10: e-STUDIO2508A/2518A/2618A
A11: e-STUDIO2520AC
A12: e-STUDIO2523A/2523AD
A13: e-STUDIO2525AC
... A55: e-STUDIO6528A

Sheet 工作表2
A1: 型号
A2: 2500AC/2510AC/2610AC
A3: 2505AC/2515AC/2615AC
A4: 2508A/2518A/2618A
A5: 2520AC
A6: 2809A, 2823AM/2829A/2823AMW
A7: 3008A/3018A(AG)/3118A(AG)
A8: 3025AC
A9: 3028A
A10: 3505AC/3515AC/3615AC
A11: 3508A/3518A(AG)/3618A(AG)
A12: 3525AC/ACG
... A25: 6528A

Sheet 工作表4
A1: 機型 | B1: 部件 | C1: 零件名稱 | E1: 料號 | F1: 型號 | G1: 壽命(張)
A2: 2505 | B2: {=_xlfn.XLOOKUP(TRUE, ISNUMBER(SEARCH(工作表5!$A$1:$A$23, C2)), 工作表5!$B$1:$B$23, "其他")} -> 滾筒組 | C2: 滾筒 | D2: 滾筒組 | E2: T6LJ83358000 | F2: OD-2505 | G2: 55000
A3: 2505 | B3: {=_xlfn.XLOOKUP(TRUE, ISNUMBER(SEARCH(工作表5!$A$1:$A$23, C3)), 工作表5!$B$1:$B$23, "其他")} -> 顯像組 | C3: 顯像鐵粉 | D3: 顯像組 | E3: T6LJ83445000 | F3: D-2505 | G3: 55000
A4: 2505 | B4: {=_xlfn.XLOOKUP(TRUE, ISNUMBER(SEARCH(工作表5!$A$1:$A$23, C4)), 工作表5!$B$1:$B$23, "其他")} -> 滾筒組 | C4: 滾筒刮片 | D4: 滾筒組 | E4: T6LA27845000 | F4: BL-2320D | G4: 55000
A5: 2505 | B5: {=_xlfn.XLOOKUP(TRUE, ISNUMBER(SEARCH(工作表5!$A$1:$A$23, C5)), 工作表5!$B$1:$B$23, "其他")} -> 轉寫組 | C5: 轉寫滾軸 | D5: 轉寫組 | E5: T6LJ83407000 | F5: CR-2505-TR | G5: 55000
A6: 2505 | B6: {=_xlfn.XLOOKUP(TRUE, ISNUMBER(SEARCH(工作表5!$A$1:$A$23, C6)), 工作表5!$B$1:$B$23, "其他")} -> 定著組 | C6: 上熱滾軸 | D6: 定著組 | E6: T6LJ78116000 | F6: HR-2505-U | G6: 165000
A7: 2505 | B7: {=_xlfn.XLOOKUP(TRUE, ISNUMBER(SEARCH(工作表5!$A$1:$A$23, C7)), 工作表5!$B$1:$B$23, "其他")} -> 定著組 | C7: 下熱滾軸 | D7: 定著組 | E7: T6LJ83406000 | F7: HR-2505-L | G7: 165000
A8: 2505 | B8: {=_xlfn.XLOOKUP(TRUE, ISNUMBER(SEARCH(工作表5!$A$1:$A$23, C8)), 工作表5!$B$1:$B$23, "其他")} -> 定著組 | C8: 定著分離爪 | D8: 定著組 | E8: T6LE58405000 | F8: SCRAPER-282 | G8: 165000
A9: 2505 | B9: {=_xlfn.XLOOKUP(TRUE, ISNUMBER(SEARCH(工作表5!$A$1:$A$23, C9)), 工作表5!$B$1:$B$23, "其他")} -> 定著組 | C9: 上熱滾軸軸套 | D9: 定著組 | E9: T6LJ78009000 | F9: BUSH-FUS-HR-H24X | G9: 165000
A10: 2505 | B10: {=_xlfn.XLOOKUP(TRUE, ISNUMBER(SEARCH(工作表5!$A$1:$A$23, C10)), 工作表5!$B$1:$B$23, "其他")} -> 滾筒組 | C10: 滾筒分離爪 | D10: 滾筒組 | E10: T6LA79618000 | F10: SCRAPER-371 | G10: 165000
A11: 2505 | B11: {=_xlfn.XLOOKUP(TRUE, ISNUMBER(SEARCH(工作表5!$A$1:$A$23, C11)), 工作表5!$B$1:$B$23, "其他")} -> 滾筒組 | C11: 回收刮片 | D11: 滾筒組 | E11: T6LJ76609000 | F11: SHEET-BLADE-REC-H24X_N | G11: 165000
A12: 2505 | B12: {=_xlfn.XLOOKUP(TRUE, ISNUMBER(SEARCH(工作表5!$A$1:$A$23, C12)), 工作表5!$B$1:$B$23, "其他")} -> 其他 | C12: 臭氧過濾棉 | D12: 其他 | E12: T6LJ80213000 | F12: FILTER-OZONE-H24X | G12: 165000
A13: 2505 | B13: {=_xlfn.XLOOKUP(TRUE, ISNUMBER(SEARCH(工作表5!$A$1:$A$23, C13)), 工作表5!$B$1:$B$23, "其他")} -> 顯像組 | C13: 放電座針狀放電線 | D13: 滾筒組 | E13: T6LJ78626000 | F13: CH-M-H24X-NEW | G13: 165000
... A20: 2505 | B20: {=_xlfn.XLOOKUP(TRUE, ISNUMBER(SEARCH(工作表5!$A$1:$A$23, C20)), 工作表5!$B$1:$B$23, "其他")} -> 其他 | C20: 保養更新套件 | D20: 其他 | E20: T6LJ78114000 | F20: FR_R-KIT-2505-NEW | G20: 165000
A21: 2505 | B21: {=_xlfn.XLOOKUP(TRUE, ISNUMBER(SEARCH(工作表5!$A$1:$A$23, C21)), 工作表5!$B$1:$B$23, "其他")} -> 顯像組 | C21: 顯像組 | D21: 顯像組 | E21: T6LJ76605000 | F21: DEV-UNIT-2505 | G21: #VALUE!
A22: 2505 | B22: {=_xlfn.XLOOKUP(TRUE, ISNUMBER(SEARCH(工作表5!$A$1:$A$23, C22)), 工作表5!$B$1:$B$23, "其他")} -> 滾筒組 | C22: 滾筒清潔組 | D22: 滾筒組 | E22: T6LJ75530000 | F22: CLN-DRUM-2505 | G22: #VALUE!
A23: 2505 | B23: {=_xlfn.XLOOKUP(TRUE, ISNUMBER(SEARCH(工作表5!$A$1:$A$23, C23)), 工作表5!$B$1:$B$23, "其他")} -> 顯像組 | C23: 放電座组件 | D23: 顯像組 | E23: T6LJ78627000 | F23: MAIN-CH-2505-N | G23: #VALUE!
A24: 2505 | B24: {=_xlfn.XLOOKUP(TRUE, ISNUMBER(SEARCH(工作表5!$A$1:$A$23, C24)), 工作表5!$B$1:$B$23, "其他")} -> 定著組 | C24: 定著組（230V） | D24: 定著組 | E24: T6LJ78111000 | F24: FUSER-2505-230 | G24: #VALUE!
A25: 2802A/AM/AF, 2822AM | B25: {=_xlfn.XLOOKUP(TRUE, ISNUMBER(SEARCH(工作表5!$A$1:$A$23, C25)), 工作表5!$B$1:$B$23, "其他")} -> 滾筒組 | C25: 滾筒 | E25: T6LJ83358000 | F25: OD-2505 | G25: 64000
A26: 2802A/AM/AF, 2822AM | B26: {=_xlfn.XLOOKUP(TRUE, ISNUMBER(SEARCH(工作表5!$A$1:$A$23, C26)), 工作表5!$B$1:$B$23, "其他")} -> 顯像組 | C26: 顯像鐵粉 | E26: T6LJ83445000 | F26: D-2505 | G26: 64000
A27: 2802A/AM/AF, 2822AM | B27: {=_xlfn.XLOOKUP(TRUE, ISNUMBER(SEARCH(工作表5!$A$1:$A$23, C27)), 工作表5!$B$1:$B$23, "其他")} -> 顯像組 | C27: 新機鐵粉盒 | D27: 其他 | E27: T6LJ84278000 | F27: D-2309 | G27: 64000
A28: 2802A/AM/AF, 2822AM | B28: {=_xlfn.XLOOKUP(TRUE, ISNUMBER(SEARCH(工作表5!$A$1:$A$23, C28)), 工作表5!$B$1:$B$23, "其他")} -> 滾筒組 | C28: 滾筒刮片 | E28: T6LA27845000 | F28: BL-2320D | G28: 64000
A29: 2802A/AM/AF, 2822AM | B29: {=_xlfn.XLOOKUP(TRUE, ISNUMBER(SEARCH(工作表5!$A$1:$A$23, C29)), 工作表5!$B$1:$B$23, "其他")} -> 轉寫組 | C29: 轉寫滾軸 | E29: T6LJ83407000 | F29: CR-2505-TR | G29: 64000
A30: 2802A/AM/AF, 2822AM | B30: {=_xlfn.XLOOKUP(TRUE, ISNUMBER(SEARCH(工作表5!$A$1:$A$23, C30)), 工作表5!$B$1:$B$23, "其他")} -> 定著組 | C30: 上熱滾軸 | E30: T6LJ78116000 | F30: HR-2505-U | G30: 192000
A31: 2802A/AM/AF, 2822AM | B31: {=_xlfn.XLOOKUP(TRUE, ISNUMBER(SEARCH(工作表5!$A$1:$A$23, C31)), 工作表5!$B$1:$B$23, "其他")} -> 定著組 | C31: 下熱滾軸 | E31: T6LJ78088000 | F31: HR-2809-L | G31: 192000
A32: 2802A/AM/AF, 2822AM | B32: {=_xlfn.XLOOKUP(TRUE, ISNUMBER(SEARCH(工作表5!$A$1:$A$23, C32)), 工作表5!$B$1:$B$23, "其他")} -> 定著組 | C32: 定著分離爪 | E32: T6LE58405000 | F32: SCRAPER-282 | G32: 192000
A33: 2802A/AM/AF, 2822AM | B33: {=_xlfn.XLOOKUP(TRUE, ISNUMBER(SEARCH(工作表5!$A$1:$A$23, C33)), 工作表5!$B$1:$B$23, "其他")} -> 定著組 | C33: 上熱滾軸軸套 | E33: T6LJ78009000 | F33: BUSH-FUS-HR-H24X | G33: 192000
A34: 2802A/AM/AF, 2822AM | B34: {=_xlfn.XLOOKUP(TRUE, ISNUMBER(SEARCH(工作表5!$A$1:$A$23, C34)), 工作表5!$B$1:$B$23, "其他")} -> 滾筒組 | C34: 滾筒分離爪 | E34: T6LA79618000 | F34: SCRAPER-371 | G34: 192000
A35: 2802A/AM/AF, 2822AM | B35: {=_xlfn.XLOOKUP(TRUE, ISNUMBER(SEARCH(工作表5!$A$1:$A$23, C35)), 工作表5!$B$1:$B$23, "其他")} -> 滾筒組 | C35: 回收刮片 | E35: T6LJ76609000 | F35: SHEET-BLADE-REC-H24X_N | G35: 192000
A36: 2802A/AM/AF, 2822AM | B36: {=_xlfn.XLOOKUP(TRUE, ISNUMBER(SEARCH(工作表5!$A$1:$A$23, C36)), 工作表5!$B$1:$B$23, "其他")} -> 其他 | C36: 臭氧過濾棉 | E36: T6LJ80213000 | F36: FILTER-OZONE-H24X | G36: 192000
A37: 2802A/AM/AF, 2822AM | B37: {=_xlfn.XLOOKUP(TRUE, ISNUMBER(SEARCH(工作表5!$A$1:$A$23, C37)), 工作表5!$B$1:$B$23, "其他")} -> 顯像組 | C37: 放電座針狀放電線 | E37: T6LJ78626000 | F37: CH-M-H24X-NEW | G37: 192000
A38: 2802A/AM/AF, 2822AM | B38: {=_xlfn.XLOOKUP(TRUE, ISNUMBER(SEARCH(工作表5!$A$1:$A$23, C38)), 工作表5!$B$1:$B$23, "其他")} -> 滾筒組 | C38: 柵極網 | E38: T6LJ78604000 | F38: GRID-CH-M-H24X | G38: 64000
A39: 2802A/AM/AF, 2822AM | B39: {=_xlfn.XLOOKUP(TRUE, ISNUMBER(SEARCH(工作表5!$A$1:$A$23, C39)), 工作表5!$B$1:$B$23, "其他")} -> 取紙組 | C39: 紙匣用送紙滾軸 | E39: T6LJ75249000 | F39: ASYS-ROL-F32 | G39: 80000
... A45: 2802A/AM/AF, 2822AM | B45: {=_xlfn.XLOOKUP(TRUE, ISNUMBER(SEARCH(工作表5!$A$1:$A$23, C45)), 工作表5!$B$1:$B$23, "其他")} -> 其他 | C45: 保養更新套件 | E45: T6LJ78113000 | F45: FR_R-KIT-2809 | G45: 192000
A46: 2802A/AM/AF, 2822AM | B46: {=_xlfn.XLOOKUP(TRUE, ISNUMBER(SEARCH(工作表5!$A$1:$A$23, C46)), 工作表5!$B$1:$B$23, "其他")} -> 顯像組 | C46: 顯像組 | E46: T6LJ76601000 | F46: DEV-UNIT-2809 | G46: #VALUE!
A47: 2802A/AM/AF, 2822AM | B47: {=_xlfn.XLOOKUP(TRUE, ISNUMBER(SEARCH(工作表5!$A$1:$A$23, C47)), 工作表5!$B$1:$B$23, "其他")} -> 滾筒組 | C47: 滾筒清潔組 | E47: T6LJ75530000 | F47: CLN-DRUM-2505 | G47: #VALUE!
A48: 2802A/AM/AF, 2822AM | B48: {=_xlfn.XLOOKUP(TRUE, ISNUMBER(SEARCH(工作表5!$A$1:$A$23, C48)), 工作表5!$B$1:$B$23, "其他")} -> 顯像組 | C48: 放電座组件 | E48: T6LJ78627000 | F48: MAIN-CH-2505-N | G48: #VALUE!
A49: 2802A/AM/AF, 2822AM | B49: {=_xlfn.XLOOKUP(TRUE, ISNUMBER(SEARCH(工作表5!$A$1:$A$23, C49)), 工作表5!$B$1:$B$23, "其他")} -> 定著組 | C49: 定著組（230V） | E49: T6LJ78106000 | F49: FUSER-2809-230 | G49: #VALUE!
A50: 2006/2306/2506/2007/2307/2507 | B50: {=_xlfn.XLOOKUP(TRUE, ISNUMBER(SEARCH(工作表5!$A$1:$A$23, C50)), 工作表5!$B$1:$B$23, "其他")} -> 滾筒組 | C50: 滾筒 | E50: T6LJ83358000 | F50: OD-2505 | G50: 55000
A51: 2006/2306/2506/2007/2307/2507 | B51: {=_xlfn.XLOOKUP(TRUE, ISNUMBER(SEARCH(工作表5!$A$1:$A$23, C51)), 工作表5!$B$1:$B$23, "其他")} -> 顯像組 | C51: 顯像鐵粉 | E51: T6LJ83445000 | F51: D-2505 | G51: 55000
...

Sheet 工作表5
A1: 滾筒 | B1: 滾筒組 | F1: 滾筒 | G1: 滾筒組
A2: 鐵粉 | B2: 顯像組 | F2: 鐵粉 | G2: 顯像組
A3: 轉寫 | B3: 轉寫組 | F3: 轉寫 | G3: 轉寫組
A4: 上熱 | B4: 定著組 | F4: 上熱 | G4: 定著組
A5: 下熱 | B5: 定著組 | F5: 下熱 | G5: 定著組
A6: 定著 | B6: 定著組 | F6: 定著 | G6: 定著組
A7: 柵極 | B7: 滾筒組 | F7: 柵極 | G7: 滾筒組
A8: 紙匣 | B8: 取紙組 | F8: 紙匣 | G8: 取紙組
A9: RADF | B9: 送稿機 | F9: RADF | G9: 送稿機
A10: DSDF | B10: 送稿機 | F10: DSDF | G10: 送稿機
A11: KD | B11: 取紙組 | F11: KD | G11: 取紙組
A12: MY | B12: 取紙組 | F12: MY | G12: 取紙組
... A14: LCF | B14: 大容量取紙組 | F14: LCF | G14: 大容量取紙組
A15: 分頁片组件 | B15: 手送台
A16: 手送台送纸器用送紙滾軸 | B16: 手送台
A17: 手送台 | B17: 手送台
A18: 放電 | B18: 顯像組
A19: 回收 | B19: 滾筒組
A20: 顯像 | B20: 顯像組
A21: MR | B21: 送稿機
A22: 自動送稿器 | B22: 送稿機
A23: 自動雙面 | B23: 送稿機
