Workbook
Name A: #N/A
Name A: #REF!
Name A: #REF!
Name A: #N/A
Name A: [0]!A
Name A: #REF!
Name A00: [1]督導二課!$D$80
Name AA: #REF!
Name AA: #REF!
Name AA: #REF!
Name AA: #REF!
Name AA: #REF!
Name AA: #REF!
Name BEGIN: #N/A
Name BEGIN: #REF!
Name BEGIN: #REF!
Name BEGIN: #N/A
Name BEGIN: [0]!BEGIN
Name BEGIN: #REF!
Name BONUS: #N/A
Name BONUS: #REF!
Name BONUS: #REF!
Name BONUS: #N/A
Name BONUS: [0]!BONUS
Name BONUS: #REF!
Name CALK3: #N/A
Name CALK3: #REF!
Name CALK3: #REF!
Name CALK3: #N/A
Name CALK3: [0]!CALK3
Name CALK3: #REF!
Name CALP3: #N/A
Name CALP3: #REF!
Name CALP3: #REF!
Name CALP3: #N/A
Name CALP3: [0]!CALP3
Name CALP3: #REF!
Name DRALINE: #N/A
Name DRALINE: #REF!
Name DRALINE: #REF!
Name DRALINE: #N/A
Name DRALINE: [0]!DRALINE
Name DRALINE: #REF!
Name DRAWLINE: #N/A
Name DRAWLINE: #REF!
Name DRAWLINE: #REF!
Name DRAWLINE: #N/A
Name DRAWLINE: [0]!DRAWLINE
Name DRAWLINE: #REF!
Name FUCK: #REF!
Name FUCK: #REF!
Name FUCK: #REF!
Name FUCK: #REF!
Name FUCK: #REF!
Name FUCK: #REF!
Name FUCK1: #REF!
Name FUCK1: #REF!
Name FUCK1: #REF!
Name FUCK1: #REF!
Name FUCK1: #REF!

Sheet 門市主檔
A1: =首頁!I4 -> 46113 | B1: =首頁!L4 -> 46204 | C1: =首頁!A2 -> PMQ2 | D1: =首頁!B2 -> +SC7 | E1: =IF(首頁!C2=0,"",首頁!C2) -> -- | F1: =IF(首頁!D2=0,"",首頁!D2) -> -- | G1: 自強 | H1: {=IFERROR(HYPERLINK("#" & ADDRESS(MIN(IF(ISNUMBER(SEARCH(G1, A22:W490)), ROW(A22:W490), 10000000000)), MIN(IF(ISNUMBER(SEARCH(G1, A22:W490)), COLUMN(A22:W490), 10000000000))), "搜索"), "未找到")} -> 搜索 | I1: +HUB | J1: +EDC
A2: =IFERROR(HYPERLINK("#'門市主檔'!A"&MATCH(A23,門市主檔!A22:A293,0)+20, "新北一部"), "查無店編") -> 新北一部 | B2: =IFERROR(HYPERLINK("#'門市主檔'!A"&MATCH(A228,門市主檔!A:A,0), "統計"), "查無店編") -> 統計 | C2: 石門區 | D2: 三芝區 | E2: 淡水區 | F2: 金山區 | G2: 八里區 | H2: 蘆洲區 | I2: 三重區 | J2: 蘆竹區 | K2: 龜山區 | L2: 五股區 | M2: 新莊區 | N2: 泰山區 | O2: 林口區 | P2: 板橋區 | Q2: 中和區 | R2: 永和區 | S2: (定保) | T2: - | U2: (定保) | V2: -
A3: 門市數量(303) | B3: =SUM(C3:R3) -> 302 | C3: =COUNTIF($D$22:$D$489,C2)-C20 -> 1 | D3: =COUNTIF($D$22:$D$489,D2)-D20 -> 2 | E3: =COUNTIF($D$22:$D$489,E2)-E20 -> 15 | F3: =COUNTIF($D$22:$D$489,F2)-F20 -> 2 | G3: =COUNTIF($D$22:$D$489,G2)-G20 -> 9 | H3: =COUNTIF($D$22:$D$489,H2)-H20 -> 18 | I3: =COUNTIF($D$22:$D$489,I2)-I20 -> 73 | J3: =COUNTIF($D$22:$D$489,J2)-J20 -> 29 | ... R3: =COUNTIF($D$22:$D$489,R2)-R20 -> 6
A4: =首頁!A2&" 進度" -> PMQ2 進度 | B4: =B5/B3 -> 0.98344371 | C4: =C5/(C3-C20) -> 1 | D4: =D5/(D3-D20) -> 1 | E4: =E5/(E3-E20) -> 1 | F4: =F5/(F3-F20) -> 1 | G4: =G5/(G3-G20) -> 1 | H4: =H5/(H3-H20) -> 1 | I4: =I5/(I3-I20) -> 0.98630137 | J4: =J5/(J3-J20) -> 0.96551724 | ... R4: =R5/(R3-R20) -> 1
A5: 完工數量 | B5: =SUM(C5:R5) -> 297 | C5: =COUNTIFS($D$22:$D$489,C2,$I$22:$I$489,$C$1) -> 1 | D5: =COUNTIFS($D$22:$D$489,D2,$I$22:$I$489,$C$1) -> 2 | E5: =COUNTIFS($D$22:$D$489,E2,$I$22:$I$489,$C$1) -> 15 | F5: =COUNTIFS($D$22:$D$489,F2,$I$22:$I$489,$C$1) -> 2 | G5: =COUNTIFS($D$22:$D$489,G2,$I$22:$I$489,$C$1) -> 9 | H5: =COUNTIFS($D$22:$D$489,H2,$I$22:$I$489,$C$1) -> 18 | I5: =COUNTIFS($D$22:$D$489,I2,$I$22:$I$489,$C$1) -> 72 | J5: =COUNTIFS($D$22:$D$489,J2,$I$22:$I$489,$C$1) -> 28 | ... R5: =COUNTIFS($D$22:$D$489,R2,$I$22:$I$489,$C$1) -> 6
A6: 剩餘門市 | B6: =SUM(C6:R6) -> 5 | C6: =IF(C3-C5<0,0,C3-C5) -> 0 | D6: =IF(D3-D5<0,0,D3-D5) -> 0 | E6: =IF(E3-E5<0,0,E3-E5) -> 0 | F6: =IF(F3-F5<0,0,F3-F5) -> 0 | G6: =IF(G3-G5<0,0,G3-G5) -> 0 | H6: =IF(H3-H5<0,0,H3-H5) -> 0 | I6: =IF(I3-I5<0,0,I3-I5) -> 1 | J6: =IF(J3-J5<0,0,J3-J5) -> 1 | ... R6: =IF(R3-R5<0,0,R3-R5) -> 0 | S6: =IF(#REF!-#REF!<0,0) -> #REF!
A7: =D1 -> +SC7 | B7: =SUM(C7:R7) -> 23 | C7: =COUNTIFS('0919門市清單主檔'!$V:$V,C2,'0919門市清單主檔'!$AF:$AF,$D$1, '0919門市清單主檔'!$AA:$AA,"<>新開不保養", '0919門市清單主檔'!$AA:$AA,"<>閉店不保養" ) -> 0 | D7: =COUNTIFS('0919門市清單主檔'!$V:$V,D2,'0919門市清單主檔'!$AF:$AF,$D$1, '0919門市清單主檔'!$AA:$AA,"<>新開不保養", '0919門市清單主檔'!$AA:$AA,"<>閉店不保養" ) -> 0 | E7: =COUNTIFS('0919門市清單主檔'!$V:$V,E2,'0919門市清單主檔'!$AF:$AF,$D$1, '0919門市清單主檔'!$AA:$AA,"<>新開不保養", '0919門市清單主檔'!$AA:$AA,"<>閉店不保養" ) -> 3 | F7: =COUNTIFS('0919門市清單主檔'!$V:$V,F2,'0919門市清單主檔'!$AF:$AF,$D$1, '0919門市清單主檔'!$AA:$AA,"<>新開不保養", '0919門市清單主檔'!$AA:$AA,"<>閉店不保養" ) -> 0 | G7: =COUNTIFS('0919門市清單主檔'!$V:$V,G2,'0919門市清單主檔'!$AF:$AF,$D$1, '0919門市清單主檔'!$AA:$AA,"<>新開不保養", '0919門市清單主檔'!$AA:$AA,"<>閉店不保養" ) -> 1 | H7: =COUNTIFS('0919門市清單主檔'!$V:$V,H2,'0919門市清單主檔'!$AF:$AF,$D$1, '0919門市清單主檔'!$AA:$AA,"<>新開不保養", '0919門市清單主檔'!$AA:$AA,"<>閉店不保養" ) -> 1 | I7: =COUNTIFS('0919門市清單主檔'!$V:$V,I2,'0919門市清單主檔'!$AF:$AF,$D$1, '0919門市清單主檔'!$AA:$AA,"<>新開不保養", '0919門市清單主檔'!$AA:$AA,"<>閉店不保養" ) -> 3 | J7: =COUNTIFS('0919門市清單主檔'!$V:$V,J2,'0919門市清單主檔'!$AF:$AF,$D$1, '0919門市清單主檔'!$AA:$AA,"<>新開不保養", '0919門市清單主檔'!$AA:$AA,"<>閉店不保養" ) -> 3 | ... R7: =COUNTIFS('0919門市清單主檔'!$V:$V,R2,'0919門市清單主檔'!$AF:$AF,$D$1, '0919門市清單主檔'!$AA:$AA,"<>新開不保養", '0919門市清單主檔'!$AA:$AA,"<>閉店不保養" ) -> 1
A8: 完工進度 | B8: =IF(A7<>"-",B9/B7,"") -> 0.52173913 | C8: =C9/C7 -> #DIV/0! | D8: =D9/D7 -> #DIV/0! | E8: =E9/E7 -> 0 | F8: =F9/F7 -> #DIV/0! | G8: =G9/G7 -> 0 | H8: =H9/H7 -> 1 | I8: =I9/I7 -> 0.66666667 | J8: =J9/J7 -> 0 | ... R8: =R9/R7 -> 1
A9: 完工數量 | B9: =IF(A7<>"-",SUM(C9:R9),"") -> 12 | C9: =COUNTIFS($D$22:$D$489,C2,$Q$22:$Q$489,$D$1,$F$22:$F$489,"<>新開不保養",$F$22:$F$489,"<>閉店不保養") -> 0 | D9: =COUNTIFS($D$22:$D$489,D2,$Q$22:$Q$489,$D$1,$F$22:$F$489,"<>新開不保養",$F$22:$F$489,"<>閉店不保養") -> 0 | E9: =COUNTIFS($D$22:$D$489,E2,$Q$22:$Q$489,$D$1,$F$22:$F$489,"<>新開不保養",$F$22:$F$489,"<>閉店不保養") -> 0 | F9: =COUNTIFS($D$22:$D$489,F2,$Q$22:$Q$489,$D$1,$F$22:$F$489,"<>新開不保養",$F$22:$F$489,"<>閉店不保養") -> 0 | G9: =COUNTIFS($D$22:$D$489,G2,$Q$22:$Q$489,$D$1,$F$22:$F$489,"<>新開不保養",$F$22:$F$489,"<>閉店不保養") -> 0 | H9: =COUNTIFS($D$22:$D$489,H2,$Q$22:$Q$489,$D$1,$F$22:$F$489,"<>新開不保養",$F$22:$F$489,"<>閉店不保養") -> 1 | I9: =COUNTIFS($D$22:$D$489,I2,$Q$22:$Q$489,$D$1,$F$22:$F$489,"<>新開不保養",$F$22:$F$489,"<>閉店不保養") -> 2 | J9: =COUNTIFS($D$22:$D$489,J2,$Q$22:$Q$489,$D$1,$F$22:$F$489,"<>新開不保養",$F$22:$F$489,"<>閉店不保養") -> 0 | ... R9: =COUNTIFS($D$22:$D$489,R2,$Q$22:$Q$489,$D$1,$F$22:$F$489,"<>新開不保養",$F$22:$F$489,"<>閉店不保養") -> 1
A10: 剩餘門市 | B10: =IF(A7<>"-",SUM(C10:R10),"") -> 11 | C10: =C7-C9 -> 0 | D10: =D7-D9 -> 0 | E10: =E7-E9 -> 3 | F10: =F7-F9 -> 0 | G10: =G7-G9 -> 1 | H10: =H7-H9 -> 0 | I10: =I7-I9 -> 1 | J10: =J7-J9 -> 3 | ... R10: =R7-R9 -> 0
A11: =E1 -> -- | B11: =IF(SUM(C11:R11)=0,"",(SUM(C11:R11))) | C11: =COUNTIFS('0919門市清單主檔'!$V:$V,C2,'0919門市清單主檔'!$AG:$AG,$E$1, '0919門市清單主檔'!$AA:$AA,"<>新開不保養") -> 0 | D11: =COUNTIFS('0919門市清單主檔'!$V:$V,D2,'0919門市清單主檔'!$AG:$AG,$E$1, '0919門市清單主檔'!$AA:$AA,"<>新開不保養") -> 0 | E11: =COUNTIFS('0919門市清單主檔'!$V:$V,E2,'0919門市清單主檔'!$AG:$AG,$E$1, '0919門市清單主檔'!$AA:$AA,"<>新開不保養") -> 0 | F11: =COUNTIFS('0919門市清單主檔'!$V:$V,F2,'0919門市清單主檔'!$AG:$AG,$E$1, '0919門市清單主檔'!$AA:$AA,"<>新開不保養") -> 0 | G11: =COUNTIFS('0919門市清單主檔'!$V:$V,G2,'0919門市清單主檔'!$AG:$AG,$E$1, '0919門市清單主檔'!$AA:$AA,"<>新開不保養") -> 0 | H11: =COUNTIFS('0919門市清單主檔'!$V:$V,H2,'0919門市清單主檔'!$AG:$AG,$E$1, '0919門市清單主檔'!$AA:$AA,"<>新開不保養") -> 0 | I11: =COUNTIFS('0919門市清單主檔'!$V:$V,I2,'0919門市清單主檔'!$AG:$AG,$E$1, '0919門市清單主檔'!$AA:$AA,"<>新開不保養") -> 0 | J11: =COUNTIFS('0919門市清單主檔'!$V:$V,J2,'0919門市清單主檔'!$AG:$AG,$E$1, '0919門市清單主檔'!$AA:$AA,"<>新開不保養") -> 0 | ... R11: =COUNTIFS('0919門市清單主檔'!$V:$V,R2,'0919門市清單主檔'!$AG:$AG,$E$1, '0919門市清單主檔'!$AA:$AA,"<>新開不保養") -> 0
A12: 完工進度 | B12: =IF(A11<>"--",B13/B11,"") | C12: =C13/C11 -> #DIV/0! | D12: =D13/D11 -> #DIV/0! | E12: =E13/E11 -> #DIV/0! | F12: =F13/F11 -> #DIV/0! | G12: =G13/G11 -> #DIV/0! | H12: =H13/H11 -> #DIV/0! | I12: =I13/I11 -> #DIV/0! | J12: =J13/J11 -> #DIV/0! | ... R12: =R13/R11 -> #DIV/0!
A13: 完工數量 | B13: =IF(A11<>"--",SUM(C13:R13),"") | C13: =COUNTIFS($D$22:$D$489,C2,$S$22:$S$489,$E$1,$F$22:$F$489,"<>新開不保養") -> 0 | D13: =COUNTIFS($D$22:$D$489,D2,$S$22:$S$489,$E$1,$F$22:$F$489,"<>新開不保養") -> 0 | E13: =COUNTIFS($D$22:$D$489,E2,$S$22:$S$489,$E$1,$F$22:$F$489,"<>新開不保養") -> 0 | F13: =COUNTIFS($D$22:$D$489,F2,$S$22:$S$489,$E$1,$F$22:$F$489,"<>新開不保養") -> 0 | G13: =COUNTIFS($D$22:$D$489,G2,$S$22:$S$489,$E$1,$F$22:$F$489,"<>新開不保養") -> 0 | H13: =COUNTIFS($D$22:$D$489,H2,$S$22:$S$489,$E$1,$F$22:$F$489,"<>新開不保養") -> 0 | I13: =COUNTIFS($D$22:$D$489,I2,$S$22:$S$489,$E$1,$F$22:$F$489,"<>新開不保養") -> 0 | J13: =COUNTIFS($D$22:$D$489,J2,$S$22:$S$489,$E$1,$F$22:$F$489,"<>新開不保養") -> 0 | ... R13: =COUNTIFS($D$22:$D$489,R2,$S$22:$S$489,$E$1,$F$22:$F$489,"<>新開不保養") -> 0
A14: 剩餘門市 | B14: =IF(A11<>"--",SUM(C14:R14),"") | C14: =C11-C13 -> 0 | D14: =D11-D13 -> 0 | E14: =E11-E13 -> 0 | F14: =F11-F13 -> 0 | G14: =G11-G13 -> 0 | H14: =H11-H13 -> 0 | I14: =I11-I13 -> 0 | J14: =J11-J13 -> 0 | ... R14: =R11-R13 -> 0
A15: =F1 -> -- | B15: =IF(SUM(C15:R15)=0,"",SUM(C15:R15)) | C15: =COUNTIFS('0919門市清單主檔'!$V:$V,C2,'0919門市清單主檔'!$AH:$AH,$F$1, '0919門市清單主檔'!$AA:$AA,"<>新開不保養" ) -> 0 | D15: =COUNTIFS('0919門市清單主檔'!$V:$V,D2,'0919門市清單主檔'!$AH:$AH,$F$1, '0919門市清單主檔'!$AA:$AA,"<>新開不保養" ) -> 0 | E15: =COUNTIFS('0919門市清單主檔'!$V:$V,E2,'0919門市清單主檔'!$AH:$AH,$F$1, '0919門市清單主檔'!$AA:$AA,"<>新開不保養" ) -> 0 | F15: =COUNTIFS('0919門市清單主檔'!$V:$V,F2,'0919門市清單主檔'!$AH:$AH,$F$1, '0919門市清單主檔'!$AA:$AA,"<>新開不保養" ) -> 0 | G15: =COUNTIFS('0919門市清單主檔'!$V:$V,G2,'0919門市清單主檔'!$AH:$AH,$F$1, '0919門市清單主檔'!$AA:$AA,"<>新開不保養" ) -> 0 | H15: =COUNTIFS('0919門市清單主檔'!$V:$V,H2,'0919門市清單主檔'!$AH:$AH,$F$1, '0919門市清單主檔'!$AA:$AA,"<>新開不保養" ) -> 0 | I15: =COUNTIFS('0919門市清單主檔'!$V:$V,I2,'0919門市清單主檔'!$AH:$AH,$F$1, '0919門市清單主檔'!$AA:$AA,"<>新開不保養" ) -> 0 | J15: =COUNTIFS('0919門市清單主檔'!$V:$V,J2,'0919門市清單主檔'!$AH:$AH,$F$1, '0919門市清單主檔'!$AA:$AA,"<>新開不保養" ) -> 0 | ... R15: =COUNTIFS('0919門市清單主檔'!$V:$V,R2,'0919門市清單主檔'!$AH:$AH,$F$1, '0919門市清單主檔'!$AA:$AA,"<>新開不保養" ) -> 0
A16: 完工進度 | B16: =IF(A15<>"--",B17/B15,"") | C16: =C17/C15 -> #DIV/0! | D16: =D17/D15 -> #DIV/0! | E16: =E17/E15 -> #DIV/0! | F16: =F17/F15 -> #DIV/0! | G16: =G17/G15 -> #DIV/0! | H16: =H17/H15 -> #DIV/0! | I16: =I17/I15 -> #DIV/0! | J16: =J17/J15 -> #DIV/0! | ... R16: =R17/R15 -> #DIV/0!
A17: 完工數量 | B17: =IF(A15<>"--",SUM(C17:R17),"") | C17: =COUNTIFS($D$22:$D$489,C2,$U$22:$U$489,$F$1,$F$22:$F$489,"<>新開不保養") -> 0 | D17: =COUNTIFS($D$22:$D$489,D2,$U$22:$U$489,$F$1,$F$22:$F$489,"<>新開不保養") -> 0 | E17: =COUNTIFS($D$22:$D$489,E2,$U$22:$U$489,$F$1,$F$22:$F$489,"<>新開不保養") -> 0 | F17: =COUNTIFS($D$22:$D$489,F2,$U$22:$U$489,$F$1,$F$22:$F$489,"<>新開不保養") -> 0 | G17: =COUNTIFS($D$22:$D$489,G2,$U$22:$U$489,$F$1,$F$22:$F$489,"<>新開不保養") -> 0 | H17: =COUNTIFS($D$22:$D$489,H2,$U$22:$U$489,$F$1,$F$22:$F$489,"<>新開不保養") -> 0 | I17: =COUNTIFS($D$22:$D$489,I2,$U$22:$U$489,$F$1,$F$22:$F$489,"<>新開不保養") -> 0 | J17: =COUNTIFS($D$22:$D$489,J2,$U$22:$U$489,$F$1,$F$22:$F$489,"<>新開不保養") -> 0 | ... R17: =COUNTIFS($D$22:$D$489,R2,$U$22:$U$489,$F$1,$F$22:$F$489,"<>新開不保養") -> 0
A18: 剩餘門市 | B18: =IF(A15<>"--",SUM(C18:R18),"") | C18: =C15-C17 -> 0 | D18: =D15-D17 -> 0 | E18: =E15-E17 -> 0 | F18: =F15-F17 -> 0 | G18: =G15-G17 -> 0 | H18: =H15-H17 -> 0 | I18: =I15-I17 -> 0 | J18: =J15-J17 -> 0 | ... R18: =R15-R17 -> 0
A19: 撤店 | B19: =SUM(C19:R19) -> 6 | C19: =COUNTIFS($D$22:$D$482,C2,$F$22:$F$482,"*閉店不保養*") -> 0 | D19: =COUNTIFS($D$22:$D$482,D2,$F$22:$F$482,"*閉店不保養*") -> 0 | E19: =COUNTIFS($D$22:$D$482,E2,$F$22:$F$482,"*閉店不保養*") -> 0 | F19: =COUNTIFS($D$22:$D$482,F2,$F$22:$F$482,"*閉店不保養*") -> 0 | G19: =COUNTIFS($D$22:$D$482,G2,$F$22:$F$482,"*閉店不保養*") -> 0 | H19: =COUNTIFS($D$22:$D$482,H2,$F$22:$F$482,"*閉店不保養*") -> 0 | I19: =COUNTIFS($D$22:$D$482,I2,$F$22:$F$482,"*閉店不保養*") -> 1 | J19: =COUNTIFS($D$22:$D$482,J2,$F$22:$F$482,"*閉店不保養*") -> 1 | ... R19: =COUNTIFS($D$22:$D$482,R2,$F$22:$F$482,"*閉店不保養*") -> 0 | S19: =COUNTIFS($D$22:$D$291,#REF!,$F$22:$F$291,"*撤店*") -> 0
A20: 新開 | B20: =SUM(C20:R20) -> 2 | C20: =COUNTIFS($D$22:$D$482,C2,$F$22:$F$482,"新開不保養") -> 0 | D20: =COUNTIFS($D$22:$D$482,D2,$F$22:$F$482,"新開不保養") -> 0 | E20: =COUNTIFS($D$22:$D$482,E2,$F$22:$F$482,"新開不保養") -> 0 | F20: =COUNTIFS($D$22:$D$482,F2,$F$22:$F$482,"新開不保養") -> 0 | G20: =COUNTIFS($D$22:$D$482,G2,$F$22:$F$482,"新開不保養") -> 0 | H20: =COUNTIFS($D$22:$D$482,H2,$F$22:$F$482,"新開不保養") -> 0 | I20: =COUNTIFS($D$22:$D$482,I2,$F$22:$F$482,"新開不保養") -> 0 | J20: =COUNTIFS($D$22:$D$482,J2,$F$22:$F$482,"新開不保養") -> 0 | ... R20: =COUNTIFS($D$22:$D$482,R2,$F$22:$F$482,"新開不保養") -> 0
A21: 門市編號 | B21: 門市名稱 | C21: 縣市別 | D21: 鄉鎮市區 | E21: 工程師 | F21: 門市狀態 | G21: 門市屬性 | H21: 保養單 | I21: PMQ_ 檢核 | J21: 完工檢核2 | K21: iM筆數 | L21: iMainte | M21: 專案檢核 | N21: HUB | O21: 完工檢核 | P21: 完工確認 | Q21: 專案1檢核 | R21: 完成日期 | S21: 專案2檢核 | T21: 完成日期 | U21: 專案3檢核 | V21: 完成日期 | W21: HUB | X21: EDC | Y21: NAME | Z21: NO
A22: 3921 | B22: =_xlfn.XLOOKUP(A22,'0919門市清單主檔'!B:B,'0919門市清單主檔'!C:C,"") -> 五股福鑫店 | C22: =_xlfn.XLOOKUP($A22,'0919門市清單主檔'!B:B,'0919門市清單主檔'!U:U,"") -> 新北市 | D22: =_xlfn.XLOOKUP($A22,'0919門市清單主檔'!B:B,'0919門市清單主檔'!V:V,"") -> 五股區 | E22: =_xlfn.XLOOKUP(D22,門市狀態!G:G,門市狀態!H:H,"") -> 湯家瑋 | F22: =IFERROR(IF(VLOOKUP(A22,門市狀態!A:D,4,FALSE)=0,"",VLOOKUP(A22,門市狀態!A:D,4,FALSE)),"") | H22: =IF(I22>0,(TEXT(I22,"yyyymmdd")&$V$2&A22&$V$2&B22&$S$2),"") -> PMQ2-3921-五股福鑫店(定保) | I22: {=IF(AND(SUMPRODUCT((IM!$F$2:$F$5000=A22)*(ISNUMBER(SEARCH($C$1, IM!$AC$2:$AC$5000))))>0), $C$1, "")} -> PMQ2 | J22: {=IFERROR(INDEX(IM!$AM$2:$AM$5000, MATCH(1, (IM!$F$2:$F$5000=A22) * (ISNUMBER(SEARCH($C$1, IM!$AC$2:$AC$5000))), 0)), "")} -> 46113 | K22: {=SUMPRODUCT((IM!$F$2:$F$5000=A22)*(IM!$AD$2:$AD$5000="O")*(ISNUMBER(SEARCH($C$1, IM!$AC$2:$AC$5000))))} -> 1 | L22: {=IF(K22>0,IFERROR(HYPERLINK("#'IM'!AC"&MATCH(1,(IM!$F$1:$F$5000=A22)*(ISNUMBER(SEARCH($C$1,IM!$AC$1:$AC$5000))),0),"檢核"),"未登錄"),"")} -> 檢核 | M22: =Q22&S22&U22&W22&X22 -> +EDC | N22: {=IF(AND( SUMPRODUCT( (IM!$F$2:$F$522=A22) * ISNUMBER(SEARCH("*HUB*", IM!$AC$2:$AC$522)) * (IM!$X$2:$X$522>=$A$1) * (IM!$X$2:$X$522<=$B$1)*(W22="HUB") ) > 0 ), "HUB", "")} | O22: =IF( IFERROR(VLOOKUP(A22,門市主檔!A:I,9,FALSE),"")<>$C$1, "未完工", IF( AND($D$1="--",$E$1="--",$F$1="--"), "已完工", IF( OR( AND($D$1<>"--", IFERROR(VLOOKUP(A22,'0919門市清單主檔'!B:AH,31,FALSE),"")=$D$1, IFERROR(VLOOKUP(A22,門市主檔!A:Q,17,FALSE),"")<>$D$1), AND($E$1<>"--", IFERROR(VLOOKUP(A22,'0919門市清單主檔'!B:AH,32,FALSE),"")=$E$1, IFERROR(VLOOKUP(A22,門市主檔!A:S,19,FALSE),"")<>$E$1), AND($F$1<>"--", IFERROR(VLOOKUP(A22,'0919門市清單主檔'!B:AH,33,FALSE),"")=$F$1, IFERROR(VLOOKUP(A22,門市主檔!A:U,21,FALSE),"")<>$F$1), AND( IFERROR(VLOOKUP(A22,'0919門市清單主檔'!B:AC,28,FALSE),"")="+HUB", IFERROR(VLOOKUP(A22,門市主檔!A:X,23,FALSE),"")<>"+HUB" ), AND( IFERROR(VLOOKUP(A22,'0919門市清單主檔'!B:AD,29,FALSE),"")="+EDC", IFERROR(VLOOKUP(A22,門市主檔!A:X,24,FALSE),"")<>"+EDC" ) ), _xlfn.TEXTJOIN( "，", TRUE, IF(AND($D$1<>"--", IFERROR(VLOOKUP(A22,'0919門市清單主檔'!B:AH,31,FALSE),"")=$D$1, IFERROR(VLOOKUP(A22,門市主檔!A:Q,17,FALSE),"")<>$D$1), $D$1, ""), IF(AND($E$1<>"--", IFERROR(VLOOKUP(A22,'0919門市清單主檔'!B:AH,32,FALSE),"")=$E$1, IFERROR(VLOOKUP(A22,門市主檔!A:S,19,FALSE),"")<>$E$1), $E$1, ""), IF(AND($F$1<>"--", IFERROR(VLOOKUP(A22,'0919門市清單主檔'!B:AH,33,FALSE),"")=$F$1, IFERROR(VLOOKUP(A22,門市主檔!A:U,21,FALSE),"")<>$F$1), $F$1, ""), IF(AND(IFERROR(VLOOKUP(A22,'0919門市清單主檔'!B:AC,28,FALSE),"")="+HUB", IFERROR(VLOOKUP(A22,門市主檔!A:X,23,FALSE),"")<>"+HUB"), "+HUB", ""), IF(AND(IFERROR(VLOOKUP(A22,'0919門市清單主檔'!B:AD,29,FALSE),"")="+EDC", IFERROR(VLOOKUP(A22,門市主檔!A:X,24,FALSE),"")<>"+EDC"), "+EDC", "") ) & "未完工", "已完工" ) ) ) -> 已完工 | P22: =(TEXT(I22,"yyyymmdd"))&$V$2&A22&$V$2&B22&$S$2 -> PMQ2-3921-五股福鑫店(定保) | Q22: {=IF(AND(SUMPRODUCT((IM!$F$2:$F$5000=A22)*(ISNUMBER(SEARCH($D$1, IM!$AC$2:$AC$5000))))>0), $D$1, "")} | R22: {=IFERROR(INDEX(IM!$AM$2:$AM$5000, MATCH(1, (IM!$F$2:$F$5000=A22) * (ISNUMBER(SEARCH($D$1, IM!$AC$2:$AC$5000))), 0)), "")} | S22: {=IF(AND(SUMPRODUCT((IM!$F$2:$F$5000=A22)*(ISNUMBER(SEARCH($E$1, IM!$AC$2:$AC$5000))))>0), $E$1, "")} | T22: {=IFERROR(INDEX(IM!$AM$2:$AM$5000, MATCH(1, (IM!$F$2:$F$5000=A22) * (ISNUMBER(SEARCH($E$1, IM!$AC$2:$AC$5000))), 0)), "")} | U22: {=IF(AND(SUMPRODUCT((IM!$F$2:$F$5000=A22)*(ISNUMBER(SEARCH($F$1, IM!$AC$2:$AC$5000))))>0), $F$1, "")} | V22: {=IFERROR(INDEX(IM!$AM$2:$AM$5000, MATCH(1, (IM!$F$2:$F$5000=A22) * (ISNUMBER(SEARCH($F$1, IM!$AC$2:$AC$5000))), 0)), "")} | W22: {=IF( SUMPRODUCT( (IM!$F$2:$F$5000=A22)* (ISNUMBER(SEARCH($I$1,IM!$AC$2:$AC$5000)))* (IM!$X$2:$X$5000>=$A$1)* (IM!$X$2:$X$5000<=$B$1) )>0, $I$1, "" )} | X22: {=IF(AND(SUMPRODUCT((IM!$F$2:$F$5000=A22)*(ISNUMBER(SEARCH($J$1, IM!$AC$2:$AC$5000))))>0), $J$1, "")} -> +EDC | Y22: =A22 -> 3921 | Z22: =B22 -> 五股福鑫店 | AC22: =VLOOKUP(A23,門市主檔!A:I,9,FALSE) -> PMQ2
A23: 4658 | B23: =_xlfn.XLOOKUP(A23,'0919門市清單主檔'!B:B,'0919門市清單主檔'!C:C,"") -> 淡水英才店 | C23: =_xlfn.XLOOKUP($A23,'0919門市清單主檔'!B:B,'0919門市清單主檔'!U:U,"") -> 新北市 | D23: =_xlfn.XLOOKUP($A23,'0919門市清單主檔'!B:B,'0919門市清單主檔'!V:V,"") -> 淡水區 | E23: =_xlfn.XLOOKUP(D23,門市狀態!G:G,門市狀態!H:H,"") -> 吳宗鴻 | F23: =IFERROR(IF(VLOOKUP(A23,門市狀態!A:D,4,FALSE)=0,"",VLOOKUP(A23,門市狀態!A:D,4,FALSE)),"") | H23: =IF(I23>0,(TEXT(I23,"yyyymmdd")&$V$2&A23&$V$2&B23&$S$2),"") -> PMQ2-4658-淡水英才店(定保) | I23: {=IF(AND(SUMPRODUCT((IM!$F$2:$F$5000=A23)*(ISNUMBER(SEARCH($C$1, IM!$AC$2:$AC$5000))))>0), $C$1, "")} -> PMQ2 | J23: {=IFERROR(INDEX(IM!$AM$2:$AM$5000, MATCH(1, (IM!$F$2:$F$5000=A23) * (ISNUMBER(SEARCH($C$1, IM!$AC$2:$AC$5000))), 0)), "")} -> 46113 | K23: {=SUMPRODUCT((IM!$F$2:$F$5000=A23)*(IM!$AD$2:$AD$5000="O")*(ISNUMBER(SEARCH($C$1, IM!$AC$2:$AC$5000))))} -> 1 | L23: {=IF(K23>0,IFERROR(HYPERLINK("#'IM'!AC"&MATCH(1,(IM!$F$1:$F$5000=A23)*(ISNUMBER(SEARCH($C$1,IM!$AC$1:$AC$5000))),0),"檢核"),"未登錄"),"")} -> 檢核 | M23: =Q23&S23&U23&W23&X23 -> +EDC | N23: {=IF(AND( SUMPRODUCT( (IM!$F$2:$F$522=A23) * ISNUMBER(SEARCH("*HUB*", IM!$AC$2:$AC$522)) * (IM!$X$2:$X$522>=$A$1) * (IM!$X$2:$X$522<=$B$1)*(W23="HUB") ) > 0 ), "HUB", "")} | O23: =IF( IFERROR(VLOOKUP(A23,門市主檔!A:I,9,FALSE),"")<>$C$1, "未完工", IF( AND($D$1="--",$E$1="--",$F$1="--"), "已完工", IF( OR( AND($D$1<>"--", IFERROR(VLOOKUP(A23,'0919門市清單主檔'!B:AH,31,FALSE),"")=$D$1, IFERROR(VLOOKUP(A23,門市主檔!A:Q,17,FALSE),"")<>$D$1), AND($E$1<>"--", IFERROR(VLOOKUP(A23,'0919門市清單主檔'!B:AH,32,FALSE),"")=$E$1, IFERROR(VLOOKUP(A23,門市主檔!A:S,19,FALSE),"")<>$E$1), AND($F$1<>"--", IFERROR(VLOOKUP(A23,'0919門市清單主檔'!B:AH,33,FALSE),"")=$F$1, IFERROR(VLOOKUP(A23,門市主檔!A:U,21,FALSE),"")<>$F$1), AND( IFERROR(VLOOKUP(A23,'0919門市清單主檔'!B:AC,28,FALSE),"")="+HUB", IFERROR(VLOOKUP(A23,門市主檔!A:X,23,FALSE),"")<>"+HUB" ), AND( IFERROR(VLOOKUP(A23,'0919門市清單主檔'!B:AD,29,FALSE),"")="+EDC", IFERROR(VLOOKUP(A23,門市主檔!A:X,24,FALSE),"")<>"+EDC" ) ), _xlfn.TEXTJOIN( "，", TRUE, IF(AND($D$1<>"--", IFERROR(VLOOKUP(A23,'0919門市清單主檔'!B:AH,31,FALSE),"")=$D$1, IFERROR(VLOOKUP(A23,門市主檔!A:Q,17,FALSE),"")<>$D$1), $D$1, ""), IF(AND($E$1<>"--", IFERROR(VLOOKUP(A23,'0919門市清單主檔'!B:AH,32,FALSE),"")=$E$1, IFERROR(VLOOKUP(A23,門市主檔!A:S,19,FALSE),"")<>$E$1), $E$1, ""), IF(AND($F$1<>"--", IFERROR(VLOOKUP(A23,'0919門市清單主檔'!B:AH,33,FALSE),"")=$F$1, IFERROR(VLOOKUP(A23,門市主檔!A:U,21,FALSE),"")<>$F$1), $F$1, ""), IF(AND(IFERROR(VLOOKUP(A23,'0919門市清單主檔'!B:AC,28,FALSE),"")="+HUB", IFERROR(VLOOKUP(A23,門市主檔!A:X,23,FALSE),"")<>"+HUB"), "+HUB", ""), IF(AND(IFERROR(VLOOKUP(A23,'0919門市清單主檔'!B:AD,29,FALSE),"")="+EDC", IFERROR(VLOOKUP(A23,門市主檔!A:X,24,FALSE),"")<>"+EDC"), "+EDC", "") ) & "未完工", "已完工" ) ) ) -> 已完工 | P23: =(TEXT(I23,"yyyymmdd"))&$V$2&A23&$V$2&B23&$S$2 -> PMQ2-4658-淡水英才店(定保) | Q23: {=IF(AND(SUMPRODUCT((IM!$F$2:$F$5000=A23)*(ISNUMBER(SEARCH($D$1, IM!$AC$2:$AC$5000))))>0), $D$1, "")} | R23: {=IFERROR(INDEX(IM!$AM$2:$AM$5000, MATCH(1, (IM!$F$2:$F$5000=A23) * (ISNUMBER(SEARCH($D$1, IM!$AC$2:$AC$5000))), 0)), "")} | S23: {=IF(AND(SUMPRODUCT((IM!$F$2:$F$5000=A23)*(ISNUMBER(SEARCH($E$1, IM!$AC$2:$AC$5000))))>0), $E$1, "")} | T23: {=IFERROR(INDEX(IM!$AM$2:$AM$5000, MATCH(1, (IM!$F$2:$F$5000=A23) * (ISNUMBER(SEARCH($E$1, IM!$AC$2:$AC$5000))), 0)), "")} | U23: {=IF(AND(SUMPRODUCT((IM!$F$2:$F$5000=A23)*(ISNUMBER(SEARCH($F$1, IM!$AC$2:$AC$5000))))>0), $F$1, "")} | V23: {=IFERROR(INDEX(IM!$AM$2:$AM$5000, MATCH(1, (IM!$F$2:$F$5000=A23) * (ISNUMBER(SEARCH($F$1, IM!$AC$2:$AC$5000))), 0)), "")} | W23: {=IF( SUMPRODUCT( (IM!$F$2:$F$5000=A23)* (ISNUMBER(SEARCH($I$1,IM!$AC$2:$AC$5000)))* (IM!$X$2:$X$5000>=$A$1)* (IM!$X$2:$X$5000<=$B$1) )>0, $I$1, "" )} | X23: {=IF(AND(SUMPRODUCT((IM!$F$2:$F$5000=A23)*(ISNUMBER(SEARCH($J$1, IM!$AC$2:$AC$5000))))>0), $J$1, "")} -> +EDC | Y23: =A23 -> 4658 | Z23: =B23 -> 淡水英才店
A24: A171 | B24: =_xlfn.XLOOKUP(A24,'0919門市清單主檔'!B:B,'0919門市清單主檔'!C:C,"") -> 淡水金龍店 | C24: =_xlfn.XLOOKUP($A24,'0919門市清單主檔'!B:B,'0919門市清單主檔'!U:U,"") -> 新北市 | D24: =_xlfn.XLOOKUP($A24,'0919門市清單主檔'!B:B,'0919門市清單主檔'!V:V,"") -> 淡水區 | E24: =_xlfn.XLOOKUP(D24,門市狀態!G:G,門市狀態!H:H,"") -> 吳宗鴻 | F24: =IFERROR(IF(VLOOKUP(A24,門市狀態!A:D,4,FALSE)=0,"",VLOOKUP(A24,門市狀態!A:D,4,FALSE)),"") | H24: =IF(I24>0,(TEXT(I24,"yyyymmdd")&$V$2&A24&$V$2&B24&$S$2),"") -> PMQ2-A171-淡水金龍店(定保) | I24: {=IF(AND(SUMPRODUCT((IM!$F$2:$F$5000=A24)*(ISNUMBER(SEARCH($C$1, IM!$AC$2:$AC$5000))))>0), $C$1, "")} -> PMQ2 | J24: {=IFERROR(INDEX(IM!$AM$2:$AM$5000, MATCH(1, (IM!$F$2:$F$5000=A24) * (ISNUMBER(SEARCH($C$1, IM!$AC$2:$AC$5000))), 0)), "")} -> 46113 | K24: {=SUMPRODUCT((IM!$F$2:$F$5000=A24)*(IM!$AD$2:$AD$5000="O")*(ISNUMBER(SEARCH($C$1, IM!$AC$2:$AC$5000))))} -> 1 | L24: {=IF(K24>0,IFERROR(HYPERLINK("#'IM'!AC"&MATCH(1,(IM!$F$1:$F$5000=A24)*(ISNUMBER(SEARCH($C$1,IM!$AC$1:$AC$5000))),0),"檢核"),"未登錄"),"")} -> 檢核 | M24: =Q24&S24&U24&W24&X24 -> +EDC | N24: {=IF(AND( SUMPRODUCT( (IM!$F$2:$F$522=A24) * ISNUMBER(SEARCH("*HUB*", IM!$AC$2:$AC$522)) * (IM!$X$2:$X$522>=$A$1) * (IM!$X$2:$X$522<=$B$1)*(W24="HUB") ) > 0 ), "HUB", "")} | O24: =IF( IFERROR(VLOOKUP(A24,門市主檔!A:I,9,FALSE),"")<>$C$1, "未完工", IF( AND($D$1="--",$E$1="--",$F$1="--"), "已完工", IF( OR( AND($D$1<>"--", IFERROR(VLOOKUP(A24,'0919門市清單主檔'!B:AH,31,FALSE),"")=$D$1, IFERROR(VLOOKUP(A24,門市主檔!A:Q,17,FALSE),"")<>$D$1), AND($E$1<>"--", IFERROR(VLOOKUP(A24,'0919門市清單主檔'!B:AH,32,FALSE),"")=$E$1, IFERROR(VLOOKUP(A24,門市主檔!A:S,19,FALSE),"")<>$E$1), AND($F$1<>"--", IFERROR(VLOOKUP(A24,'0919門市清單主檔'!B:AH,33,FALSE),"")=$F$1, IFERROR(VLOOKUP(A24,門市主檔!A:U,21,FALSE),"")<>$F$1), AND( IFERROR(VLOOKUP(A24,'0919門市清單主檔'!B:AC,28,FALSE),"")="+HUB", IFERROR(VLOOKUP(A24,門市主檔!A:X,23,FALSE),"")<>"+HUB" ), AND( IFERROR(VLOOKUP(A24,'0919門市清單主檔'!B:AD,29,FALSE),"")="+EDC", IFERROR(VLOOKUP(A24,門市主檔!A:X,24,FALSE),"")<>"+EDC" ) ), _xlfn.TEXTJOIN( "，", TRUE, IF(AND($D$1<>"--", IFERROR(VLOOKUP(A24,'0919門市清單主檔'!B:AH,31,FALSE),"")=$D$1, IFERROR(VLOOKUP(A24,門市主檔!A:Q,17,FALSE),"")<>$D$1), $D$1, ""), IF(AND($E$1<>"--", IFERROR(VLOOKUP(A24,'0919門市清單主檔'!B:AH,32,FALSE),"")=$E$1, IFERROR(VLOOKUP(A24,門市主檔!A:S,19,FALSE),"")<>$E$1), $E$1, ""), IF(AND($F$1<>"--", IFERROR(VLOOKUP(A24,'0919門市清單主檔'!B:AH,33,FALSE),"")=$F$1, IFERROR(VLOOKUP(A24,門市主檔!A:U,21,FALSE),"")<>$F$1), $F$1, ""), IF(AND(IFERROR(VLOOKUP(A24,'0919門市清單主檔'!B:AC,28,FALSE),"")="+HUB", IFERROR(VLOOKUP(A24,門市主檔!A:X,23,FALSE),"")<>"+HUB"), "+HUB", ""), IF(AND(IFERROR(VLOOKUP(A24,'0919門市清單主檔'!B:AD,29,FALSE),"")="+EDC", IFERROR(VLOOKUP(A24,門市主檔!A:X,24,FALSE),"")<>"+EDC"), "+EDC", "") ) & "未完工", "已完工" ) ) ) -> +SC7未完工 | P24: =(TEXT(I24,"yyyymmdd"))&$V$2&A24&$V$2&B24&$S$2 -> PMQ2-A171-淡水金龍店(定保) | Q24: {=IF(AND(SUMPRODUCT((IM!$F$2:$F$5000=A24)*(ISNUMBER(SEARCH($D$1, IM!$AC$2:$AC$5000))))>0), $D$1, "")} | R24: {=IFERROR(INDEX(IM!$AM$2:$AM$5000, MATCH(1, (IM!$F$2:$F$5000=A24) * (ISNUMBER(SEARCH($D$1, IM!$AC$2:$AC$5000))), 0)), "")} | S24: {=IF(AND(SUMPRODUCT((IM!$F$2:$F$5000=A24)*(ISNUMBER(SEARCH($E$1, IM!$AC$2:$AC$5000))))>0), $E$1, "")} | T24: {=IFERROR(INDEX(IM!$AM$2:$AM$5000, MATCH(1, (IM!$F$2:$F$5000=A24) * (ISNUMBER(SEARCH($E$1, IM!$AC$2:$AC$5000))), 0)), "")} | U24: {=IF(AND(SUMPRODUCT((IM!$F$2:$F$5000=A24)*(ISNUMBER(SEARCH($F$1, IM!$AC$2:$AC$5000))))>0), $F$1, "")} | V24: {=IFERROR(INDEX(IM!$AM$2:$AM$5000, MATCH(1, (IM!$F$2:$F$5000=A24) * (ISNUMBER(SEARCH($F$1, IM!$AC$2:$AC$5000))), 0)), "")} | W24: {=IF( SUMPRODUCT( (IM!$F$2:$F$5000=A24)* (ISNUMBER(SEARCH($I$1,IM!$AC$2:$AC$5000)))* (IM!$X$2:$X$5000>=$A$1)* (IM!$X$2:$X$5000<=$B$1) )>0, $I$1, "" )} | X24: {=IF(AND(SUMPRODUCT((IM!$F$2:$F$5000=A24)*(ISNUMBER(SEARCH($J$1, IM!$AC$2:$AC$5000))))>0), $J$1, "")} -> +EDC | Y24: =A24 -> A171 | Z24: =B24 -> 淡水金龍店
A25: 2318 | B25: =_xlfn.XLOOKUP(A25,'0919門市清單主檔'!B:B,'0919門市清單主檔'!C:C,"") -> 北縣淡俊店 | C25: =_xlfn.XLOOKUP($A25,'0919門市清單主檔'!B:B,'0919門市清單主檔'!U:U,"") -> 新北市 | D25: =_xlfn.XLOOKUP($A25,'0919門市清單主檔'!B:B,'0919門市清單主檔'!V:V,"") -> 淡水區 | E25: =_xlfn.XLOOKUP(D25,門市狀態!G:G,門市狀態!H:H,"") -> 吳宗鴻 | F25: =IFERROR(IF(VLOOKUP(A25,門市狀態!A:D,4,FALSE)=0,"",VLOOKUP(A25,門市狀態!A:D,4,FALSE)),"") | H25: =IF(I25>0,(TEXT(I25,"yyyymmdd")&$V$2&A25&$V$2&B25&$S$2),"") -> PMQ2-2318-北縣淡俊店(定保) | I25: {=IF(AND(SUMPRODUCT((IM!$F$2:$F$5000=A25)*(ISNUMBER(SEARCH($C$1, IM!$AC$2:$AC$5000))))>0), $C$1, "")} -> PMQ2 | J25: {=IFERROR(INDEX(IM!$AM$2:$AM$5000, MATCH(1, (IM!$F$2:$F$5000=A25) * (ISNUMBER(SEARCH($C$1, IM!$AC$2:$AC$5000))), 0)), "")} -> 46113 | K25: {=SUMPRODUCT((IM!$F$2:$F$5000=A25)*(IM!$AD$2:$AD$5000="O")*(ISNUMBER(SEARCH($C$1, IM!$AC$2:$AC$5000))))} -> 1 | L25: {=IF(K25>0,IFERROR(HYPERLINK("#'IM'!AC"&MATCH(1,(IM!$F$1:$F$5000=A25)*(ISNUMBER(SEARCH($C$1,IM!$AC$1:$AC$5000))),0),"檢核"),"未登錄"),"")} -> 檢核 | M25: =Q25&S25&U25&W25&X25 -> +EDC | N25: {=IF(AND( SUMPRODUCT( (IM!$F$2:$F$522=A25) * ISNUMBER(SEARCH("*HUB*", IM!$AC$2:$AC$522)) * (IM!$X$2:$X$522>=$A$1) * (IM!$X$2:$X$522<=$B$1)*(W25="HUB") ) > 0 ), "HUB", "")} | O25: =IF( IFERROR(VLOOKUP(A25,門市主檔!A:I,9,FALSE),"")<>$C$1, "未完工", IF( AND($D$1="--",$E$1="--",$F$1="--"), "已完工", IF( OR( AND($D$1<>"--", IFERROR(VLOOKUP(A25,'0919門市清單主檔'!B:AH,31,FALSE),"")=$D$1, IFERROR(VLOOKUP(A25,門市主檔!A:Q,17,FALSE),"")<>$D$1), AND($E$1<>"--", IFERROR(VLOOKUP(A25,'0919門市清單主檔'!B:AH,32,FALSE),"")=$E$1, IFERROR(VLOOKUP(A25,門市主檔!A:S,19,FALSE),"")<>$E$1), AND($F$1<>"--", IFERROR(VLOOKUP(A25,'0919門市清單主檔'!B:AH,33,FALSE),"")=$F$1, IFERROR(VLOOKUP(A25,門市主檔!A:U,21,FALSE),"")<>$F$1), AND( IFERROR(VLOOKUP(A25,'0919門市清單主檔'!B:AC,28,FALSE),"")="+HUB", IFERROR(VLOOKUP(A25,門市主檔!A:X,23,FALSE),"")<>"+HUB" ), AND( IFERROR(VLOOKUP(A25,'0919門市清單主檔'!B:AD,29,FALSE),"")="+EDC", IFERROR(VLOOKUP(A25,門市主檔!A:X,24,FALSE),"")<>"+EDC" ) ), _xlfn.TEXTJOIN( "，", TRUE, IF(AND($D$1<>"--", IFERROR(VLOOKUP(A25,'0919門市清單主檔'!B:AH,31,FALSE),"")=$D$1, IFERROR(VLOOKUP(A25,門市主檔!A:Q,17,FALSE),"")<>$D$1), $D$1, ""), IF(AND($E$1<>"--", IFERROR(VLOOKUP(A25,'0919門市清單主檔'!B:AH,32,FALSE),"")=$E$1, IFERROR(VLOOKUP(A25,門市主檔!A:S,19,FALSE),"")<>$E$1), $E$1, ""), IF(AND($F$1<>"--", IFERROR(VLOOKUP(A25,'0919門市清單主檔'!B:AH,33,FALSE),"")=$F$1, IFERROR(VLOOKUP(A25,門市主檔!A:U,21,FALSE),"")<>$F$1), $F$1, ""), IF(AND(IFERROR(VLOOKUP(A25,'0919門市清單主檔'!B:AC,28,FALSE),"")="+HUB", IFERROR(VLOOKUP(A25,門市主檔!A:X,23,FALSE),"")<>"+HUB"), "+HUB", ""), IF(AND(IFERROR(VLOOKUP(A25,'0919門市清單主檔'!B:AD,29,FALSE),"")="+EDC", IFERROR(VLOOKUP(A25,門市主檔!A:X,24,FALSE),"")<>"+EDC"), "+EDC", "") ) & "未完工", "已完工" ) ) ) -> 已完工 | P25: =(TEXT(I25,"yyyymmdd"))&$V$2&A25&$V$2&B25&$S$2 -> PMQ2-2318-北縣淡俊店(定保) | Q25: {=IF(AND(SUMPRODUCT((IM!$F$2:$F$5000=A25)*(ISNUMBER(SEARCH($D$1, IM!$AC$2:$AC$5000))))>0), $D$1, "")} | R25: {=IFERROR(INDEX(IM!$AM$2:$AM$5000, MATCH(1, (IM!$F$2:$F$5000=A25) * (ISNUMBER(SEARCH($D$1, IM!$AC$2:$AC$5000))), 0)), "")} | S25: {=IF(AND(SUMPRODUCT((IM!$F$2:$F$5000=A25)*(ISNUMBER(SEARCH($E$1, IM!$AC$2:$AC$5000))))>0), $E$1, "")} | T25: {=IFERROR(INDEX(IM!$AM$2:$AM$5000, MATCH(1, (IM!$F$2:$F$5000=A25) * (ISNUMBER(SEARCH($E$1, IM!$AC$2:$AC$5000))), 0)), "")} | U25: {=IF(AND(SUMPRODUCT((IM!$F$2:$F$5000=A25)*(ISNUMBER(SEARCH($F$1, IM!$AC$2:$AC$5000))))>0), $F$1, "")} | V25: {=IFERROR(INDEX(IM!$AM$2:$AM$5000, MATCH(1, (IM!$F$2:$F$5000=A25) * (ISNUMBER(SEARCH($F$1, IM!$AC$2:$AC$5000))), 0)), "")} | W25: {=IF( SUMPRODUCT( (IM!$F$2:$F$5000=A25)* (ISNUMBER(SEARCH($I$1,IM!$AC$2:$AC$5000)))* (IM!$X$2:$X$5000>=$A$1)* (IM!$X$2:$X$5000<=$B$1) )>0, $I$1, "" )} | X25: {=IF(AND(SUMPRODUCT((IM!$F$2:$F$5000=A25)*(ISNUMBER(SEARCH($J$1, IM!$AC$2:$AC$5000))))>0), $J$1, "")} -> +EDC | Y25: =A25 -> 2318 | Z25: =B25 -> 北縣淡俊店
A26: 2897 | B26: =_xlfn.XLOOKUP(A26,'0919門市清單主檔'!B:B,'0919門市清單主檔'!C:C,"") -> 淡水台電宿舍 | C26: =_xlfn.XLOOKUP($A26,'0919門市清單主檔'!B:B,'0919門市清單主檔'!U:U,"") -> 新北市 | D26: =_xlfn.XLOOKUP($A26,'0919門市清單主檔'!B:B,'0919門市清單主檔'!V:V,"") -> 淡水區 | E26: =_xlfn.XLOOKUP(D26,門市狀態!G:G,門市狀態!H:H,"") -> 吳宗鴻 | F26: =IFERROR(IF(VLOOKUP(A26,門市狀態!A:D,4,FALSE)=0,"",VLOOKUP(A26,門市狀態!A:D,4,FALSE)),"") | H26: =IF(I26>0,(TEXT(I26,"yyyymmdd")&$V$2&A26&$V$2&B26&$S$2),"") -> PMQ2-2897-淡水台電宿舍(定保) | I26: {=IF(AND(SUMPRODUCT((IM!$F$2:$F$5000=A26)*(ISNUMBER(SEARCH($C$1, IM!$AC$2:$AC$5000))))>0), $C$1, "")} -> PMQ2 | J26: {=IFERROR(INDEX(IM!$AM$2:$AM$5000, MATCH(1, (IM!$F$2:$F$5000=A26) * (ISNUMBER(SEARCH($C$1, IM!$AC$2:$AC$5000))), 0)), "")} -> 46113 | K26: {=SUMPRODUCT((IM!$F$2:$F$5000=A26)*(IM!$AD$2:$AD$5000="O")*(ISNUMBER(SEARCH($C$1, IM!$AC$2:$AC$5000))))} -> 1 | L26: {=IF(K26>0,IFERROR(HYPERLINK("#'IM'!AC"&MATCH(1,(IM!$F$1:$F$5000=A26)*(ISNUMBER(SEARCH($C$1,IM!$AC$1:$AC$5000))),0),"檢核"),"未登錄"),"")} -> 檢核 | M26: =Q26&S26&U26&W26&X26 -> +EDC | N26: {=IF(AND( SUMPRODUCT( (IM!$F$2:$F$522=A26) * ISNUMBER(SEARCH("*HUB*", IM!$AC$2:$AC$522)) * (IM!$X$2:$X$522>=$A$1) * (IM!$X$2:$X$522<=$B$1)*(W26="HUB") ) > 0 ), "HUB", "")} | O26: =IF( IFERROR(VLOOKUP(A26,門市主檔!A:I,9,FALSE),"")<>$C$1, "未完工", IF( AND($D$1="--",$E$1="--",$F$1="--"), "已完工", IF( OR( AND($D$1<>"--", IFERROR(VLOOKUP(A26,'0919門市清單主檔'!B:AH,31,FALSE),"")=$D$1, IFERROR(VLOOKUP(A26,門市主檔!A:Q,17,FALSE),"")<>$D$1), AND($E$1<>"--", IFERROR(VLOOKUP(A26,'0919門市清單主檔'!B:AH,32,FALSE),"")=$E$1, IFERROR(VLOOKUP(A26,門市主檔!A:S,19,FALSE),"")<>$E$1), AND($F$1<>"--", IFERROR(VLOOKUP(A26,'0919門市清單主檔'!B:AH,33,FALSE),"")=$F$1, IFERROR(VLOOKUP(A26,門市主檔!A:U,21,FALSE),"")<>$F$1), AND( IFERROR(VLOOKUP(A26,'0919門市清單主檔'!B:AC,28,FALSE),"")="+HUB", IFERROR(VLOOKUP(A26,門市主檔!A:X,23,FALSE),"")<>"+HUB" ), AND( IFERROR(VLOOKUP(A26,'0919門市清單主檔'!B:AD,29,FALSE),"")="+EDC", IFERROR(VLOOKUP(A26,門市主檔!A:X,24,FALSE),"")<>"+EDC" ) ), _xlfn.TEXTJOIN( "，", TRUE, IF(AND($D$1<>"--", IFERROR(VLOOKUP(A26,'0919門市清單主檔'!B:AH,31,FALSE),"")=$D$1, IFERROR(VLOOKUP(A26,門市主檔!A:Q,17,FALSE),"")<>$D$1), $D$1, ""), IF(AND($E$1<>"--", IFERROR(VLOOKUP(A26,'0919門市清單主檔'!B:AH,32,FALSE),"")=$E$1, IFERROR(VLOOKUP(A26,門市主檔!A:S,19,FALSE),"")<>$E$1), $E$1, ""), IF(AND($F$1<>"--", IFERROR(VLOOKUP(A26,'0919門市清單主檔'!B:AH,33,FALSE),"")=$F$1, IFERROR(VLOOKUP(A26,門市主檔!A:U,21,FALSE),"")<>$F$1), $F$1, ""), IF(AND(IFERROR(VLOOKUP(A26,'0919門市清單主檔'!B:AC,28,FALSE),"")="+HUB", IFERROR(VLOOKUP(A26,門市主檔!A:X,23,FALSE),"")<>"+HUB"), "+HUB", ""), IF(AND(IFERROR(VLOOKUP(A26,'0919門市清單主檔'!B:AD,29,FALSE),"")="+EDC", IFERROR(VLOOKUP(A26,門市主檔!A:X,24,FALSE),"")<>"+EDC"), "+EDC", "") ) & "未完工", "已完工" ) ) ) -> 已完工 | P26: =(TEXT(I26,"yyyymmdd"))&$V$2&A26&$V$2&B26&$S$2 -> PMQ2-2897-淡水台電宿舍(定保) | Q26: {=IF(AND(SUMPRODUCT((IM!$F$2:$F$5000=A26)*(ISNUMBER(SEARCH($D$1, IM!$AC$2:$AC$5000))))>0), $D$1, "")} | R26: {=IFERROR(INDEX(IM!$AM$2:$AM$5000, MATCH(1, (IM!$F$2:$F$5000=A26) * (ISNUMBER(SEARCH($D$1, IM!$AC$2:$AC$5000))), 0)), "")} | S26: {=IF(AND(SUMPRODUCT((IM!$F$2:$F$5000=A26)*(ISNUMBER(SEARCH($E$1, IM!$AC$2:$AC$5000))))>0), $E$1, "")} | T26: {=IFERROR(INDEX(IM!$AM$2:$AM$5000, MATCH(1, (IM!$F$2:$F$5000=A26) * (ISNUMBER(SEARCH($E$1, IM!$AC$2:$AC$5000))), 0)), "")} | U26: {=IF(AND(SUMPRODUCT((IM!$F$2:$F$5000=A26)*(ISNUMBER(SEARCH($F$1, IM!$AC$2:$AC$5000))))>0), $F$1, "")} | V26: {=IFERROR(INDEX(IM!$AM$2:$AM$5000, MATCH(1, (IM!$F$2:$F$5000=A26) * (ISNUMBER(SEARCH($F$1, IM!$AC$2:$AC$5000))), 0)), "")} | W26: {=IF( SUMPRODUCT( (IM!$F$2:$F$5000=A26)* (ISNUMBER(SEARCH($I$1,IM!$AC$2:$AC$5000)))* (IM!$X$2:$X$5000>=$A$1)* (IM!$X$2:$X$5000<=$B$1) )>0, $I$1, "" )} | X26: {=IF(AND(SUMPRODUCT((IM!$F$2:$F$5000=A26)*(ISNUMBER(SEARCH($J$1, IM!$AC$2:$AC$5000))))>0), $J$1, "")} -> +EDC | Y26: =A26 -> 2897 | Z26: =B26 -> 淡水台電宿舍
A27: 3892 | B27: =_xlfn.XLOOKUP(A27,'0919門市清單主檔'!B:B,'0919門市清單主檔'!C:C,"") -> 蘆洲光榮店 | C27: =_xlfn.XLOOKUP($A27,'0919門市清單主檔'!B:B,'0919門市清單主檔'!U:U,"") -> 新北市 | D27: =_xlfn.XLOOKUP($A27,'0919門市清單主檔'!B:B,'0919門市清單主檔'!V:V,"") -> 蘆洲區 | E27: =_xlfn.XLOOKUP(D27,門市狀態!G:G,門市狀態!H:H,"") -> 湯家瑋 | F27: =IFERROR(IF(VLOOKUP(A27,門市狀態!A:D,4,FALSE)=0,"",VLOOKUP(A27,門市狀態!A:D,4,FALSE)),"") | H27: =IF(I27>0,(TEXT(I27,"yyyymmdd")&$V$2&A27&$V$2&B27&$S$2),"") -> PMQ2-3892-蘆洲光榮店(定保) | I27: {=IF(AND(SUMPRODUCT((IM!$F$2:$F$5000=A27)*(ISNUMBER(SEARCH($C$1, IM!$AC$2:$AC$5000))))>0), $C$1, "")} -> PMQ2 | J27: {=IFERROR(INDEX(IM!$AM$2:$AM$5000, MATCH(1, (IM!$F$2:$F$5000=A27) * (ISNUMBER(SEARCH($C$1, IM!$AC$2:$AC$5000))), 0)), "")} -> 46113 | K27: {=SUMPRODUCT((IM!$F$2:$F$5000=A27)*(IM!$AD$2:$AD$5000="O")*(ISNUMBER(SEARCH($C$1, IM!$AC$2:$AC$5000))))} -> 1 | L27: {=IF(K27>0,IFERROR(HYPERLINK("#'IM'!AC"&MATCH(1,(IM!$F$1:$F$5000=A27)*(ISNUMBER(SEARCH($C$1,IM!$AC$1:$AC$5000))),0),"檢核"),"未登錄"),"")} -> 檢核 | M27: =Q27&S27&U27&W27&X27 -> +EDC | N27: {=IF(AND( SUMPRODUCT( (IM!$F$2:$F$522=A27) * ISNUMBER(SEARCH("*HUB*", IM!$AC$2:$AC$522)) * (IM!$X$2:$X$522>=$A$1) * (IM!$X$2:$X$522<=$B$1)*(W27="HUB") ) > 0 ), "HUB", "")} | O27: =IF( IFERROR(VLOOKUP(A27,門市主檔!A:I,9,FALSE),"")<>$C$1, "未完工", IF( AND($D$1="--",$E$1="--",$F$1="--"), "已完工", IF( OR( AND($D$1<>"--", IFERROR(VLOOKUP(A27,'0919門市清單主檔'!B:AH,31,FALSE),"")=$D$1, IFERROR(VLOOKUP(A27,門市主檔!A:Q,17,FALSE),"")<>$D$1), AND($E$1<>"--", IFERROR(VLOOKUP(A27,'0919門市清單主檔'!B:AH,32,FALSE),"")=$E$1, IFERROR(VLOOKUP(A27,門市主檔!A:S,19,FALSE),"")<>$E$1), AND($F$1<>"--", IFERROR(VLOOKUP(A27,'0919門市清單主檔'!B:AH,33,FALSE),"")=$F$1, IFERROR(VLOOKUP(A27,門市主檔!A:U,21,FALSE),"")<>$F$1), AND( IFERROR(VLOOKUP(A27,'0919門市清單主檔'!B:AC,28,FALSE),"")="+HUB", IFERROR(VLOOKUP(A27,門市主檔!A:X,23,FALSE),"")<>"+HUB" ), AND( IFERROR(VLOOKUP(A27,'0919門市清單主檔'!B:AD,29,FALSE),"")="+EDC", IFERROR(VLOOKUP(A27,門市主檔!A:X,24,FALSE),"")<>"+EDC" ) ), _xlfn.TEXTJOIN( "，", TRUE, IF(AND($D$1<>"--", IFERROR(VLOOKUP(A27,'0919門市清單主檔'!B:AH,31,FALSE),"")=$D$1, IFERROR(VLOOKUP(A27,門市主檔!A:Q,17,FALSE),"")<>$D$1), $D$1, ""), IF(AND($E$1<>"--", IFERROR(VLOOKUP(A27,'0919門市清單主檔'!B:AH,32,FALSE),"")=$E$1, IFERROR(VLOOKUP(A27,門市主檔!A:S,19,FALSE),"")<>$E$1), $E$1, ""), IF(AND($F$1<>"--", IFERROR(VLOOKUP(A27,'0919門市清單主檔'!B:AH,33,FALSE),"")=$F$1, IFERROR(VLOOKUP(A27,門市主檔!A:U,21,FALSE),"")<>$F$1), $F$1, ""), IF(AND(IFERROR(VLOOKUP(A27,'0919門市清單主檔'!B:AC,28,FALSE),"")="+HUB", IFERROR(VLOOKUP(A27,門市主檔!A:X,23,FALSE),"")<>"+HUB"), "+HUB", ""), IF(AND(IFERROR(VLOOKUP(A27,'0919門市清單主檔'!B:AD,29,FALSE),"")="+EDC", IFERROR(VLOOKUP(A27,門市主檔!A:X,24,FALSE),"")<>"+EDC"), "+EDC", "") ) & "未完工", "已完工" ) ) ) -> 已完工 | P27: =(TEXT(I27,"yyyymmdd"))&$V$2&A27&$V$2&B27&$S$2 -> PMQ2-3892-蘆洲光榮店(定保) | Q27: {=IF(AND(SUMPRODUCT((IM!$F$2:$F$5000=A27)*(ISNUMBER(SEARCH($D$1, IM!$AC$2:$AC$5000))))>0), $D$1, "")} | R27: {=IFERROR(INDEX(IM!$AM$2:$AM$5000, MATCH(1, (IM!$F$2:$F$5000=A27) * (ISNUMBER(SEARCH($D$1, IM!$AC$2:$AC$5000))), 0)), "")} | S27: {=IF(AND(SUMPRODUCT((IM!$F$2:$F$5000=A27)*(ISNUMBER(SEARCH($E$1, IM!$AC$2:$AC$5000))))>0), $E$1, "")} | T27: {=IFERROR(INDEX(IM!$AM$2:$AM$5000, MATCH(1, (IM!$F$2:$F$5000=A27) * (ISNUMBER(SEARCH($E$1, IM!$AC$2:$AC$5000))), 0)), "")} | U27: {=IF(AND(SUMPRODUCT((IM!$F$2:$F$5000=A27)*(ISNUMBER(SEARCH($F$1, IM!$AC$2:$AC$5000))))>0), $F$1, "")} | V27: {=IFERROR(INDEX(IM!$AM$2:$AM$5000, MATCH(1, (IM!$F$2:$F$5000=A27) * (ISNUMBER(SEARCH($F$1, IM!$AC$2:$AC$5000))), 0)), "")} | W27: {=IF( SUMPRODUCT( (IM!$F$2:$F$5000=A27)* (ISNUMBER(SEARCH($I$1,IM!$AC$2:$AC$5000)))* (IM!$X$2:$X$5000>=$A$1)* (IM!$X$2:$X$5000<=$B$1) )>0, $I$1, "" )} | X27: {=IF(AND(SUMPRODUCT((IM!$F$2:$F$5000=A27)*(ISNUMBER(SEARCH($J$1, IM!$AC$2:$AC$5000))))>0), $J$1, "")} -> +EDC | Y27: =A27 -> 3892 | Z27: =B27 -> 蘆洲光榮店
A28: C660 | B28: =_xlfn.XLOOKUP(A28,'0919門市清單主檔'!B:B,'0919門市清單主檔'!C:C,"") -> 中和永安市場 | C28: =_xlfn.XLOOKUP($A28,'0919門市清單主檔'!B:B,'0919門市清單主檔'!U:U,"") -> 新北市 | D28: =_xlfn.XLOOKUP($A28,'0919門市清單主檔'!B:B,'0919門市清單主檔'!V:V,"") -> 中和區 | E28: =_xlfn.XLOOKUP(D28,門市狀態!G:G,門市狀態!H:H,"") -> 劉柏均 | F28: =IFERROR(IF(VLOOKUP(A28,門市狀態!A:D,4,FALSE)=0,"",VLOOKUP(A28,門市狀態!A:D,4,FALSE)),"") | H28: =IF(I28>0,(TEXT(I28,"yyyymmdd")&$V$2&A28&$V$2&B28&$S$2),"") -> PMQ2-C660-中和永安市場(定保) | I28: {=IF(AND(SUMPRODUCT((IM!$F$2:$F$5000=A28)*(ISNUMBER(SEARCH($C$1, IM!$AC$2:$AC$5000))))>0), $C$1, "")} -> PMQ2 | J28: {=IFERROR(INDEX(IM!$AM$2:$AM$5000, MATCH(1, (IM!$F$2:$F$5000=A28) * (ISNUMBER(SEARCH($C$1, IM!$AC$2:$AC$5000))), 0)), "")} -> 46114 | K28: {=SUMPRODUCT((IM!$F$2:$F$5000=A28)*(IM!$AD$2:$AD$5000="O")*(ISNUMBER(SEARCH($C$1, IM!$AC$2:$AC$5000))))} -> 1 | L28: {=IF(K28>0,IFERROR(HYPERLINK("#'IM'!AC"&MATCH(1,(IM!$F$1:$F$5000=A28)*(ISNUMBER(SEARCH($C$1,IM!$AC$1:$AC$5000))),0),"檢核"),"未登錄"),"")} -> 檢核 | M28: =Q28&S28&U28&W28&X28 -> +EDC | N28: {=IF(AND( SUMPRODUCT( (IM!$F$2:$F$522=A28) * ISNUMBER(SEARCH("*HUB*", IM!$AC$2:$AC$522)) * (IM!$X$2:$X$522>=$A$1) * (IM!$X$2:$X$522<=$B$1)*(W28="HUB") ) > 0 ), "HUB", "")} | O28: =IF( IFERROR(VLOOKUP(A28,門市主檔!A:I,9,FALSE),"")<>$C$1, "未完工", IF( AND($D$1="--",$E$1="--",$F$1="--"), "已完工", IF( OR( AND($D$1<>"--", IFERROR(VLOOKUP(A28,'0919門市清單主檔'!B:AH,31,FALSE),"")=$D$1, IFERROR(VLOOKUP(A28,門市主檔!A:Q,17,FALSE),"")<>$D$1), AND($E$1<>"--", IFERROR(VLOOKUP(A28,'0919門市清單主檔'!B:AH,32,FALSE),"")=$E$1, IFERROR(VLOOKUP(A28,門市主檔!A:S,19,FALSE),"")<>$E$1), AND($F$1<>"--", IFERROR(VLOOKUP(A28,'0919門市清單主檔'!B:AH,33,FALSE),"")=$F$1, IFERROR(VLOOKUP(A28,門市主檔!A:U,21,FALSE),"")<>$F$1), AND( IFERROR(VLOOKUP(A28,'0919門市清單主檔'!B:AC,28,FALSE),"")="+HUB", IFERROR(VLOOKUP(A28,門市主檔!A:X,23,FALSE),"")<>"+HUB" ), AND( IFERROR(VLOOKUP(A28,'0919門市清單主檔'!B:AD,29,FALSE),"")="+EDC", IFERROR(VLOOKUP(A28,門市主檔!A:X,24,FALSE),"")<>"+EDC" ) ), _xlfn.TEXTJOIN( "，", TRUE, IF(AND($D$1<>"--", IFERROR(VLOOKUP(A28,'0919門市清單主檔'!B:AH,31,FALSE),"")=$D$1, IFERROR(VLOOKUP(A28,門市主檔!A:Q,17,FALSE),"")<>$D$1), $D$1, ""), IF(AND($E$1<>"--", IFERROR(VLOOKUP(A28,'0919門市清單主檔'!B:AH,32,FALSE),"")=$E$1, IFERROR(VLOOKUP(A28,門市主檔!A:S,19,FALSE),"")<>$E$1), $E$1, ""), IF(AND($F$1<>"--", IFERROR(VLOOKUP(A28,'0919門市清單主檔'!B:AH,33,FALSE),"")=$F$1, IFERROR(VLOOKUP(A28,門市主檔!A:U,21,FALSE),"")<>$F$1), $F$1, ""), IF(AND(IFERROR(VLOOKUP(A28,'0919門市清單主檔'!B:AC,28,FALSE),"")="+HUB", IFERROR(VLOOKUP(A28,門市主檔!A:X,23,FALSE),"")<>"+HUB"), "+HUB", ""), IF(AND(IFERROR(VLOOKUP(A28,'0919門市清單主檔'!B:AD,29,FALSE),"")="+EDC", IFERROR(VLOOKUP(A28,門市主檔!A:X,24,FALSE),"")<>"+EDC"), "+EDC", "") ) & "未完工", "已完工" ) ) ) -> 已完工 | P28: =(TEXT(I28,"yyyymmdd"))&$V$2&A28&$V$2&B28&$S$2 -> PMQ2-C660-中和永安市場(定保) | Q28: {=IF(AND(SUMPRODUCT((IM!$F$2:$F$5000=A28)*(ISNUMBER(SEARCH($D$1, IM!$AC$2:$AC$5000))))>0), $D$1, "")} | R28: {=IFERROR(INDEX(IM!$AM$2:$AM$5000, MATCH(1, (IM!$F$2:$F$5000=A28) * (ISNUMBER(SEARCH($D$1, IM!$AC$2:$AC$5000))), 0)), "")} | S28: {=IF(AND(SUMPRODUCT((IM!$F$2:$F$5000=A28)*(ISNUMBER(SEARCH($E$1, IM!$AC$2:$AC$5000))))>0), $E$1, "")} | T28: {=IFERROR(INDEX(IM!$AM$2:$AM$5000, MATCH(1, (IM!$F$2:$F$5000=A28) * (ISNUMBER(SEARCH($E$1, IM!$AC$2:$AC$5000))), 0)), "")} | U28: {=IF(AND(SUMPRODUCT((IM!$F$2:$F$5000=A28)*(ISNUMBER(SEARCH($F$1, IM!$AC$2:$AC$5000))))>0), $F$1, "")} | V28: {=IFERROR(INDEX(IM!$AM$2:$AM$5000, MATCH(1, (IM!$F$2:$F$5000=A28) * (ISNUMBER(SEARCH($F$1, IM!$AC$2:$AC$5000))), 0)), "")} | W28: {=IF( SUMPRODUCT( (IM!$F$2:$F$5000=A28)* (ISNUMBER(SEARCH($I$1,IM!$AC$2:$AC$5000)))* (IM!$X$2:$X$5000>=$A$1)* (IM!$X$2:$X$5000<=$B$1) )>0, $I$1, "" )} | X28: {=IF(AND(SUMPRODUCT((IM!$F$2:$F$5000=A28)*(ISNUMBER(SEARCH($J$1, IM!$AC$2:$AC$5000))))>0), $J$1, "")} -> +EDC | Y28: =A28 -> C660 | Z28: =B28 -> 中和永安市場 | AA28: L90未執行
A29: 3929 | B29: =_xlfn.XLOOKUP(A29,'0919門市清單主檔'!B:B,'0919門市清單主檔'!C:C,"") -> 蘆洲中山一 | C29: =_xlfn.XLOOKUP($A29,'0919門市清單主檔'!B:B,'0919門市清單主檔'!U:U,"") -> 新北市 | D29: =_xlfn.XLOOKUP($A29,'0919門市清單主檔'!B:B,'0919門市清單主檔'!V:V,"") -> 蘆洲區 | E29: =_xlfn.XLOOKUP(D29,門市狀態!G:G,門市狀態!H:H,"") -> 湯家瑋 | F29: =IFERROR(IF(VLOOKUP(A29,門市狀態!A:D,4,FALSE)=0,"",VLOOKUP(A29,門市狀態!A:D,4,FALSE)),"") | H29: =IF(I29>0,(TEXT(I29,"yyyymmdd")&$V$2&A29&$V$2&B29&$S$2),"") -> PMQ2-3929-蘆洲中山一(定保) | I29: {=IF(AND(SUMPRODUCT((IM!$F$2:$F$5000=A29)*(ISNUMBER(SEARCH($C$1, IM!$AC$2:$AC$5000))))>0), $C$1, "")} -> PMQ2 | J29: {=IFERROR(INDEX(IM!$AM$2:$AM$5000, MATCH(1, (IM!$F$2:$F$5000=A29) * (ISNUMBER(SEARCH($C$1, IM!$AC$2:$AC$5000))), 0)), "")} -> 46114 | K29: {=SUMPRODUCT((IM!$F$2:$F$5000=A29)*(IM!$AD$2:$AD$5000="O")*(ISNUMBER(SEARCH($C$1, IM!$AC$2:$AC$5000))))} -> 1 | L29: {=IF(K29>0,IFERROR(HYPERLINK("#'IM'!AC"&MATCH(1,(IM!$F$1:$F$5000=A29)*(ISNUMBER(SEARCH($C$1,IM!$AC$1:$AC$5000))),0),"檢核"),"未登錄"),"")} -> 檢核 | M29: =Q29&S29&U29&W29&X29 -> +EDC | N29: {=IF(AND( SUMPRODUCT( (IM!$F$2:$F$522=A29) * ISNUMBER(SEARCH("*HUB*", IM!$AC$2:$AC$522)) * (IM!$X$2:$X$522>=$A$1) * (IM!$X$2:$X$522<=$B$1)*(W29="HUB") ) > 0 ), "HUB", "")} | O29: =IF( IFERROR(VLOOKUP(A29,門市主檔!A:I,9,FALSE),"")<>$C$1, "未完工", IF( AND($D$1="--",$E$1="--",$F$1="--"), "已完工", IF( OR( AND($D$1<>"--", IFERROR(VLOOKUP(A29,'0919門市清單主檔'!B:AH,31,FALSE),"")=$D$1, IFERROR(VLOOKUP(A29,門市主檔!A:Q,17,FALSE),"")<>$D$1), AND($E$1<>"--", IFERROR(VLOOKUP(A29,'0919門市清單主檔'!B:AH,32,FALSE),"")=$E$1, IFERROR(VLOOKUP(A29,門市主檔!A:S,19,FALSE),"")<>$E$1), AND($F$1<>"--", IFERROR(VLOOKUP(A29,'0919門市清單主檔'!B:AH,33,FALSE),"")=$F$1, IFERROR(VLOOKUP(A29,門市主檔!A:U,21,FALSE),"")<>$F$1), AND( IFERROR(VLOOKUP(A29,'0919門市清單主檔'!B:AC,28,FALSE),"")="+HUB", IFERROR(VLOOKUP(A29,門市主檔!A:X,23,FALSE),"")<>"+HUB" ), AND( IFERROR(VLOOKUP(A29,'0919門市清單主檔'!B:AD,29,FALSE),"")="+EDC", IFERROR(VLOOKUP(A29,門市主檔!A:X,24,FALSE),"")<>"+EDC" ) ), _xlfn.TEXTJOIN( "，", TRUE, IF(AND($D$1<>"--", IFERROR(VLOOKUP(A29,'0919門市清單主檔'!B:AH,31,FALSE),"")=$D$1, IFERROR(VLOOKUP(A29,門市主檔!A:Q,17,FALSE),"")<>$D$1), $D$1, ""), IF(AND($E$1<>"--", IFERROR(VLOOKUP(A29,'0919門市清單主檔'!B:AH,32,FALSE),"")=$E$1, IFERROR(VLOOKUP(A29,門市主檔!A:S,19,FALSE),"")<>$E$1), $E$1, ""), IF(AND($F$1<>"--", IFERROR(VLOOKUP(A29,'0919門市清單主檔'!B:AH,33,FALSE),"")=$F$1, IFERROR(VLOOKUP(A29,門市主檔!A:U,21,FALSE),"")<>$F$1), $F$1, ""), IF(AND(IFERROR(VLOOKUP(A29,'0919門市清單主檔'!B:AC,28,FALSE),"")="+HUB", IFERROR(VLOOKUP(A29,門市主檔!A:X,23,FALSE),"")<>"+HUB"), "+HUB", ""), IF(AND(IFERROR(VLOOKUP(A29,'0919門市清單主檔'!B:AD,29,FALSE),"")="+EDC", IFERROR(VLOOKUP(A29,門市主檔!A:X,24,FALSE),"")<>"+EDC"), "+EDC", "") ) & "未完工", "已完工" ) ) ) -> 已完工 | P29: =(TEXT(I29,"yyyymmdd"))&$V$2&A29&$V$2&B29&$S$2 -> PMQ2-3929-蘆洲中山一(定保) | Q29: {=IF(AND(SUMPRODUCT((IM!$F$2:$F$5000=A29)*(ISNUMBER(SEARCH($D$1, IM!$AC$2:$AC$5000))))>0), $D$1, "")} | R29: {=IFERROR(INDEX(IM!$AM$2:$AM$5000, MATCH(1, (IM!$F$2:$F$5000=A29) * (ISNUMBER(SEARCH($D$1, IM!$AC$2:$AC$5000))), 0)), "")} | S29: {=IF(AND(SUMPRODUCT((IM!$F$2:$F$5000=A29)*(ISNUMBER(SEARCH($E$1, IM!$AC$2:$AC$5000))))>0), $E$1, "")} | T29: {=IFERROR(INDEX(IM!$AM$2:$AM$5000, MATCH(1, (IM!$F$2:$F$5000=A29) * (ISNUMBER(SEARCH($E$1, IM!$AC$2:$AC$5000))), 0)), "")} | U29: {=IF(AND(SUMPRODUCT((IM!$F$2:$F$5000=A29)*(ISNUMBER(SEARCH($F$1, IM!$AC$2:$AC$5000))))>0), $F$1, "")} | V29: {=IFERROR(INDEX(IM!$AM$2:$AM$5000, MATCH(1, (IM!$F$2:$F$5000=A29) * (ISNUMBER(SEARCH($F$1, IM!$AC$2:$AC$5000))), 0)), "")} | W29: {=IF( SUMPRODUCT( (IM!$F$2:$F$5000=A29)* (ISNUMBER(SEARCH($I$1,IM!$AC$2:$AC$5000)))* (IM!$X$2:$X$5000>=$A$1)* (IM!$X$2:$X$5000<=$B$1) )>0, $I$1, "" )} | X29: {=IF(AND(SUMPRODUCT((IM!$F$2:$F$5000=A29)*(ISNUMBER(SEARCH($J$1, IM!$AC$2:$AC$5000))))>0), $J$1, "")} -> +EDC | Y29: =A29 -> 3929 | Z29: =B29 -> 蘆洲中山一
A30: D193 | B30: =_xlfn.XLOOKUP(A30,'0919門市清單主檔'!B:B,'0919門市清單主檔'!C:C,"") -> 蘆洲權義店 | C30: =_xlfn.XLOOKUP($A30,'0919門市清單主檔'!B:B,'0919門市清單主檔'!U:U,"") -> 新北市 | D30: =_xlfn.XLOOKUP($A30,'0919門市清單主檔'!B:B,'0919門市清單主檔'!V:V,"") -> 蘆洲區 | E30: =_xlfn.XLOOKUP(D30,門市狀態!G:G,門市狀態!H:H,"") -> 湯家瑋 | F30: =IFERROR(IF(VLOOKUP(A30,門市狀態!A:D,4,FALSE)=0,"",VLOOKUP(A30,門市狀態!A:D,4,FALSE)),"") | H30: =IF(I30>0,(TEXT(I30,"yyyymmdd")&$V$2&A30&$V$2&B30&$S$2),"") -> PMQ2-D193-蘆洲權義店(定保) | I30: {=IF(AND(SUMPRODUCT((IM!$F$2:$F$5000=A30)*(ISNUMBER(SEARCH($C$1, IM!$AC$2:$AC$5000))))>0), $C$1, "")} -> PMQ2 | J30: {=IFERROR(INDEX(IM!$AM$2:$AM$5000, MATCH(1, (IM!$F$2:$F$5000=A30) * (ISNUMBER(SEARCH($C$1, IM!$AC$2:$AC$5000))), 0)), "")} -> 46114 | K30: {=SUMPRODUCT((IM!$F$2:$F$5000=A30)*(IM!$AD$2:$AD$5000="O")*(ISNUMBER(SEARCH($C$1, IM!$AC$2:$AC$5000))))} -> 1 | L30: {=IF(K30>0,IFERROR(HYPERLINK("#'IM'!AC"&MATCH(1,(IM!$F$1:$F$5000=A30)*(ISNUMBER(SEARCH($C$1,IM!$AC$1:$AC$5000))),0),"檢核"),"未登錄"),"")} -> 檢核 | M30: =Q30&S30&U30&W30&X30 -> +EDC | N30: {=IF(AND( SUMPRODUCT( (IM!$F$2:$F$522=A30) * ISNUMBER(SEARCH("*HUB*", IM!$AC$2:$AC$522)) * (IM!$X$2:$X$522>=$A$1) * (IM!$X$2:$X$522<=$B$1)*(W30="HUB") ) > 0 ), "HUB", "")} | O30: =IF( IFERROR(VLOOKUP(A30,門市主檔!A:I,9,FALSE),"")<>$C$1, "未完工", IF( AND($D$1="--",$E$1="--",$F$1="--"), "已完工", IF( OR( AND($D$1<>"--", IFERROR(VLOOKUP(A30,'0919門市清單主檔'!B:AH,31,FALSE),"")=$D$1, IFERROR(VLOOKUP(A30,門市主檔!A:Q,17,FALSE),"")<>$D$1), AND($E$1<>"--", IFERROR(VLOOKUP(A30,'0919門市清單主檔'!B:AH,32,FALSE),"")=$E$1, IFERROR(VLOOKUP(A30,門市主檔!A:S,19,FALSE),"")<>$E$1), AND($F$1<>"--", IFERROR(VLOOKUP(A30,'0919門市清單主檔'!B:AH,33,FALSE),"")=$F$1, IFERROR(VLOOKUP(A30,門市主檔!A:U,21,FALSE),"")<>$F$1), AND( IFERROR(VLOOKUP(A30,'0919門市清單主檔'!B:AC,28,FALSE),"")="+HUB", IFERROR(VLOOKUP(A30,門市主檔!A:X,23,FALSE),"")<>"+HUB" ), AND( IFERROR(VLOOKUP(A30,'0919門市清單主檔'!B:AD,29,FALSE),"")="+EDC", IFERROR(VLOOKUP(A30,門市主檔!A:X,24,FALSE),"")<>"+EDC" ) ), _xlfn.TEXTJOIN( "，", TRUE, IF(AND($D$1<>"--", IFERROR(VLOOKUP(A30,'0919門市清單主檔'!B:AH,31,FALSE),"")=$D$1, IFERROR(VLOOKUP(A30,門市主檔!A:Q,17,FALSE),"")<>$D$1), $D$1, ""), IF(AND($E$1<>"--", IFERROR(VLOOKUP(A30,'0919門市清單主檔'!B:AH,32,FALSE),"")=$E$1, IFERROR(VLOOKUP(A30,門市主檔!A:S,19,FALSE),"")<>$E$1), $E$1, ""), IF(AND($F$1<>"--", IFERROR(VLOOKUP(A30,'0919門市清單主檔'!B:AH,33,FALSE),"")=$F$1, IFERROR(VLOOKUP(A30,門市主檔!A:U,21,FALSE),"")<>$F$1), $F$1, ""), IF(AND(IFERROR(VLOOKUP(A30,'0919門市清單主檔'!B:AC,28,FALSE),"")="+HUB", IFERROR(VLOOKUP(A30,門市主檔!A:X,23,FALSE),"")<>"+HUB"), "+HUB", ""), IF(AND(IFERROR(VLOOKUP(A30,'0919門市清單主檔'!B:AD,29,FALSE),"")="+EDC", IFERROR(VLOOKUP(A30,門市主檔!A:X,24,FALSE),"")<>"+EDC"), "+EDC", "") ) & "未完工", "已完工" ) ) ) -> 已完工 | P30: =(TEXT(I30,"yyyymmdd"))&$V$2&A30&$V$2&B30&$S$2 -> PMQ2-D193-蘆洲權義店(定保) | Q30: {=IF(AND(SUMPRODUCT((IM!$F$2:$F$5000=A30)*(ISNUMBER(SEARCH($D$1, IM!$AC$2:$AC$5000))))>0), $D$1, "")} | R30: {=IFERROR(INDEX(IM!$AM$2:$AM$5000, MATCH(1, (IM!$F$2:$F$5000=A30) * (ISNUMBER(SEARCH($D$1, IM!$AC$2:$AC$5000))), 0)), "")} | S30: {=IF(AND(SUMPRODUCT((IM!$F$2:$F$5000=A30)*(ISNUMBER(SEARCH($E$1, IM!$AC$2:$AC$5000))))>0), $E$1, "")} | T30: {=IFERROR(INDEX(IM!$AM$2:$AM$5000, MATCH(1, (IM!$F$2:$F$5000=A30) * (ISNUMBER(SEARCH($E$1, IM!$AC$2:$AC$5000))), 0)), "")} | U30: {=IF(AND(SUMPRODUCT((IM!$F$2:$F$5000=A30)*(ISNUMBER(SEARCH($F$1, IM!$AC$2:$AC$5000))))>0), $F$1, "")} | V30: {=IFERROR(INDEX(IM!$AM$2:$AM$5000, MATCH(1, (IM!$F$2:$F$5000=A30) * (ISNUMBER(SEARCH($F$1, IM!$AC$2:$AC$5000))), 0)), "")} | W30: {=IF( SUMPRODUCT( (IM!$F$2:$F$5000=A30)* (ISNUMBER(SEARCH($I$1,IM!$AC$2:$AC$5000)))* (IM!$X$2:$X$5000>=$A$1)* (IM!$X$2:$X$5000<=$B$1) )>0, $I$1, "" )} | X30: {=IF(AND(SUMPRODUCT((IM!$F$2:$F$5000=A30)*(ISNUMBER(SEARCH($J$1, IM!$AC$2:$AC$5000))))>0), $J$1, "")} -> +EDC | Y30: =A30 -> D193 | Z30: =B30 -> 蘆洲權義店
A31: 3008 | B31: =_xlfn.XLOOKUP(A31,'0919門市清單主檔'!B:B,'0919門市清單主檔'!C:C,"") -> 龜山香品店 | C31: =_xlfn.XLOOKUP($A31,'0919門市清單主檔'!B:B,'0919門市清單主檔'!U:U,"") -> 桃園市 | D31: =_xlfn.XLOOKUP($A31,'0919門市清單主檔'!B:B,'0919門市清單主檔'!V:V,"") -> 龜山區 | E31: =_xlfn.XLOOKUP(D31,門市狀態!G:G,門市狀態!H:H,"") -> 吳宗鴻 | F31: =IFERROR(IF(VLOOKUP(A31,門市狀態!A:D,4,FALSE)=0,"",VLOOKUP(A31,門市狀態!A:D,4,FALSE)),"") | H31: =IF(I31>0,(TEXT(I31,"yyyymmdd")&$V$2&A31&$V$2&B31&$S$2),"") -> PMQ2-3008-龜山香品店(定保) | I31: {=IF(AND(SUMPRODUCT((IM!$F$2:$F$5000=A31)*(ISNUMBER(SEARCH($C$1, IM!$AC$2:$AC$5000))))>0), $C$1, "")} -> PMQ2 | J31: {=IFERROR(INDEX(IM!$AM$2:$AM$5000, MATCH(1, (IM!$F$2:$F$5000=A31) * (ISNUMBER(SEARCH($C$1, IM!$AC$2:$AC$5000))), 0)), "")} -> 46119 | K31: {=SUMPRODUCT((IM!$F$2:$F$5000=A31)*(IM!$AD$2:$AD$5000="O")*(ISNUMBER(SEARCH($C$1, IM!$AC$2:$AC$5000))))} -> 1 | L31: {=IF(K31>0,IFERROR(HYPERLINK("#'IM'!AC"&MATCH(1,(IM!$F$1:$F$5000=A31)*(ISNUMBER(SEARCH($C$1,IM!$AC$1:$AC$5000))),0),"檢核"),"未登錄"),"")} -> 檢核 | M31: =Q31&S31&U31&W31&X31 -> +EDC | N31: {=IF(AND( SUMPRODUCT( (IM!$F$2:$F$522=A31) * ISNUMBER(SEARCH("*HUB*", IM!$AC$2:$AC$522)) * (IM!$X$2:$X$522>=$A$1) * (IM!$X$2:$X$522<=$B$1)*(W31="HUB") ) > 0 ), "HUB", "")} | O31: =IF( IFERROR(VLOOKUP(A31,門市主檔!A:I,9,FALSE),"")<>$C$1, "未完工", IF( AND($D$1="--",$E$1="--",$F$1="--"), "已完工", IF( OR( AND($D$1<>"--", IFERROR(VLOOKUP(A31,'0919門市清單主檔'!B:AH,31,FALSE),"")=$D$1, IFERROR(VLOOKUP(A31,門市主檔!A:Q,17,FALSE),"")<>$D$1), AND($E$1<>"--", IFERROR(VLOOKUP(A31,'0919門市清單主檔'!B:AH,32,FALSE),"")=$E$1, IFERROR(VLOOKUP(A31,門市主檔!A:S,19,FALSE),"")<>$E$1), AND($F$1<>"--", IFERROR(VLOOKUP(A31,'0919門市清單主檔'!B:AH,33,FALSE),"")=$F$1, IFERROR(VLOOKUP(A31,門市主檔!A:U,21,FALSE),"")<>$F$1), AND( IFERROR(VLOOKUP(A31,'0919門市清單主檔'!B:AC,28,FALSE),"")="+HUB", IFERROR(VLOOKUP(A31,門市主檔!A:X,23,FALSE),"")<>"+HUB" ), AND( IFERROR(VLOOKUP(A31,'0919門市清單主檔'!B:AD,29,FALSE),"")="+EDC", IFERROR(VLOOKUP(A31,門市主檔!A:X,24,FALSE),"")<>"+EDC" ) ), _xlfn.TEXTJOIN( "，", TRUE, IF(AND($D$1<>"--", IFERROR(VLOOKUP(A31,'0919門市清單主檔'!B:AH,31,FALSE),"")=$D$1, IFERROR(VLOOKUP(A31,門市主檔!A:Q,17,FALSE),"")<>$D$1), $D$1, ""), IF(AND($E$1<>"--", IFERROR(VLOOKUP(A31,'0919門市清單主檔'!B:AH,32,FALSE),"")=$E$1, IFERROR(VLOOKUP(A31,門市主檔!A:S,19,FALSE),"")<>$E$1), $E$1, ""), IF(AND($F$1<>"--", IFERROR(VLOOKUP(A31,'0919門市清單主檔'!B:AH,33,FALSE),"")=$F$1, IFERROR(VLOOKUP(A31,門市主檔!A:U,21,FALSE),"")<>$F$1), $F$1, ""), IF(AND(IFERROR(VLOOKUP(A31,'0919門市清單主檔'!B:AC,28,FALSE),"")="+HUB", IFERROR(VLOOKUP(A31,門市主檔!A:X,23,FALSE),"")<>"+HUB"), "+HUB", ""), IF(AND(IFERROR(VLOOKUP(A31,'0919門市清單主檔'!B:AD,29,FALSE),"")="+EDC", IFERROR(VLOOKUP(A31,門市主檔!A:X,24,FALSE),"")<>"+EDC"), "+EDC", "") ) & "未完工", "已完工" ) ) ) -> 已完工 | P31: =(TEXT(I31,"yyyymmdd"))&$V$2&A31&$V$2&B31&$S$2 -> PMQ2-3008-龜山香品店(定保) | Q31: {=IF(AND(SUMPRODUCT((IM!$F$2:$F$5000=A31)*(ISNUMBER(SEARCH($D$1, IM!$AC$2:$AC$5000))))>0), $D$1, "")} | R31: {=IFERROR(INDEX(IM!$AM$2:$AM$5000, MATCH(1, (IM!$F$2:$F$5000=A31) * (ISNUMBER(SEARCH($D$1, IM!$AC$2:$AC$5000))), 0)), "")} | S31: {=IF(AND(SUMPRODUCT((IM!$F$2:$F$5000=A31)*(ISNUMBER(SEARCH($E$1, IM!$AC$2:$AC$5000))))>0), $E$1, "")} | T31: {=IFERROR(INDEX(IM!$AM$2:$AM$5000, MATCH(1, (IM!$F$2:$F$5000=A31) * (ISNUMBER(SEARCH($E$1, IM!$AC$2:$AC$5000))), 0)), "")} | U31: {=IF(AND(SUMPRODUCT((IM!$F$2:$F$5000=A31)*(ISNUMBER(SEARCH($F$1, IM!$AC$2:$AC$5000))))>0), $F$1, "")} | V31: {=IFERROR(INDEX(IM!$AM$2:$AM$5000, MATCH(1, (IM!$F$2:$F$5000=A31) * (ISNUMBER(SEARCH($F$1, IM!$AC$2:$AC$5000))), 0)), "")} | W31: {=IF( SUMPRODUCT( (IM!$F$2:$F$5000=A31)* (ISNUMBER(SEARCH($I$1,IM!$AC$2:$AC$5000)))* (IM!$X$2:$X$5000>=$A$1)* (IM!$X$2:$X$5000<=$B$1) )>0, $I$1, "" )} | X31: {=IF(AND(SUMPRODUCT((IM!$F$2:$F$5000=A31)*(ISNUMBER(SEARCH($J$1, IM!$AC$2:$AC$5000))))>0), $J$1, "")} -> +EDC | Y31: =A31 -> 3008 | Z31: =B31 -> 龜山香品店 | AA31: L90未執行
A32: L534 | B32: =_xlfn.XLOOKUP(A32,'0919門市清單主檔'!B:B,'0919門市清單主檔'!C:C,"") -> 田倉文興店 | C32: =_xlfn.XLOOKUP($A32,'0919門市清單主檔'!B:B,'0919門市清單主檔'!U:U,"") -> 桃園市 | D32: =_xlfn.XLOOKUP($A32,'0919門市清單主檔'!B:B,'0919門市清單主檔'!V:V,"") -> 龜山區 | E32: =_xlfn.XLOOKUP(D32,門市狀態!G:G,門市狀態!H:H,"") -> 吳宗鴻 | F32: =IFERROR(IF(VLOOKUP(A32,門市狀態!A:D,4,FALSE)=0,"",VLOOKUP(A32,門市狀態!A:D,4,FALSE)),"") | H32: =IF(I32>0,(TEXT(I32,"yyyymmdd")&$V$2&A32&$V$2&B32&$S$2),"") -> PMQ2-L534-田倉文興店(定保) | I32: {=IF(AND(SUMPRODUCT((IM!$F$2:$F$5000=A32)*(ISNUMBER(SEARCH($C$1, IM!$AC$2:$AC$5000))))>0), $C$1, "")} -> PMQ2 | J32: {=IFERROR(INDEX(IM!$AM$2:$AM$5000, MATCH(1, (IM!$F$2:$F$5000=A32) * (ISNUMBER(SEARCH($C$1, IM!$AC$2:$AC$5000))), 0)), "")} -> 46119 | K32: {=SUMPRODUCT((IM!$F$2:$F$5000=A32)*(IM!$AD$2:$AD$5000="O")*(ISNUMBER(SEARCH($C$1, IM!$AC$2:$AC$5000))))} -> 1 | L32: {=IF(K32>0,IFERROR(HYPERLINK("#'IM'!AC"&MATCH(1,(IM!$F$1:$F$5000=A32)*(ISNUMBER(SEARCH($C$1,IM!$AC$1:$AC$5000))),0),"檢核"),"未登錄"),"")} -> 檢核 | M32: =Q32&S32&U32&W32&X32 | N32: {=IF(AND( SUMPRODUCT( (IM!$F$2:$F$522=A32) * ISNUMBER(SEARCH("*HUB*", IM!$AC$2:$AC$522)) * (IM!$X$2:$X$522>=$A$1) * (IM!$X$2:$X$522<=$B$1)*(W32="HUB") ) > 0 ), "HUB", "")} | O32: =IF( IFERROR(VLOOKUP(A32,門市主檔!A:I,9,FALSE),"")<>$C$1, "未完工", IF( AND($D$1="--",$E$1="--",$F$1="--"), "已完工", IF( OR( AND($D$1<>"--", IFERROR(VLOOKUP(A32,'0919門市清單主檔'!B:AH,31,FALSE),"")=$D$1, IFERROR(VLOOKUP(A32,門市主檔!A:Q,17,FALSE),"")<>$D$1), AND($E$1<>"--", IFERROR(VLOOKUP(A32,'0919門市清單主檔'!B:AH,32,FALSE),"")=$E$1, IFERROR(VLOOKUP(A32,門市主檔!A:S,19,FALSE),"")<>$E$1), AND($F$1<>"--", IFERROR(VLOOKUP(A32,'0919門市清單主檔'!B:AH,33,FALSE),"")=$F$1, IFERROR(VLOOKUP(A32,門市主檔!A:U,21,FALSE),"")<>$F$1), AND( IFERROR(VLOOKUP(A32,'0919門市清單主檔'!B:AC,28,FALSE),"")="+HUB", IFERROR(VLOOKUP(A32,門市主檔!A:X,23,FALSE),"")<>"+HUB" ), AND( IFERROR(VLOOKUP(A32,'0919門市清單主檔'!B:AD,29,FALSE),"")="+EDC", IFERROR(VLOOKUP(A32,門市主檔!A:X,24,FALSE),"")<>"+EDC" ) ), _xlfn.TEXTJOIN( "，", TRUE, IF(AND($D$1<>"--", IFERROR(VLOOKUP(A32,'0919門市清單主檔'!B:AH,31,FALSE),"")=$D$1, IFERROR(VLOOKUP(A32,門市主檔!A:Q,17,FALSE),"")<>$D$1), $D$1, ""), IF(AND($E$1<>"--", IFERROR(VLOOKUP(A32,'0919門市清單主檔'!B:AH,32,FALSE),"")=$E$1, IFERROR(VLOOKUP(A32,門市主檔!A:S,19,FALSE),"")<>$E$1), $E$1, ""), IF(AND($F$1<>"--", IFERROR(VLOOKUP(A32,'0919門市清單主檔'!B:AH,33,FALSE),"")=$F$1, IFERROR(VLOOKUP(A32,門市主檔!A:U,21,FALSE),"")<>$F$1), $F$1, ""), IF(AND(IFERROR(VLOOKUP(A32,'0919門市清單主檔'!B:AC,28,FALSE),"")="+HUB", IFERROR(VLOOKUP(A32,門市主檔!A:X,23,FALSE),"")<>"+HUB"), "+HUB", ""), IF(AND(IFERROR(VLOOKUP(A32,'0919門市清單主檔'!B:AD,29,FALSE),"")="+EDC", IFERROR(VLOOKUP(A32,門市主檔!A:X,24,FALSE),"")<>"+EDC"), "+EDC", "") ) & "未完工", "已完工" ) ) ) -> 已完工 | P32: =(TEXT(I32,"yyyymmdd"))&$V$2&A32&$V$2&B32&$S$2 -> PMQ2-L534-田倉文興店(定保) | Q32: {=IF(AND(SUMPRODUCT((IM!$F$2:$F$5000=A32)*(ISNUMBER(SEARCH($D$1, IM!$AC$2:$AC$5000))))>0), $D$1, "")} | R32: {=IFERROR(INDEX(IM!$AM$2:$AM$5000, MATCH(1, (IM!$F$2:$F$5000=A32) * (ISNUMBER(SEARCH($D$1, IM!$AC$2:$AC$5000))), 0)), "")} | S32: {=IF(AND(SUMPRODUCT((IM!$F$2:$F$5000=A32)*(ISNUMBER(SEARCH($E$1, IM!$AC$2:$AC$5000))))>0), $E$1, "")} | T32: {=IFERROR(INDEX(IM!$AM$2:$AM$5000, MATCH(1, (IM!$F$2:$F$5000=A32) * (ISNUMBER(SEARCH($E$1, IM!$AC$2:$AC$5000))), 0)), "")} | U32: {=IF(AND(SUMPRODUCT((IM!$F$2:$F$5000=A32)*(ISNUMBER(SEARCH($F$1, IM!$AC$2:$AC$5000))))>0), $F$1, "")} | V32: {=IFERROR(INDEX(IM!$AM$2:$AM$5000, MATCH(1, (IM!$F$2:$F$5000=A32) * (ISNUMBER(SEARCH($F$1, IM!$AC$2:$AC$5000))), 0)), "")} | W32: {=IF( SUMPRODUCT( (IM!$F$2:$F$5000=A32)* (ISNUMBER(SEARCH($I$1,IM!$AC$2:$AC$5000)))* (IM!$X$2:$X$5000>=$A$1)* (IM!$X$2:$X$5000<=$B$1) )>0, $I$1, "" )} | X32: {=IF(AND(SUMPRODUCT((IM!$F$2:$F$5000=A32)*(ISNUMBER(SEARCH($J$1, IM!$AC$2:$AC$5000))))>0), $J$1, "")} | Y32: =A32 -> L534 | Z32: =B32 -> 田倉文興店 | AA32: 車麗屋
A33: D350 | B33: =_xlfn.XLOOKUP(A33,'0919門市清單主檔'!B:B,'0919門市清單主檔'!C:C,"") -> 三重徐匯站 | C33: =_xlfn.XLOOKUP($A33,'0919門市清單主檔'!B:B,'0919門市清單主檔'!U:U,"") -> 新北市 | D33: =_xlfn.XLOOKUP($A33,'0919門市清單主檔'!B:B,'0919門市清單主檔'!V:V,"") -> 三重區 | E33: =_xlfn.XLOOKUP(D33,門市狀態!G:G,門市狀態!H:H,"") -> 劉柏均 | F33: =IFERROR(IF(VLOOKUP(A33,門市狀態!A:D,4,FALSE)=0,"",VLOOKUP(A33,門市狀態!A:D,4,FALSE)),"") | H33: =IF(I33>0,(TEXT(I33,"yyyymmdd")&$V$2&A33&$V$2&B33&$S$2),"") -> PMQ2-D350-三重徐匯站(定保) | I33: {=IF(AND(SUMPRODUCT((IM!$F$2:$F$5000=A33)*(ISNUMBER(SEARCH($C$1, IM!$AC$2:$AC$5000))))>0), $C$1, "")} -> PMQ2 | J33: {=IFERROR(INDEX(IM!$AM$2:$AM$5000, MATCH(1, (IM!$F$2:$F$5000=A33) * (ISNUMBER(SEARCH($C$1, IM!$AC$2:$AC$5000))), 0)), "")} -> 46119 | K33: {=SUMPRODUCT((IM!$F$2:$F$5000=A33)*(IM!$AD$2:$AD$5000="O")*(ISNUMBER(SEARCH($C$1, IM!$AC$2:$AC$5000))))} -> 1 | L33: {=IF(K33>0,IFERROR(HYPERLINK("#'IM'!AC"&MATCH(1,(IM!$F$1:$F$5000=A33)*(ISNUMBER(SEARCH($C$1,IM!$AC$1:$AC$5000))),0),"檢核"),"未登錄"),"")} -> 檢核 | M33: =Q33&S33&U33&W33&X33 -> +EDC | N33: {=IF(AND( SUMPRODUCT( (IM!$F$2:$F$522=A33) * ISNUMBER(SEARCH("*HUB*", IM!$AC$2:$AC$522)) * (IM!$X$2:$X$522>=$A$1) * (IM!$X$2:$X$522<=$B$1)*(W33="HUB") ) > 0 ), "HUB", "")} | O33: =IF( IFERROR(VLOOKUP(A33,門市主檔!A:I,9,FALSE),"")<>$C$1, "未完工", IF( AND($D$1="--",$E$1="--",$F$1="--"), "已完工", IF( OR( AND($D$1<>"--", IFERROR(VLOOKUP(A33,'0919門市清單主檔'!B:AH,31,FALSE),"")=$D$1, IFERROR(VLOOKUP(A33,門市主檔!A:Q,17,FALSE),"")<>$D$1), AND($E$1<>"--", IFERROR(VLOOKUP(A33,'0919門市清單主檔'!B:AH,32,FALSE),"")=$E$1, IFERROR(VLOOKUP(A33,門市主檔!A:S,19,FALSE),"")<>$E$1), AND($F$1<>"--", IFERROR(VLOOKUP(A33,'0919門市清單主檔'!B:AH,33,FALSE),"")=$F$1, IFERROR(VLOOKUP(A33,門市主檔!A:U,21,FALSE),"")<>$F$1), AND( IFERROR(VLOOKUP(A33,'0919門市清單主檔'!B:AC,28,FALSE),"")="+HUB", IFERROR(VLOOKUP(A33,門市主檔!A:X,23,FALSE),"")<>"+HUB" ), AND( IFERROR(VLOOKUP(A33,'0919門市清單主檔'!B:AD,29,FALSE),"")="+EDC", IFERROR(VLOOKUP(A33,門市主檔!A:X,24,FALSE),"")<>"+EDC" ) ), _xlfn.TEXTJOIN( "，", TRUE, IF(AND($D$1<>"--", IFERROR(VLOOKUP(A33,'0919門市清單主檔'!B:AH,31,FALSE),"")=$D$1, IFERROR(VLOOKUP(A33,門市主檔!A:Q,17,FALSE),"")<>$D$1), $D$1, ""), IF(AND($E$1<>"--", IFERROR(VLOOKUP(A33,'0919門市清單主檔'!B:AH,32,FALSE),"")=$E$1, IFERROR(VLOOKUP(A33,門市主檔!A:S,19,FALSE),"")<>$E$1), $E$1, ""), IF(AND($F$1<>"--", IFERROR(VLOOKUP(A33,'0919門市清單主檔'!B:AH,33,FALSE),"")=$F$1, IFERROR(VLOOKUP(A33,門市主檔!A:U,21,FALSE),"")<>$F$1), $F$1, ""), IF(AND(IFERROR(VLOOKUP(A33,'0919門市清單主檔'!B:AC,28,FALSE),"")="+HUB", IFERROR(VLOOKUP(A33,門市主檔!A:X,23,FALSE),"")<>"+HUB"), "+HUB", ""), IF(AND(IFERROR(VLOOKUP(A33,'0919門市清單主檔'!B:AD,29,FALSE),"")="+EDC", IFERROR(VLOOKUP(A33,門市主檔!A:X,24,FALSE),"")<>"+EDC"), "+EDC", "") ) & "未完工", "已完工" ) ) ) -> 已完工 | P33: =(TEXT(I33,"yyyymmdd"))&$V$2&A33&$V$2&B33&$S$2 -> PMQ2-D350-三重徐匯站(定保) | Q33: {=IF(AND(SUMPRODUCT((IM!$F$2:$F$5000=A33)*(ISNUMBER(SEARCH($D$1, IM!$AC$2:$AC$5000))))>0), $D$1, "")} | R33: {=IFERROR(INDEX(IM!$AM$2:$AM$5000, MATCH(1, (IM!$F$2:$F$5000=A33) * (ISNUMBER(SEARCH($D$1, IM!$AC$2:$AC$5000))), 0)), "")} | S33: {=IF(AND(SUMPRODUCT((IM!$F$2:$F$5000=A33)*(ISNUMBER(SEARCH($E$1, IM!$AC$2:$AC$5000))))>0), $E$1, "")} | T33: {=IFERROR(INDEX(IM!$AM$2:$AM$5000, MATCH(1, (IM!$F$2:$F$5000=A33) * (ISNUMBER(SEARCH($E$1, IM!$AC$2:$AC$5000))), 0)), "")} | U33: {=IF(AND(SUMPRODUCT((IM!$F$2:$F$5000=A33)*(ISNUMBER(SEARCH($F$1, IM!$AC$2:$AC$5000))))>0), $F$1, "")} | V33: {=IFERROR(INDEX(IM!$AM$2:$AM$5000, MATCH(1, (IM!$F$2:$F$5000=A33) * (ISNUMBER(SEARCH($F$1, IM!$AC$2:$AC$5000))), 0)), "")} | W33: {=IF( SUMPRODUCT( (IM!$F$2:$F$5000=A33)* (ISNUMBER(SEARCH($I$1,IM!$AC$2:$AC$5000)))* (IM!$X$2:$X$5000>=$A$1)* (IM!$X$2:$X$5000<=$B$1) )>0, $I$1, "" )} | X33: {=IF(AND(SUMPRODUCT((IM!$F$2:$F$5000=A33)*(ISNUMBER(SEARCH($J$1, IM!$AC$2:$AC$5000))))>0), $J$1, "")} -> +EDC | Y33: =A33 -> D350 | Z33: =B33 -> 三重徐匯站
